Workbook

Sheet Leia-me
A1: Zonas, ramais e blocos — EXEMPLO_AL-ILUSTRATIVO
A3: DADOS DE EXEMPLO | B3: Circuito ilustrativo. Não é rede real. Serve para validar o formato.
A4: Zona | B4: T1 do DJ ao 1º religador (79). Depois de qualquer religador é T2, inclusive religador em ramal: religador nunca cria T3. Depois de uma chave fusível (03) é no mínimo T3; se já estava em T3 ou mais, soma uma.
A5: Seccionamento | B5: Chave 03/33/02 com religador depois dela não conta como fusível: não muda a zona e aparece em "Outras chaves no bloco (88…)" como "Chave 03 de seccionamento".
A6: Tronco | B6: Caminho DJ → 1º religador → 2º religador e, depois do 2º, até os próximos ativos (religador ou fusível): o trecho entre dois ativos do tronco ainda é tronco. Pontas sem equipamento são ramal. Nunca tem T3. O resto é ramal, com o nome do poste onde sai do tronco.
A7: Ativo de referência | B7: Último DJ, 79 ou 03 antes do vão, vindo do DJ. Ele engloba o vão e tudo o que vem depois.
A8: Ativos posteriores englobados | B8: Os DJ/79/03 que ficam depois do vão ou do bloco. Se o ativo de referência abrir, todos ficam sem energia.
A9: Bloco | B9: Vãos com o mesmo ativo de referência e o mesmo ramal (de um ativo até o próximo). Chaves 88 e outras que não são DJ/79/fusível não dividem bloco: aparecem na coluna "Outras chaves no bloco (88…)". Chaves 02 e 33 contam como fusível.
A10: Nível 1…N | B10: Sequência de ativos desde o DJ até o ativo de referência. Filtrar um nível mostra tudo o que fica depois daquele ativo.
A11: Distâncias | B11: Calculadas a partir das coordenadas (haversine, raio 6.371 km), seguindo a rede.
A12: Abas | B12: Árvore de blocos: visão rápida da sequência, agrupada por tronco e ramal. Consulta: digite um poste e veja onde ele está. Blocos: um bloco por linha, com os ativos posteriores um por coluna e juntos numa coluna só. Por bloco: os vãos agrupados embaixo de cada bloco (botão + à esquerda). Trechos: um vão por linha. Ativos: resumo por ativo.
A14: Cores das zonas
A15: T1
A16: T2
A17: T3
A18: T4

Sheet Árvore de blocos
A1: Árvore de blocos — EXEMPLO_AL-ILUSTRATIVO
A2: Cada linha é um bloco. A célula colorida é o ativo de referência do bloco (cor da zona). As células em cinza à esquerda são os ativos antes dele, desde o DJ.
A3: Zonas: | B3: T1 | C3: T2 | D3: T3 | E3: T4
A5: Bloco | B5: Zona | C5: Nível 1 | D5: Nível 2 | E5: Nível 3 | F5: Nível 4 | G5: Nível 5 | H5: De | I5: Até (próximos ativos) | J5: Vãos | K5: Extensão (m) | L5: Outras chaves no bloco (88…) | M5: Ativos englobados (depois do bloco)
A6: TRONCO — do DJ ao 2º religador e até os próximos ativos
A7: 1 | B7: T1 | C7: DJ | H7: DJ | I7: RL1 | J7: =COUNTIFS(Trechos!$L$2:$L$134,A7) -> 15 | K7: =SUMIFS(Trechos!$F$2:$F$134,Trechos!$L$2:$L$134,A7) -> 659.25076 | L7: — | M7: =Blocos!Q2 -> RL1, RL2, RL3, 03-E, 03-F, 03-D, 03-C, RL-A, 03-A, 03-B
A8: 2 | B8: T2 | C8: DJ | D8: RL1 | H8: RL1 | I8: RL2 | J8: =COUNTIFS(Trechos!$L$2:$L$134,A8) -> 16 | K8: =SUMIFS(Trechos!$F$2:$F$134,Trechos!$L$2:$L$134,A8) -> 659.25076 | L8: 88-A | M8: =Blocos!Q3 -> RL2, RL3, 03-E, 03-F, 03-D
A9: 3 | B9: T2 | C9: DJ | D9: RL1 | E9: RL2 | H9: RL2 | I9: RL3 / 03-E | J9: =COUNTIFS(Trechos!$L$2:$L$134,A9) -> 17 | K9: =SUMIFS(Trechos!$F$2:$F$134,Trechos!$L$2:$L$134,A9) -> 679.23039 | L9: — | M9: =Blocos!Q4 -> RL3, 03-E, 03-F
A10: RAMAL P-102 — sai do tronco no poste P-102
A11: 4 | B11: T1 | C11: DJ | H11: poste P-102 | I11: RL-A | J11: =COUNTIFS(Trechos!$L$2:$L$134,A11) -> 5 | K11: =SUMIFS(Trechos!$F$2:$F$134,Trechos!$L$2:$L$134,A11) -> 199.77529 | L11: — | M11: =Blocos!Q5 -> RL-A, 03-A, 03-B
A12: 5 | B12: T2 | C12: DJ | D12: RL-A | H12: RL-A | I12: 03-A | J12: =COUNTIFS(Trechos!$L$2:$L$134,A12) -> 5 | K12: =SUMIFS(Trechos!$F$2:$F$134,Trechos!$L$2:$L$134,A12) -> 219.75282 | L12: — | M12: =Blocos!Q6 -> 03-A, 03-B
A13: 6 | B13: T3 | C13: DJ | D13: RL-A | E13: 03-A | H13: 03-A | I13: 03-B / fim P-124 | J13: =COUNTIFS(Trechos!$L$2:$L$134,A13) -> 16 | K13: =SUMIFS(Trechos!$F$2:$F$134,Trechos!$L$2:$L$134,A13) -> 659.25115 | L13: — | M13: =Blocos!Q7 -> 03-B
A14: 7 | B14: T4 | C14: DJ | D14: RL-A | E14: 03-A | F14: 03-B | H14: 03-B | I14: fim P-127 | J14: =COUNTIFS(Trechos!$L$2:$L$134,A14) -> 6 | K14: =SUMIFS(Trechos!$F$2:$F$134,Trechos!$L$2:$L$134,A14) -> 239.72361 | L14: — | M14: =Blocos!Q8 -> —
A15: RAMAL P-105 — sai do tronco no poste P-105
A16: 8 | B16: T1 | C16: DJ | H16: poste P-105 | I16: 03-C | J16: =COUNTIFS(Trechos!$L$2:$L$134,A16) -> 5 | K16: =SUMIFS(Trechos!$F$2:$F$134,Trechos!$L$2:$L$134,A16) -> 199.77529 | L16: — | M16: =Blocos!Q9 -> 03-C
A17: 9 | B17: T3 | C17: DJ | D17: 03-C | H17: 03-C | I17: fim P-110 | J17: =COUNTIFS(Trechos!$L$2:$L$134,A17) -> 4 | K17: =SUMIFS(Trechos!$F$2:$F$134,Trechos!$L$2:$L$134,A17) -> 159.82023 | L17: — | M17: =Blocos!Q10 -> —
A18: RAMAL P-131 — sai do tronco no poste P-131
A19: 10 | B19: T2 | C19: DJ | D19: RL1 | H19: poste P-131 | I19: 03-D | J19: =COUNTIFS(Trechos!$L$2:$L$134,A19) -> 5 | K19: =SUMIFS(Trechos!$F$2:$F$134,Trechos!$L$2:$L$134,A19) -> 219.75282 | L19: — | M19: =Blocos!Q11 -> 03-D
A20: 11 | B20: T3 | C20: DJ | D20: RL1 | E20: 03-D | H20: 03-D | I20: fim P-135 | J20: =COUNTIFS(Trechos!$L$2:$L$134,A20) -> 5 | K20: =SUMIFS(Trechos!$F$2:$F$134,Trechos!$L$2:$L$134,A20) -> 219.75282 | L20: — | M20: =Blocos!Q12 -> —
A21: RAMAL P-138 — sai do tronco no poste P-138
A22: 12 | B22: T2 | C22: DJ | D22: RL1 | H22: poste P-138 | I22: fim P-140 | J22: =COUNTIFS(Trechos!$L$2:$L$134,A22) -> 8 | K22: =SUMIFS(Trechos!$F$2:$F$134,Trechos!$L$2:$L$134,A22) -> 319.64046 | L22: — | M22: =Blocos!Q13 -> —
A23: RAMAL APÓS RL3 — sai do fim do tronco
A24: 13 | B24: T2 | C24: DJ | D24: RL1 | E24: RL2 | F24: RL3 | H24: RL3 | I24: fim P-171 | J24: =COUNTIFS(Trechos!$L$2:$L$134,A24) -> 4 | K24: =SUMIFS(Trechos!$F$2:$F$134,Trechos!$L$2:$L$134,A24) -> 159.82023 | L24: — | M24: =Blocos!Q14 -> —
A25: RAMAL APÓS 03-E — sai do fim do tronco
A26: 14 | B26: T3 | C26: DJ | D26: RL1 | E26: RL2 | F26: 03-E | H26: 03-E | I26: 03-F / fim P-195 | J26: =COUNTIFS(Trechos!$L$2:$L$134,A26) -> 18 | K26: =SUMIFS(Trechos!$F$2:$F$134,Trechos!$L$2:$L$134,A26) -> 719.18825 | L26: 88-B | M26: =Blocos!Q15 -> 03-F
A27: 15 | B27: T4 | C27: DJ | D27: RL1 | E27: RL2 | F27: 03-E | G27: 03-F | H27: 03-F | I27: fim P-199 | J27: =COUNTIFS(Trechos!$L$2:$L$134,A27) -> 4 | K27: =SUMIFS(Trechos!$F$2:$F$134,Trechos!$L$2:$L$134,A27) -> 159.82023 | L27: — | M27: =Blocos!Q16 -> —

Sheet Consulta
A1: Onde fica este poste?
A2: Digite o código do poste na célula amarela (o poste no fim do vão). A planilha mostra o vão e a sequência desde o DJ.
A4: Poste | B4: P-265 | C4: ← exemplo
A6: Trecho (vão) | B6: =IFERROR(INDEX(Trechos!$B$2:$B$134,MATCH($B$4,Trechos!$E$2:$E$134,0)),"poste não encontrado") -> TR-132
A7: Poste início | B7: =IFERROR(INDEX(Trechos!$D$2:$D$134,MATCH($B$4,Trechos!$E$2:$E$134,0)),"poste não encontrado") -> P-264
A8: Zona | B8: =IFERROR(INDEX(Trechos!$I$2:$I$134,MATCH($B$4,Trechos!$E$2:$E$134,0)),"poste não encontrado") -> T4
A9: Tronco/Ramal | B9: =IFERROR(INDEX(Trechos!$J$2:$J$134,MATCH($B$4,Trechos!$E$2:$E$134,0)),"poste não encontrado") -> Ramal
A10: Ramal | B10: =IFERROR(INDEX(Trechos!$K$2:$K$134,MATCH($B$4,Trechos!$E$2:$E$134,0)),"poste não encontrado") -> Ramal após 03-E
A11: Bloco | B11: =IFERROR(INDEX(Trechos!$L$2:$L$134,MATCH($B$4,Trechos!$E$2:$E$134,0)),"poste não encontrado") -> 15
A12: Ativo de referência | B12: =IFERROR(INDEX(Trechos!$M$2:$M$134,MATCH($B$4,Trechos!$E$2:$E$134,0)),"poste não encontrado") -> 03-F
A13: Distância do ativo de referência (m) | B13: =IFERROR(INDEX(Trechos!$H$2:$H$134,MATCH($B$4,Trechos!$E$2:$E$134,0)),"poste não encontrado") -> 119.86517
A14: Distância do DJ (m) | B14: =IFERROR(INDEX(Trechos!$G$2:$G$134,MATCH($B$4,Trechos!$E$2:$E$134,0)),"poste não encontrado") -> 2357.3246
A15: Ativos posteriores englobados | B15: =IFERROR(INDEX(Trechos!$P$2:$P$134,MATCH($B$4,Trechos!$E$2:$E$134,0)),"poste não encontrado") -> —
A16: Outra chave no fim do vão (88…) | B16: =IFERROR(INDEX(Trechos!$R$2:$R$134,MATCH($B$4,Trechos!$E$2:$E$134,0)),"poste não encontrado") -> 0
A17: Caminho desde o DJ | B17: =IFERROR(INDEX(Trechos!$X$2:$X$134,MATCH($B$4,Trechos!$E$2:$E$134,0)),"poste não encontrado") -> DJ › RL1 › RL2 › 03-E › 03-F
A18: Latitude | B18: =IFERROR(INDEX(Trechos!$Y$2:$Y$134,MATCH($B$4,Trechos!$E$2:$E$134,0)),"poste não encontrado") -> -9.6012576
A19: Longitude | B19: =IFERROR(INDEX(Trechos!$Z$2:$Z$134,MATCH($B$4,Trechos!$E$2:$E$134,0)),"poste não encontrado") -> -48.430321

Sheet Blocos
A1: Bloco | B1: Zona | C1: Tronco/Ramal | D1: Ramal | E1: Ativo de referência | F1: De | G1: Próximo ativo 1 | H1: Próximo ativo 2 | I1: Nível 1 | J1: Nível 2 | K1: Nível 3 | L1: Nível 4 | M1: Nível 5 | N1: Qtd. vãos | O1: Extensão do bloco (m) | P1: Qtd. ativos posteriores | Q1: Ativos posteriores (concatenado) | R1: Outras chaves no bloco (88…) | S1: Posterior 1 | T1: Posterior 2 | U1: Posterior 3 | V1: Posterior 4 | W1: Posterior 5 | X1: Posterior 6 | Y1: Posterior 7 | Z1: Posterior 8 | AA1: Posterior 9 | AB1: Posterior 10
A2: 1 | B2: T1 | C2: Tronco | D2: Tronco | E2: DJ | F2: DJ | G2: RL1 | I2: DJ | N2: =COUNTIFS(Trechos!$L$2:$L$134,A2) -> 15 | O2: =SUMIFS(Trechos!$F$2:$F$134,Trechos!$L$2:$L$134,A2) -> 659.25076 | P2: =COUNTA(S2:AB2) -> 10 | Q2: =IF(COUNTA(S2:AB2)=0,"—",_xlfn.TEXTJOIN(", ",TRUE(),S2:AB2)) -> RL1, RL2, RL3, 03-E, 03-F, 03-D, 03-C, RL-A, 03-A, 03-B | R2: — | S2: RL1 | T2: RL2 | U2: RL3 | V2: 03-E | W2: 03-F | X2: 03-D | Y2: 03-C | Z2: RL-A | AA2: 03-A | AB2: 03-B
A3: 2 | B3: T2 | C3: Tronco | D3: Tronco | E3: RL1 | F3: RL1 | G3: RL2 | I3: DJ | J3: RL1 | N3: =COUNTIFS(Trechos!$L$2:$L$134,A3) -> 16 | O3: =SUMIFS(Trechos!$F$2:$F$134,Trechos!$L$2:$L$134,A3) -> 659.25076 | P3: =COUNTA(S3:AB3) -> 5 | Q3: =IF(COUNTA(S3:AB3)=0,"—",_xlfn.TEXTJOIN(", ",TRUE(),S3:AB3)) -> RL2, RL3, 03-E, 03-F, 03-D | R3: 88-A | S3: RL2 | T3: RL3 | U3: 03-E | V3: 03-F | W3: 03-D
A4: 3 | B4: T2 | C4: Tronco | D4: Tronco | E4: RL2 | F4: RL2 | G4: RL3 | H4: 03-E | I4: DJ | J4: RL1 | K4: RL2 | N4: =COUNTIFS(Trechos!$L$2:$L$134,A4) -> 17 | O4: =SUMIFS(Trechos!$F$2:$F$134,Trechos!$L$2:$L$134,A4) -> 679.23039 | P4: =COUNTA(S4:AB4) -> 3 | Q4: =IF(COUNTA(S4:AB4)=0,"—",_xlfn.TEXTJOIN(", ",TRUE(),S4:AB4)) -> RL3, 03-E, 03-F | R4: — | S4: RL3 | T4: 03-E | U4: 03-F
A5: 4 | B5: T1 | C5: Ramal | D5: Ramal P-102 | E5: DJ | F5: poste P-102 | G5: RL-A | I5: DJ | N5: =COUNTIFS(Trechos!$L$2:$L$134,A5) -> 5 | O5: =SUMIFS(Trechos!$F$2:$F$134,Trechos!$L$2:$L$134,A5) -> 199.77529 | P5: =COUNTA(S5:AB5) -> 3 | Q5: =IF(COUNTA(S5:AB5)=0,"—",_xlfn.TEXTJOIN(", ",TRUE(),S5:AB5)) -> RL-A, 03-A, 03-B | R5: — | S5: RL-A | T5: 03-A | U5: 03-B
A6: 5 | B6: T2 | C6: Ramal | D6: Ramal P-102 | E6: RL-A | F6: RL-A | G6: 03-A | I6: DJ | J6: RL-A | N6: =COUNTIFS(Trechos!$L$2:$L$134,A6) -> 5 | O6: =SUMIFS(Trechos!$F$2:$F$134,Trechos!$L$2:$L$134,A6) -> 219.75282 | P6: =COUNTA(S6:AB6) -> 2 | Q6: =IF(COUNTA(S6:AB6)=0,"—",_xlfn.TEXTJOIN(", ",TRUE(),S6:AB6)) -> 03-A, 03-B | R6: — | S6: 03-A | T6: 03-B
A7: 6 | B7: T3 | C7: Ramal | D7: Ramal P-102 | E7: 03-A | F7: 03-A | G7: 03-B | H7: fim P-124 | I7: DJ | J7: RL-A | K7: 03-A | N7: =COUNTIFS(Trechos!$L$2:$L$134,A7) -> 16 | O7: =SUMIFS(Trechos!$F$2:$F$134,Trechos!$L$2:$L$134,A7) -> 659.25115 | P7: =COUNTA(S7:AB7) -> 1 | Q7: =IF(COUNTA(S7:AB7)=0,"—",_xlfn.TEXTJOIN(", ",TRUE(),S7:AB7)) -> 03-B | R7: — | S7: 03-B
A8: 7 | B8: T4 | C8: Ramal | D8: Ramal P-102 | E8: 03-B | F8: 03-B | G8: fim P-127 | I8: DJ | J8: RL-A | K8: 03-A | L8: 03-B | N8: =COUNTIFS(Trechos!$L$2:$L$134,A8) -> 6 | O8: =SUMIFS(Trechos!$F$2:$F$134,Trechos!$L$2:$L$134,A8) -> 239.72361 | P8: =COUNTA(S8:AB8) -> 0 | Q8: =IF(COUNTA(S8:AB8)=0,"—",_xlfn.TEXTJOIN(", ",TRUE(),S8:AB8)) -> — | R8: —
A9: 8 | B9: T1 | C9: Ramal | D9: Ramal P-105 | E9: DJ | F9: poste P-105 | G9: 03-C | I9: DJ | N9: =COUNTIFS(Trechos!$L$2:$L$134,A9) -> 5 | O9: =SUMIFS(Trechos!$F$2:$F$134,Trechos!$L$2:$L$134,A9) -> 199.77529 | P9: =COUNTA(S9:AB9) -> 1 | Q9: =IF(COUNTA(S9:AB9)=0,"—",_xlfn.TEXTJOIN(", ",TRUE(),S9:AB9)) -> 03-C | R9: — | S9: 03-C
A10: 9 | B10: T3 | C10: Ramal | D10: Ramal P-105 | E10: 03-C | F10: 03-C | G10: fim P-110 | I10: DJ | J10: 03-C | N10: =COUNTIFS(Trechos!$L$2:$L$134,A10) -> 4 | O10: =SUMIFS(Trechos!$F$2:$F$134,Trechos!$L$2:$L$134,A10) -> 159.82023 | P10: =COUNTA(S10:AB10) -> 0 | Q10: =IF(COUNTA(S10:AB10)=0,"—",_xlfn.TEXTJOIN(", ",TRUE(),S10:AB10)) -> — | R10: —
A11: 10 | B11: T2 | C11: Ramal | D11: Ramal P-131 | E11: RL1 | F11: poste P-131 | G11: 03-D | I11: DJ | J11: RL1 | N11: =COUNTIFS(Trechos!$L$2:$L$134,A11) -> 5 | O11: =SUMIFS(Trechos!$F$2:$F$134,Trechos!$L$2:$L$134,A11) -> 219.75282 | P11: =COUNTA(S11:AB11) -> 1 | Q11: =IF(COUNTA(S11:AB11)=0,"—",_xlfn.TEXTJOIN(", ",TRUE(),S11:AB11)) -> 03-D | R11: — | S11: 03-D
A12: 11 | B12: T3 | C12: Ramal | D12: Ramal P-131 | E12: 03-D | F12: 03-D | G12: fim P-135 | I12: DJ | J12: RL1 | K12: 03-D | N12: =COUNTIFS(Trechos!$L$2:$L$134,A12) -> 5 | O12: =SUMIFS(Trechos!$F$2:$F$134,Trechos!$L$2:$L$134,A12) -> 219.75282 | P12: =COUNTA(S12:AB12) -> 0 | Q12: =IF(COUNTA(S12:AB12)=0,"—",_xlfn.TEXTJOIN(", ",TRUE(),S12:AB12)) -> — | R12: —
A13: 12 | B13: T2 | C13: Ramal | D13: Ramal P-138 | E13: RL1 | F13: poste P-138 | G13: fim P-140 | I13: DJ | J13: RL1 | N13: =COUNTIFS(Trechos!$L$2:$L$134,A13) -> 8 | O13: =SUMIFS(Trechos!$F$2:$F$134,Trechos!$L$2:$L$134,A13) -> 319.64046 | P13: =COUNTA(S13:AB13) -> 0 | Q13: =IF(COUNTA(S13:AB13)=0,"—",_xlfn.TEXTJOIN(", ",TRUE(),S13:AB13)) -> — | R13: —
A14: 13 | B14: T2 | C14: Ramal | D14: Ramal após RL3 | E14: RL3 | F14: RL3 | G14: fim P-171 | I14: DJ | J14: RL1 | K14: RL2 | L14: RL3 | N14: =COUNTIFS(Trechos!$L$2:$L$134,A14) -> 4 | O14: =SUMIFS(Trechos!$F$2:$F$134,Trechos!$L$2:$L$134,A14) -> 159.82023 | P14: =COUNTA(S14:AB14) -> 0 | Q14: =IF(COUNTA(S14:AB14)=0,"—",_xlfn.TEXTJOIN(", ",TRUE(),S14:AB14)) -> — | R14: —
A15: 14 | B15: T3 | C15: Ramal | D15: Ramal após 03-E | E15: 03-E | F15: 03-E | G15: 03-F | H15: fim P-195 | I15: DJ | J15: RL1 | K15: RL2 | L15: 03-E | N15: =COUNTIFS(Trechos!$L$2:$L$134,A15) -> 18 | O15: =SUMIFS(Trechos!$F$2:$F$134,Trechos!$L$2:$L$134,A15) -> 719.18825 | P15: =COUNTA(S15:AB15) -> 1 | Q15: =IF(COUNTA(S15:AB15)=0,"—",_xlfn.TEXTJOIN(", ",TRUE(),S15:AB15)) -> 03-F | R15: 88-B | S15: 03-F
A16: 15 | B16: T4 | C16: Ramal | D16: Ramal após 03-E | E16: 03-F | F16: 03-F | G16: fim P-199 | I16: DJ | J16: RL1 | K16: RL2 | L16: 03-E | M16: 03-F | N16: =COUNTIFS(Trechos!$L$2:$L$134,A16) -> 4 | O16: =SUMIFS(Trechos!$F$2:$F$134,Trechos!$L$2:$L$134,A16) -> 159.82023 | P16: =COUNTA(S16:AB16) -> 0 | Q16: =IF(COUNTA(S16:AB16)=0,"—",_xlfn.TEXTJOIN(", ",TRUE(),S16:AB16)) -> — | R16: —
A17: TOTAL | N17: =SUM(N2:N16) -> 133 | O17: =SUM(O2:O16) -> 5473.8051

Sheet Por bloco
A1: Bloco | B1: Zona | C1: Tronco/Ramal | D1: Ramal | E1: Ativo de referência | F1: Trecho | G1: Poste início | H1: Poste fim | I1: Extensão (m) | J1: Distância do ativo de referência até o fim (m) | K1: Outra chave no fim do vão (88…) | L1: Próximos ativos | M1: Outras chaves no bloco (88…) | N1: Ativos posteriores
A2: 1 | B2: T1 | C2: Tronco | D2: Tronco | E2: DJ | F2: =COUNTIFS(Trechos!$L$2:$L$134,A2)&" vãos" -> 15 vãos | I2: =SUMIFS(Trechos!$F$2:$F$134,Trechos!$L$2:$L$134,A2) -> 659.25076 | L2: RL1 | M2: — | N2: =Blocos!Q2 -> RL1, RL2, RL3, 03-E, 03-F, 03-D, 03-C, RL-A, 03-A, 03-B
F3: TR-001 | G3: P-201 | H3: P-214 | I3: 43.950051 | J3: 43.950051
F4: TR-002 | G4: P-214 | H4: P-215 | I4: 43.950051 | J4: 87.900102
F5: TR-003 | G5: P-215 | H5: P-216 | I5: 43.950051 | J5: 131.85015
F6: TR-004 | G6: P-216 | H6: P-217 | I6: 43.950051 | J6: 175.8002
F7: TR-005 | G7: P-217 | H7: P-102 | I7: 43.950051 | J7: 219.75025
F8: TR-006 | G8: P-102 | H8: P-218 | I8: 43.950051 | J8: 263.70031
F9: TR-007 | G9: P-218 | H9: P-219 | I9: 43.950051 | J9: 307.65036
F10: TR-008 | G10: P-219 | H10: P-220 | I10: 43.950051 | J10: 351.60041
F11: TR-009 | G11: P-220 | H11: P-221 | I11: 43.950051 | J11: 395.55046
F12: TR-010 | G12: P-221 | H12: P-105 | I12: 43.950051 | J12: 439.50051
F13: TR-011 | G13: P-105 | H13: P-222 | I13: 43.950051 | J13: 483.45056
F14: TR-012 | G14: P-222 | H14: P-223 | I14: 43.950051 | J14: 527.40061
... F17: TR-015 | G17: P-225 | H17: P-202 | I17: 43.950051 | J17: 659.25076
A18: 2 | B18: T2 | C18: Tronco | D18: Tronco | E18: RL1 | F18: =COUNTIFS(Trechos!$L$2:$L$134,A18)&" vãos" -> 16 vãos | I18: =SUMIFS(Trechos!$F$2:$F$134,Trechos!$L$2:$L$134,A18) -> 659.25076 | L18: RL2 | M18: 88-A | N18: =Blocos!Q3 -> RL2, RL3, 03-E, 03-F, 03-D
F19: TR-016 | G19: P-202 | H19: P-226 | I19: 43.950051 | J19: 43.950051
F20: TR-017 | G20: P-226 | H20: P-227 | I20: 43.950051 | J20: 87.900102
F21: TR-018 | G21: P-227 | H21: P-228 | I21: 43.950051 | J21: 131.85015
F22: TR-019 | G22: P-228 | H22: P-229 | I22: 43.950051 | J22: 175.8002
F23: TR-020 | G23: P-229 | H23: P-131 | I23: 43.950051 | J23: 219.75025
F24: TR-021 | G24: P-131 | H24: P-230 | I24: 36.625042 | J24: 256.3753
F25: TR-022 | G25: P-230 | H25: P-231 | I25: 36.625042 | J25: 293.00034
F26: TR-023 | G26: P-231 | H26: P-203 | I26: 36.625042 | J26: 329.62538 | K26: 88-A
F27: TR-024 | G27: P-203 | H27: P-232 | I27: 36.625042 | J27: 366.25042
F28: TR-025 | G28: P-232 | H28: P-233 | I28: 36.625042 | J28: 402.87547
F29: TR-026 | G29: P-233 | H29: P-138 | I29: 36.625042 | J29: 439.50051
F30: TR-027 | G30: P-138 | H30: P-234 | I30: 43.950051 | J30: 483.45056
F31: TR-028 | G31: P-234 | H31: P-235 | I31: 43.950051 | J31: 527.40061
F32: TR-029 | G32: P-235 | H32: P-236 | I32: 43.950051 | J32: 571.35066
F33: TR-030 | G33: P-236 | H33: P-237 | I33: 43.950051 | J33: 615.30071
F34: TR-031 | G34: P-237 | H34: P-204 | I34: 43.950051 | J34: 659.25076
A35: 3 | B35: T2 | C35: Tronco | D35: Tronco | E35: RL2 | F35: =COUNTIFS(Trechos!$L$2:$L$134,A35)&" vãos" -> 17 vãos | I35: =SUMIFS(Trechos!$F$2:$F$134,Trechos!$L$2:$L$134,A35) -> 679.23039 | L35: RL3 / 03-E | M35: — | N35: =Blocos!Q4 -> RL3, 03-E, 03-F
F36: TR-032 | G36: P-204 | H36: P-238 | I36: 39.954592 | J36: 39.954592
F37: TR-033 | G37: P-238 | H37: P-239 | I37: 39.954592 | J37: 79.909184
F38: TR-034 | G38: P-239 | H38: P-240 | I38: 39.954592 | J38: 119.86378
F39: TR-035 | G39: P-240 | H39: P-241 | I39: 39.954592 | J39: 159.81837
F40: TR-036 | G40: P-241 | H40: P-242 | I40: 39.954592 | J40: 199.77296
F41: TR-037 | G41: P-242 | H41: P-160 | I41: 39.954592 | J41: 239.72755
F42: TR-038 | G42: P-160 | H42: P-243 | I42: 39.955058 | J42: 279.68261
...

Sheet Trechos
A1: Seq | B1: Trecho | C1: Trecho no Daimon | D1: Poste início | E1: Poste fim | F1: Extensão (m) | G1: Distância do DJ até o fim (m) | H1: Distância do ativo de referência até o fim (m) | I1: Zona | J1: Tronco/Ramal | K1: Ramal | L1: Bloco | M1: Ativo de referência | N1: Tipo do ativo de referência | O1: Próximo(s) ativo(s) | P1: Ativos posteriores englobados | Q1: Qtd. ativos posteriores | R1: Outra chave no fim do vão (88…) | S1: Nível 1 | T1: Nível 2 | U1: Nível 3 | V1: Nível 4 | W1: Nível 5 | X1: Caminho desde o DJ | Y1: Latitude (meio do vão) | Z1: Longitude (meio do vão) | AA1: Mapa | AB1: Chave do caminho (uso das fórmulas)
A2: 1 | B2: TR-001 | D2: P-201 | E2: P-214 | F2: 43.950051 | G2: 43.950051 | H2: 43.950051 | I2: T1 | J2: Tronco | K2: Tronco | L2: 1 | M2: DJ | N2: Disjuntor (DJ) | O2: RL1 | P2: RL1, RL2, RL3, 03-E, 03-F, 03-D, 03-C, RL-A, 03-A, 03-B | Q2: 10 | S2: DJ | X2: DJ | Y2: -9.6039526 | Z2: -48.448706 | AA2: abrir | AB2: |DJ|
A3: 2 | B3: TR-002 | D3: P-214 | E3: P-215 | F3: 43.950051 | G3: 87.900102 | H3: 87.900102 | I3: T1 | J3: Tronco | K3: Tronco | L3: 1 | M3: DJ | N3: Disjuntor (DJ) | O3: RL1 | P3: RL1, RL2, RL3, 03-E, 03-F, 03-D, 03-C, RL-A, 03-A, 03-B | Q3: 10 | S3: DJ | X3: DJ | Y3: -9.6039526 | Z3: -48.448305 | AA3: abrir | AB3: |DJ|
A4: 3 | B4: TR-003 | D4: P-215 | E4: P-216 | F4: 43.950051 | G4: 131.85015 | H4: 131.85015 | I4: T1 | J4: Tronco | K4: Tronco | L4: 1 | M4: DJ | N4: Disjuntor (DJ) | O4: RL1 | P4: RL1, RL2, RL3, 03-E, 03-F, 03-D, 03-C, RL-A, 03-A, 03-B | Q4: 10 | S4: DJ | X4: DJ | Y4: -9.6039526 | Z4: -48.447904 | AA4: abrir | AB4: |DJ|
A5: 4 | B5: TR-004 | D5: P-216 | E5: P-217 | F5: 43.950051 | G5: 175.8002 | H5: 175.8002 | I5: T1 | J5: Tronco | K5: Tronco | L5: 1 | M5: DJ | N5: Disjuntor (DJ) | O5: RL1 | P5: RL1, RL2, RL3, 03-E, 03-F, 03-D, 03-C, RL-A, 03-A, 03-B | Q5: 10 | S5: DJ | X5: DJ | Y5: -9.6039526 | Z5: -48.447504 | AA5: abrir | AB5: |DJ|
A6: 5 | B6: TR-005 | D6: P-217 | E6: P-102 | F6: 43.950051 | G6: 219.75025 | H6: 219.75025 | I6: T1 | J6: Tronco | K6: Tronco | L6: 1 | M6: DJ | N6: Disjuntor (DJ) | O6: RL1 | P6: RL1, RL2, RL3, 03-E, 03-F, 03-D, 03-C, RL-A, 03-A, 03-B | Q6: 10 | S6: DJ | X6: DJ | Y6: -9.6039526 | Z6: -48.447103 | AA6: abrir | AB6: |DJ|
A7: 6 | B7: TR-006 | D7: P-102 | E7: P-218 | F7: 43.950051 | G7: 263.70031 | H7: 263.70031 | I7: T1 | J7: Tronco | K7: Tronco | L7: 1 | M7: DJ | N7: Disjuntor (DJ) | O7: RL1 | P7: RL1, RL2, RL3, 03-E, 03-F, 03-D, 03-C | Q7: 7 | S7: DJ | X7: DJ | Y7: -9.6039526 | Z7: -48.446702 | AA7: abrir | AB7: |DJ|
A8: 7 | B8: TR-007 | D8: P-218 | E8: P-219 | F8: 43.950051 | G8: 307.65036 | H8: 307.65036 | I8: T1 | J8: Tronco | K8: Tronco | L8: 1 | M8: DJ | N8: Disjuntor (DJ) | O8: RL1 | P8: RL1, RL2, RL3, 03-E, 03-F, 03-D, 03-C | Q8: 7 | S8: DJ | X8: DJ | Y8: -9.6039526 | Z8: -48.446301 | AA8: abrir | AB8: |DJ|
A9: 8 | B9: TR-008 | D9: P-219 | E9: P-220 | F9: 43.950051 | G9: 351.60041 | H9: 351.60041 | I9: T1 | J9: Tronco | K9: Tronco | L9: 1 | M9: DJ | N9: Disjuntor (DJ) | O9: RL1 | P9: RL1, RL2, RL3, 03-E, 03-F, 03-D, 03-C | Q9: 7 | S9: DJ | X9: DJ | Y9: -9.6039526 | Z9: -48.4459 | AA9: abrir | AB9: |DJ|
A10: 9 | B10: TR-009 | D10: P-220 | E10: P-221 | F10: 43.950051 | G10: 395.55046 | H10: 395.55046 | I10: T1 | J10: Tronco | K10: Tronco | L10: 1 | M10: DJ | N10: Disjuntor (DJ) | O10: RL1 | P10: RL1, RL2, RL3, 03-E, 03-F, 03-D, 03-C | Q10: 7 | S10: DJ | X10: DJ | Y10: -9.6039526 | Z10: -48.445499 | AA10: abrir | AB10: |DJ|
A11: 10 | B11: TR-010 | D11: P-221 | E11: P-105 | F11: 43.950051 | G11: 439.50051 | H11: 439.50051 | I11: T1 | J11: Tronco | K11: Tronco | L11: 1 | M11: DJ | N11: Disjuntor (DJ) | O11: RL1 | P11: RL1, RL2, RL3, 03-E, 03-F, 03-D, 03-C | Q11: 7 | S11: DJ | X11: DJ | Y11: -9.6039526 | Z11: -48.445098 | AA11: abrir | AB11: |DJ|
A12: 11 | B12: TR-011 | D12: P-105 | E12: P-222 | F12: 43.950051 | G12: 483.45056 | H12: 483.45056 | I12: T1 | J12: Tronco | K12: Tronco | L12: 1 | M12: DJ | N12: Disjuntor (DJ) | O12: RL1 | P12: RL1, RL2, RL3, 03-E, 03-F, 03-D | Q12: 6 | S12: DJ | X12: DJ | Y12: -9.6039526 | Z12: -48.444698 | AA12: abrir | AB12: |DJ|
A13: 12 | B13: TR-012 | D13: P-222 | E13: P-223 | F13: 43.950051 | G13: 527.40061 | H13: 527.40061 | I13: T1 | J13: Tronco | K13: Tronco | L13: 1 | M13: DJ | N13: Disjuntor (DJ) | O13: RL1 | P13: RL1, RL2, RL3, 03-E, 03-F, 03-D | Q13: 6 | S13: DJ | X13: DJ | Y13: -9.6039526 | Z13: -48.444297 | AA13: abrir | AB13: |DJ|
... A16: 15 | B16: TR-015 | D16: P-225 | E16: P-202 | F16: 43.950051 | G16: 659.25076 | H16: 659.25076 | I16: T1 | J16: Tronco | K16: Tronco | L16: 1 | M16: DJ | N16: Disjuntor (DJ) | O16: RL1 | P16: RL1, RL2, RL3, 03-E, 03-F, 03-D | Q16: 6 | S16: DJ | X16: DJ | Y16: -9.6039526 | Z16: -48.443094 | AA16: abrir | AB16: |DJ|
A17: 16 | B17: TR-016 | D17: P-202 | E17: P-226 | F17: 43.950051 | G17: 703.20082 | H17: 43.950051 | I17: T2 | J17: Tronco | K17: Tronco | L17: 2 | M17: RL1 | N17: Religador (79) | O17: RL2 | P17: RL2, RL3, 03-E, 03-F, 03-D | Q17: 5 | S17: DJ | T17: RL1 | X17: DJ › RL1 | Y17: -9.6039526 | Z17: -48.442693 | AA17: abrir | AB17: |DJ|RL1|
A18: 17 | B18: TR-017 | D18: P-226 | E18: P-227 | F18: 43.950051 | G18: 747.15087 | H18: 87.900102 | I18: T2 | J18: Tronco | K18: Tronco | L18: 2 | M18: RL1 | N18: Religador (79) | O18: RL2 | P18: RL2, RL3, 03-E, 03-F, 03-D | Q18: 5 | S18: DJ | T18: RL1 | X18: DJ › RL1 | Y18: -9.6039526 | Z18: -48.442292 | AA18: abrir | AB18: |DJ|RL1|
A19: 18 | B19: TR-018 | D19: P-227 | E19: P-228 | F19: 43.950051 | G19: 791.10092 | H19: 131.85015 | I19: T2 | J19: Tronco | K19: Tronco | L19: 2 | M19: RL1 | N19: Religador (79) | O19: RL2 | P19: RL2, RL3, 03-E, 03-F, 03-D | Q19: 5 | S19: DJ | T19: RL1 | X19: DJ › RL1 | Y19: -9.6039526 | Z19: -48.441891 | AA19: abrir | AB19: |DJ|RL1|
A20: 19 | B20: TR-019 | D20: P-228 | E20: P-229 | F20: 43.950051 | G20: 835.05097 | H20: 175.8002 | I20: T2 | J20: Tronco | K20: Tronco | L20: 2 | M20: RL1 | N20: Religador (79) | O20: RL2 | P20: RL2, RL3, 03-E, 03-F, 03-D | Q20: 5 | S20: DJ | T20: RL1 | X20: DJ › RL1 | Y20: -9.6039526 | Z20: -48.441491 | AA20: abrir | AB20: |DJ|RL1|
A21: 20 | B21: TR-020 | D21: P-229 | E21: P-131 | F21: 43.950051 | G21: 879.00102 | H21: 219.75025 | I21: T2 | J21: Tronco | K21: Tronco | L21: 2 | M21: RL1 | N21: Religador (79) | O21: RL2 | P21: RL2, RL3, 03-E, 03-F, 03-D | Q21: 5 | S21: DJ | T21: RL1 | X21: DJ › RL1 | Y21: -9.6039526 | Z21: -48.44109 | AA21: abrir | AB21: |DJ|RL1|
A22: 21 | B22: TR-021 | D22: P-131 | E22: P-230 | F22: 36.625042 | G22: 915.62606 | H22: 256.3753 | I22: T2 | J22: Tronco | K22: Tronco | L22: 2 | M22: RL1 | N22: Religador (79) | O22: RL2 | P22: RL2, RL3, 03-E, 03-F | Q22: 4 | S22: DJ | T22: RL1 | X22: DJ › RL1 | Y22: -9.6039526 | Z22: -48.440722 | AA22: abrir | AB22: |DJ|RL1|
A23: 22 | B23: TR-022 | D23: P-230 | E23: P-231 | F23: 36.625042 | G23: 952.2511 | H23: 293.00034 | I23: T2 | J23: Tronco | K23: Tronco | L23: 2 | M23: RL1 | N23: Religador (79) | O23: RL2 | P23: RL2, RL3, 03-E, 03-F | Q23: 4 | S23: DJ | T23: RL1 | X23: DJ › RL1 | Y23: -9.6039526 | Z23: -48.440388 | AA23: abrir | AB23: |DJ|RL1|
A24: 23 | B24: TR-023 | D24: P-231 | E24: P-203 | F24: 36.625042 | G24: 988.87615 | H24: 329.62538 | I24: T2 | J24: Tronco | K24: Tronco | L24: 2 | M24: RL1 | N24: Religador (79) | O24: RL2 | P24: RL2, RL3, 03-E, 03-F | Q24: 4 | R24: 88-A | S24: DJ | T24: RL1 | X24: DJ › RL1 | Y24: -9.6039526 | Z24: -48.440054 | AA24: abrir | AB24: |DJ|RL1|
A25: 24 | B25: TR-024 | D25: P-203 | E25: P-232 | F25: 36.625042 | G25: 1025.5012 | H25: 366.25042 | I25: T2 | J25: Tronco | K25: Tronco | L25: 2 | M25: RL1 | N25: Religador (79) | O25: RL2 | P25: RL2, RL3, 03-E, 03-F | Q25: 4 | S25: DJ | T25: RL1 | X25: DJ › RL1 | Y25: -9.6039526 | Z25: -48.43972 | AA25: abrir | AB25: |DJ|RL1|
A26: 25 | B26: TR-025 | D26: P-232 | E26: P-233 | F26: 36.625042 | G26: 1062.1262 | H26: 402.87547 | I26: T2 | J26: Tronco | K26: Tronco | L26: 2 | M26: RL1 | N26: Religador (79) | O26: RL2 | P26: RL2, RL3, 03-E, 03-F | Q26: 4 | S26: DJ | T26: RL1 | X26: DJ › RL1 | Y26: -9.6039526 | Z26: -48.439386 | AA26: abrir | AB26: |DJ|RL1|
A27: 26 | B27: TR-026 | D27: P-233 | E27: P-138 | F27: 36.625042 | G27: 1098.7513 | H27: 439.50051 | I27: T2 | J27: Tronco | K27: Tronco | L27: 2 | M27: RL1 | N27: Religador (79) | O27: RL2 | P27: RL2, RL3, 03-E, 03-F | Q27: 4 | S27: DJ | T27: RL1 | X27: DJ › RL1 | Y27: -9.6039526 | Z27: -48.439052 | AA27: abrir | AB27: |DJ|RL1|
A28: 27 | B28: TR-027 | D28: P-138 | E28: P-234 | F28: 43.950051 | G28: 1142.7013 | H28: 483.45056 | I28: T2 | J28: Tronco | K28: Tronco | L28: 2 | M28: RL1 | N28: Religador (79) | O28: RL2 | P28: RL2, RL3, 03-E, 03-F | Q28: 4 | S28: DJ | T28: RL1 | X28: DJ › RL1 | Y28: -9.6039526 | Z28: -48.438685 | AA28: abrir | AB28: |DJ|RL1|
A29: 28 | B29: TR-028 | D29: P-234 | E29: P-235 | F29: 43.950051 | G29: 1186.6514 | H29: 527.40061 | I29: T2 | J29: Tronco | K29: Tronco | L29: 2 | M29: RL1 | N29: Religador (79) | O29: RL2 | P29: RL2, RL3, 03-E, 03-F | Q29: 4 | S29: DJ | T29: RL1 | X29: DJ › RL1 | Y29: -9.6039526 | Z29: -48.438284 | AA29: abrir | AB29: |DJ|RL1|
A30: 29 | B30: TR-029 | D30: P-235 | E30: P-236 | F30: 43.950051 | G30: 1230.6014 | H30: 571.35066 | I30: T2 | J30: Tronco | K30: Tronco | L30: 2 | M30: RL1 | N30: Religador (79) | O30: RL2 | P30: RL2, RL3, 03-E, 03-F | Q30: 4 | S30: DJ | T30: RL1 | X30: DJ › RL1 | Y30: -9.6039526 | Z30: -48.437883 | AA30: abrir | AB30: |DJ|RL1|
A31: 30 | B31: TR-030 | D31: P-236 | E31: P-237 | F31: 43.950051 | G31: 1274.5515 | H31: 615.30071 | I31: T2 | J31: Tronco | K31: Tronco | L31: 2 | M31: RL1 | N31: Religador (79) | O31: RL2 | P31: RL2, RL3, 03-E, 03-F | Q31: 4 | S31: DJ | T31: RL1 | X31: DJ › RL1 | Y31: -9.6039526 | Z31: -48.437482 | AA31: abrir | AB31: |DJ|RL1|
A32: 31 | B32: TR-031 | D32: P-237 | E32: P-204 | F32: 43.950051 | G32: 1318.5015 | H32: 659.25076 | I32: T2 | J32: Tronco | K32: Tronco | L32: 2 | M32: RL1 | N32: Religador (79) | O32: RL2 | P32: RL2, RL3, 03-E, 03-F | Q32: 4 | S32: DJ | T32: RL1 | X32: DJ › RL1 | Y32: -9.6039526 | Z32: -48.437081 | AA32: abrir | AB32: |DJ|RL1|
A33: 32 | B33: TR-032 | D33: P-204 | E33: P-238 | F33: 39.954592 | G33: 1358.4561 | H33: 39.954592 | I33: T2 | J33: Tronco | K33: Tronco | L33: 3 | M33: RL2 | N33: Religador (79) | O33: RL3 / 03-E | P33: RL3, 03-E, 03-F | Q33: 3 | S33: DJ | T33: RL1 | U33: RL2 | X33: DJ › RL1 › RL2 | Y33: -9.6039526 | Z33: -48.436698 | AA33: abrir | AB33: |DJ|RL1|RL2|
A34: 33 | B34: TR-033 | D34: P-238 | E34: P-239 | F34: 39.954592 | G34: 1398.4107 | H34: 79.909184 | I34: T2 | J34: Tronco | K34: Tronco | L34: 3 | M34: RL2 | N34: Religador (79) | O34: RL3 / 03-E | P34: RL3, 03-E, 03-F | Q34: 3 | S34: DJ | T34: RL1 | U34: RL2 | X34: DJ › RL1 › RL2 | Y34: -9.6039526 | Z34: -48.436334 | AA34: abrir | AB34: |DJ|RL1|RL2|
A35: 34 | B35: TR-034 | D35: P-239 | E35: P-240 | F35: 39.954592 | G35: 1438.3653 | H35: 119.86378 | I35: T2 | J35: Tronco | K35: Tronco | L35: 3 | M35: RL2 | N35: Religador (79) | O35: RL3 / 03-E | P35: RL3, 03-E, 03-F | Q35: 3 | S35: DJ | T35: RL1 | U35: RL2 | X35: DJ › RL1 › RL2 | Y35: -9.6039526 | Z35: -48.435969 | AA35: abrir | AB35: |DJ|RL1|RL2|
A36: 35 | B36: TR-035 | D36: P-240 | E36: P-241 | F36: 39.954592 | G36: 1478.3199 | H36: 159.81837 | I36: T2 | J36: Tronco | K36: Tronco | L36: 3 | M36: RL2 | N36: Religador (79) | O36: RL3 / 03-E | P36: RL3, 03-E, 03-F | Q36: 3 | S36: DJ | T36: RL1 | U36: RL2 | X36: DJ › RL1 › RL2 | Y36: -9.6039526 | Z36: -48.435605 | AA36: abrir | AB36: |DJ|RL1|RL2|
A37: 36 | B37: TR-036 | D37: P-241 | E37: P-242 | F37: 39.954592 | G37: 1518.2745 | H37: 199.77296 | I37: T2 | J37: Tronco | K37: Tronco | L37: 3 | M37: RL2 | N37: Religador (79) | O37: RL3 / 03-E | P37: RL3, 03-E, 03-F | Q37: 3 | S37: DJ | T37: RL1 | U37: RL2 | X37: DJ › RL1 › RL2 | Y37: -9.6039526 | Z37: -48.435241 | AA37: abrir | AB37: |DJ|RL1|RL2|
A38: 37 | B38: TR-037 | D38: P-242 | E38: P-160 | F38: 39.954592 | G38: 1558.2291 | H38: 239.72755 | I38: T2 | J38: Tronco | K38: Tronco | L38: 3 | M38: RL2 | N38: Religador (79) | O38: RL3 / 03-E | P38: RL3, 03-E, 03-F | Q38: 3 | S38: DJ | T38: RL1 | U38: RL2 | X38: DJ › RL1 › RL2 | Y38: -9.6039526 | Z38: -48.434876 | AA38: abrir | AB38: |DJ|RL1|RL2|
A39: 38 | B39: TR-038 | D39: P-160 | E39: P-243 | F39: 39.955058 | G39: 1598.1841 | H39: 279.68261 | I39: T2 | J39: Tronco | K39: Tronco | L39: 3 | M39: RL2 | N39: Religador (79) | O39: RL3 / 03-E | P39: RL3 | Q39: 1 | S39: DJ | T39: RL1 | U39: RL2 | X39: DJ › RL1 › RL2 | Y39: -9.6037729 | Z39: -48.434694 | AA39: abrir | AB39: |DJ|RL1|RL2|
A40: 39 | B40: TR-039 | D40: P-243 | E40: P-244 | F40: 39.955058 | G40: 1638.1392 | H40: 319.63767 | I40: T2 | J40: Tronco | K40: Tronco | L40: 3 | M40: RL2 | N40: Religador (79) | O40: RL3 / 03-E | P40: RL3 | Q40: 1 | S40: DJ | T40: RL1 | U40: RL2 | X40: DJ › RL1 › RL2 | Y40: -9.6034136 | Z40: -48.434694 | AA40: abrir | AB40: |DJ|RL1|RL2|
A41: 40 | B41: TR-040 | D41: P-244 | E41: P-245 | F41: 39.955058 | G41: 1678.0943 | H41: 359.59273 | I41: T2 | J41: Tronco | K41: Tronco | L41: 3 | M41: RL2 | N41: Religador (79) | O41: RL3 / 03-E | P41: RL3 | Q41: 1 | S41: DJ | T41: RL1 | U41: RL2 | X41: DJ › RL1 › RL2 | Y41: -9.6030543 | Z41: -48.434694 | AA41: abrir | AB41: |DJ|RL1|RL2|
A42: 41 | B42: TR-041 | D42: P-245 | E42: P-246 | F42: 39.955058 | G42: 1718.0493 | H42: 399.54778 | I42: T2 | J42: Tronco | K42: Tronco | L42: 3 | M42: RL2 | N42: Religador (79) | O42: RL3 / 03-E | P42: RL3 | Q42: 1 | S42: DJ | T42: RL1 | U42: RL2 | X42: DJ › RL1 › RL2 | Y42: -9.6026949 | Z42: -48.434694 | AA42: abrir | AB42: |DJ|RL1|RL2|
...

Sheet Ativos
A1: Ativo | B1: Tipo | C1: Poste | D1: No tronco | E1: Zona antes | F1: Zona depois | G1: Bloco onde está | H1: Blocos em que é referência | I1: Caminho desde o DJ | J1: Vãos em que é a referência | K1: Extensão em que é a referência (m) | L1: Vãos englobados (tudo a jusante) | M1: Extensão englobada (m) | N1: Ativos posteriores englobados | O1: Latitude | P1: Longitude | Q1: Mapa
A2: DJ | B2: Disjuntor (DJ) | C2: P-201 | D2: sim | E2: — | F2: T1 | G2: — | H2: 1, 4, 8 | I2: DJ | J2: =COUNTIFS(Trechos!$M$2:$M$134,A2) -> 25 | K2: =SUMIFS(Trechos!$F$2:$F$134,Trechos!$M$2:$M$134,A2) -> 1058.8013 | L2: =SUMPRODUCT(--ISNUMBER(SEARCH("|"&A2&"|",Trechos!$AB$2:$AB$134))) -> 133 | M2: =SUMPRODUCT(ISNUMBER(SEARCH("|"&A2&"|",Trechos!$AB$2:$AB$134))*Trechos!$F$2:$F$134) -> 5473.8051 | N2: RL1, RL2, RL3, 03-E, 03-F, 03-D, 03-C, RL-A, 03-A, 03-B | O2: -9.6039526 | P2: -48.448907 | Q2: abrir
A3: RL1 | B3: Religador (79) | C3: P-202 | D3: sim | E3: T1 | F3: T2 | G3: 1 | H3: 2, 10, 12 | I3: DJ › RL1 | J3: =COUNTIFS(Trechos!$M$2:$M$134,A3) -> 29 | K3: =SUMIFS(Trechos!$F$2:$F$134,Trechos!$M$2:$M$134,A3) -> 1198.644 | L3: =SUMPRODUCT(--ISNUMBER(SEARCH("|"&A3&"|",Trechos!$AB$2:$AB$134))) -> 77 | M3: =SUMPRODUCT(ISNUMBER(SEARCH("|"&A3&"|",Trechos!$AB$2:$AB$134))*Trechos!$F$2:$F$134) -> 3136.456 | N3: RL2, RL3, 03-E, 03-F, 03-D | O3: -9.6039526 | P3: -48.442894 | Q3: abrir
A4: 88-A | B4: Chave 88 | C4: P-203 | D4: sim | E4: T2 | F4: T2 | G4: 2 | H4: — | I4: DJ › RL1 | N4: RL2, RL3, 03-E, 03-F | O4: -9.6039526 | P4: -48.439887 | Q4: abrir
A5: RL2 | B5: Religador (79) | C5: P-204 | D5: sim | E5: T2 | F5: T2 | G5: 2 | H5: 3 | I5: DJ › RL1 › RL2 | J5: =COUNTIFS(Trechos!$M$2:$M$134,A5) -> 17 | K5: =SUMIFS(Trechos!$F$2:$F$134,Trechos!$M$2:$M$134,A5) -> 679.23039 | L5: =SUMPRODUCT(--ISNUMBER(SEARCH("|"&A5&"|",Trechos!$AB$2:$AB$134))) -> 43 | M5: =SUMPRODUCT(ISNUMBER(SEARCH("|"&A5&"|",Trechos!$AB$2:$AB$134))*Trechos!$F$2:$F$134) -> 1718.0591 | N5: RL3, 03-E, 03-F | O5: -9.6039526 | P5: -48.436881 | Q5: abrir
A6: RL3 | B6: Religador (79) | C6: P-205 | D6: sim | E6: T2 | F6: T2 | G6: 3 | H6: 13 | I6: DJ › RL1 › RL2 › RL3 | J6: =COUNTIFS(Trechos!$M$2:$M$134,A6) -> 4 | K6: =SUMIFS(Trechos!$F$2:$F$134,Trechos!$M$2:$M$134,A6) -> 159.82023 | L6: =SUMPRODUCT(--ISNUMBER(SEARCH("|"&A6&"|",Trechos!$AB$2:$AB$134))) -> 4 | M6: =SUMPRODUCT(ISNUMBER(SEARCH("|"&A6&"|",Trechos!$AB$2:$AB$134))*Trechos!$F$2:$F$134) -> 159.82023 | N6: — | O6: -9.6021559 | P6: -48.434694 | Q6: abrir
A7: 03-E | B7: Chave fusível (03) | C7: P-206 | D7: sim | E7: T2 | F7: T3 | G7: 3 | H7: 14 | I7: DJ › RL1 › RL2 › 03-E | J7: =COUNTIFS(Trechos!$M$2:$M$134,A7) -> 18 | K7: =SUMIFS(Trechos!$F$2:$F$134,Trechos!$M$2:$M$134,A7) -> 719.18825 | L7: =SUMPRODUCT(--ISNUMBER(SEARCH("|"&A7&"|",Trechos!$AB$2:$AB$134))) -> 22 | M7: =SUMPRODUCT(ISNUMBER(SEARCH("|"&A7&"|",Trechos!$AB$2:$AB$134))*Trechos!$F$2:$F$134) -> 879.00848 | N7: 03-F | O7: -9.6039526 | P7: -48.432507 | Q7: abrir
A8: RL-A | B8: Religador (79) | C8: P-209 | D8: não | E8: T1 | F8: T2 | G8: 4 | H8: 5 | I8: DJ › RL-A | J8: =COUNTIFS(Trechos!$M$2:$M$134,A8) -> 5 | K8: =SUMIFS(Trechos!$F$2:$F$134,Trechos!$M$2:$M$134,A8) -> 219.75282 | L8: =SUMPRODUCT(--ISNUMBER(SEARCH("|"&A8&"|",Trechos!$AB$2:$AB$134))) -> 27 | M8: =SUMPRODUCT(ISNUMBER(SEARCH("|"&A8&"|",Trechos!$AB$2:$AB$134))*Trechos!$F$2:$F$134) -> 1118.7276 | N8: 03-A, 03-B | O8: -9.6057492 | P8: -48.446902 | Q8: abrir
A9: 03-A | B9: Chave fusível (03) | C9: P-210 | D9: não | E9: T2 | F9: T3 | G9: 5 | H9: 6 | I9: DJ › RL-A › 03-A | J9: =COUNTIFS(Trechos!$M$2:$M$134,A9) -> 16 | K9: =SUMIFS(Trechos!$F$2:$F$134,Trechos!$M$2:$M$134,A9) -> 659.25115 | L9: =SUMPRODUCT(--ISNUMBER(SEARCH("|"&A9&"|",Trechos!$AB$2:$AB$134))) -> 22 | M9: =SUMPRODUCT(ISNUMBER(SEARCH("|"&A9&"|",Trechos!$AB$2:$AB$134))*Trechos!$F$2:$F$134) -> 898.97476 | N9: 03-B | O9: -9.6077255 | P9: -48.446902 | Q9: abrir
A10: 03-B | B10: Chave fusível (03) | C10: P-211 | D10: não | E10: T3 | F10: T4 | G10: 6 | H10: 7 | I10: DJ › RL-A › 03-A › 03-B | J10: =COUNTIFS(Trechos!$M$2:$M$134,A10) -> 6 | K10: =SUMIFS(Trechos!$F$2:$F$134,Trechos!$M$2:$M$134,A10) -> 239.72361 | L10: =SUMPRODUCT(--ISNUMBER(SEARCH("|"&A10&"|",Trechos!$AB$2:$AB$134))) -> 6 | M10: =SUMPRODUCT(ISNUMBER(SEARCH("|"&A10&"|",Trechos!$AB$2:$AB$134))*Trechos!$F$2:$F$134) -> 239.72361 | N10: — | O10: -9.6095221 | P10: -48.444534 | Q10: abrir
A11: 03-C | B11: Chave fusível (03) | C11: P-212 | D11: não | E11: T1 | F11: T3 | G11: 8 | H11: 9 | I11: DJ › 03-C | J11: =COUNTIFS(Trechos!$M$2:$M$134,A11) -> 4 | K11: =SUMIFS(Trechos!$F$2:$F$134,Trechos!$M$2:$M$134,A11) -> 159.82023 | L11: =SUMPRODUCT(--ISNUMBER(SEARCH("|"&A11&"|",Trechos!$AB$2:$AB$134))) -> 4 | M11: =SUMPRODUCT(ISNUMBER(SEARCH("|"&A11&"|",Trechos!$AB$2:$AB$134))*Trechos!$F$2:$F$134) -> 159.82023 | N11: — | O11: -9.6021559 | P11: -48.444898 | Q11: abrir
A12: 03-D | B12: Chave fusível (03) | C12: P-213 | D12: não | E12: T2 | F12: T3 | G12: 10 | H12: 11 | I12: DJ › RL1 › 03-D | J12: =COUNTIFS(Trechos!$M$2:$M$134,A12) -> 5 | K12: =SUMIFS(Trechos!$F$2:$F$134,Trechos!$M$2:$M$134,A12) -> 219.75282 | L12: =SUMPRODUCT(--ISNUMBER(SEARCH("|"&A12&"|",Trechos!$AB$2:$AB$134))) -> 5 | M12: =SUMPRODUCT(ISNUMBER(SEARCH("|"&A12&"|",Trechos!$AB$2:$AB$134))*Trechos!$F$2:$F$134) -> 219.75282 | N12: — | O12: -9.6059289 | P12: -48.440889 | Q12: abrir
A13: 88-B | B13: Chave 88 | C13: P-207 | D13: não | E13: T3 | F13: T3 | G13: 14 | H13: — | I13: DJ › RL1 › RL2 › 03-E | N13: 03-F | O13: -9.6039526 | P13: -48.43105 | Q13: abrir
A14: 03-F | B14: Chave fusível (03) | C14: P-208 | D14: não | E14: T3 | F14: T4 | G14: 14 | H14: 15 | I14: DJ › RL1 › RL2 › 03-E › 03-F | J14: =COUNTIFS(Trechos!$M$2:$M$134,A14) -> 4 | K14: =SUMIFS(Trechos!$F$2:$F$134,Trechos!$M$2:$M$134,A14) -> 159.82023 | L14: =SUMPRODUCT(--ISNUMBER(SEARCH("|"&A14&"|",Trechos!$AB$2:$AB$134))) -> 4 | M14: =SUMPRODUCT(ISNUMBER(SEARCH("|"&A14&"|",Trechos!$AB$2:$AB$134))*Trechos!$F$2:$F$134) -> 159.82023 | N14: — | O14: -9.6021559 | P14: -48.430321 | Q14: abrir
