Workbook

Sheet Leia-me
A1: Zonas, ramais e blocos — AL01048007
A3: Zona | B3: T1 do DJ ao 1º religador (79). Depois de qualquer religador é T2, inclusive religador em ramal: religador nunca cria T3. Depois de uma chave fusível (03) é no mínimo T3; se já estava em T3 ou mais, soma uma.
A4: Seccionamento | B4: Chave 03/33/02 com religador depois dela não conta como fusível: não muda a zona e aparece em "Outras chaves no bloco (88…)" como "Chave 03 de seccionamento".
A5: Tronco | B5: Caminho DJ → 1º religador → 2º religador e, depois do 2º, até os próximos ativos (religador ou fusível): o trecho entre dois ativos do tronco ainda é tronco. Pontas sem equipamento são ramal. Nunca tem T3. O resto é ramal, com o nome do poste onde sai do tronco.
A6: Ativo de referência | B6: Último DJ, 79 ou 03 antes do vão, vindo do DJ. Ele engloba o vão e tudo o que vem depois.
A7: Ativos posteriores englobados | B7: Os DJ/79/03 que ficam depois do vão ou do bloco. Se o ativo de referência abrir, todos ficam sem energia.
A8: Bloco | B8: Vãos com o mesmo ativo de referência e o mesmo ramal (de um ativo até o próximo). Chaves 88 e outras que não são DJ/79/fusível não dividem bloco: aparecem na coluna "Outras chaves no bloco (88…)". Chaves 02 e 33 contam como fusível.
A9: Nível 1…N | B9: Sequência de ativos desde o DJ até o ativo de referência. Filtrar um nível mostra tudo o que fica depois daquele ativo.
A10: Distâncias | B10: Calculadas a partir das coordenadas (haversine, raio 6.371 km), seguindo a rede.
A11: Abas | B11: Árvore de blocos: visão rápida da sequência, agrupada por tronco e ramal. Consulta: digite um poste e veja onde ele está. Blocos: um bloco por linha, com os ativos posteriores um por coluna e juntos numa coluna só. Por bloco: os vãos agrupados embaixo de cada bloco (botão + à esquerda). Trechos: um vão por linha. Ativos: resumo por ativo.
A12: Aviso | B12: Alimentador sem 2º religador: o tronco seguiu o lado com mais rede T1/T2 e parou antes de chave 03.
A14: Cores das zonas
A15: T1
A16: T2
A17: T3
A18: T4
A19: T5

Sheet Árvore de blocos
A1: Árvore de blocos — AL01048007
A2: Cada linha é um bloco. A célula colorida é o ativo de referência do bloco (cor da zona). As células em cinza à esquerda são os ativos antes dele, desde o DJ.
A3: Zonas: | B3: T1 | C3: T2 | D3: T3 | E3: T4 | F3: T5
A5: Bloco | B5: Zona | C5: Nível 1 | D5: Nível 2 | E5: Nível 3 | F5: Nível 4 | G5: Nível 5 | H5: De | I5: Até (próximos ativos) | J5: Vãos | K5: Extensão (m) | L5: Outras chaves no bloco (88…) | M5: Ativos englobados (depois do bloco)
A6: TRONCO — do DJ ao 2º religador e até os próximos ativos
A7: 1 | B7: T1 | C7: DJ AL01048007 | H7: DJ AL01048007 | I7: 7925573007 | J7: =COUNTIFS(Trechos!$L$2:$L$275,A7) -> 19 | K7: =SUMIFS(Trechos!$F$2:$F$275,Trechos!$L$2:$L$275,A7) -> 1449.3614 | L7: 8800042007, 8808674007, 8800054007 | M7: =Blocos!AA2 -> 7925573007, 0300040007, 0200038007, 0300111007, 0300115007, 0300145007, 0200114007, 0301201007, 0300109007, 0300068007, 0300070007, 0300073007, 0300074007, 0300065007, 0300062007, 0200061007, 0300057007, 0357094007, 0300056007, 0200055007, 0300050007, 0200475007, 0200047007
A8: 2 | B8: T2 | C8: DJ AL01048007 | D8: 7925573007 | H8: 7925573007 | I8: fim N228 | J8: =COUNTIFS(Trechos!$L$2:$L$275,A8) -> 17 | K8: =SUMIFS(Trechos!$F$2:$F$275,Trechos!$L$2:$L$275,A8) -> 960.40964 | L8: 8800075007 | M8: =Blocos!AA3 -> 0300040007, 0200038007, 0300111007, 0300115007, 0300145007, 0200114007, 0301201007, 0300109007, 0300068007, 0300070007, 0300073007, 0300074007
A9: RAMAL 1478970 — sai do tronco no poste 1478970
A10: 3 | B10: T1 | C10: DJ AL01048007 | H10: DJ AL01048007 | I10: 0300043007 | J10: =COUNTIFS(Trechos!$L$2:$L$275,A10) -> 2 | K10: =SUMIFS(Trechos!$F$2:$F$275,Trechos!$L$2:$L$275,A10) -> 38.914441 | L10: — | M10: =Blocos!AA4 -> 0300043007, 0301038007, 0301039007, 0301117007, 0201291007, 0302253007, 0301273007
A11: 4 | B11: T3 | C11: DJ AL01048007 | D11: 0300043007 | H11: 0300043007 | I11: 0301038007 / fim 69120630 / 0301117007 / fim 299845 / 0301273007 | J11: =COUNTIFS(Trechos!$L$2:$L$275,A11) -> 15 | K11: =SUMIFS(Trechos!$F$2:$F$275,Trechos!$L$2:$L$275,A11) -> 2457.9533 | L11: 386243 | M11: =Blocos!AA5 -> 0301038007, 0301039007, 0301117007, 0201291007, 0302253007, 0301273007
A12: 5 | B12: T4 | C12: DJ AL01048007 | D12: 0300043007 | E12: 0301038007 | H12: 0301038007 | I12: 0301039007 | J12: =COUNTIFS(Trechos!$L$2:$L$275,A12) -> 2 | K12: =SUMIFS(Trechos!$F$2:$F$275,Trechos!$L$2:$L$275,A12) -> 223.13742 | L12: — | M12: =Blocos!AA6 -> 0301039007
A13: 6 | B13: T5 | C13: DJ AL01048007 | D13: 0300043007 | E13: 0301038007 | F13: 0301039007 | H13: 0301039007 | I13: fim 289786 | J13: =COUNTIFS(Trechos!$L$2:$L$275,A13) -> 1 | K13: =SUMIFS(Trechos!$F$2:$F$275,Trechos!$L$2:$L$275,A13) -> 92.473831 | L13: — | M13: =Blocos!AA7 -> —
A14: 7 | B14: T4 | C14: DJ AL01048007 | D14: 0300043007 | E14: 0301117007 | H14: 0301117007 | I14: 0201291007 / 0302253007 / fim 1078155 | J14: =COUNTIFS(Trechos!$L$2:$L$275,A14) -> 37 | K14: =SUMIFS(Trechos!$F$2:$F$275,Trechos!$L$2:$L$275,A14) -> 2136.3104 | L14: — | M14: =Blocos!AA8 -> 0201291007, 0302253007
A15: 8 | B15: T5 | C15: DJ AL01048007 | D15: 0300043007 | E15: 0301117007 | F15: 0201291007 | H15: 0201291007 | I15: fim 315977 | J15: =COUNTIFS(Trechos!$L$2:$L$275,A15) -> 1 | K15: =SUMIFS(Trechos!$F$2:$F$275,Trechos!$L$2:$L$275,A15) -> 16.087812 | L15: — | M15: =Blocos!AA9 -> —
A16: 9 | B16: T5 | C16: DJ AL01048007 | D16: 0300043007 | E16: 0301117007 | F16: 0302253007 | H16: 0302253007 | I16: fim 1088763 / fim 1088774 / fim 1089030 / fim 1088769 / fim N118 / fim 1088761 / fim N120 / fim 1089031 | J16: =COUNTIFS(Trechos!$L$2:$L$275,A16) -> 18 | K16: =SUMIFS(Trechos!$F$2:$F$275,Trechos!$L$2:$L$275,A16) -> 1159.7448 | L16: — | M16: =Blocos!AA10 -> —
A17: 10 | B17: T4 | C17: DJ AL01048007 | D17: 0300043007 | E17: 0301273007 | H17: 0301273007 | I17: fim 309513 | J17: =COUNTIFS(Trechos!$L$2:$L$275,A17) -> 1 | K17: =SUMIFS(Trechos!$F$2:$F$275,Trechos!$L$2:$L$275,A17) -> 83.786375 | L17: — | M17: =Blocos!AA11 -> —
A18: RAMAL DO 0200475007 — sai do tronco no poste 0200475007
A19: 11 | B19: T1 | C19: DJ AL01048007 | H19: poste N8 | I19: fim 144443 / fim 202873 / fim 202872 / 0200475007 / fim 145175 / fim 145089 / 0200047007 / fim 144450 | J19: =COUNTIFS(Trechos!$L$2:$L$275,A19) -> 15 | K19: =SUMIFS(Trechos!$F$2:$F$275,Trechos!$L$2:$L$275,A19) -> 870.97186 | L19: — | M19: =Blocos!AA12 -> 0200475007, 0200047007
A20: 12 | B20: T3 | C20: DJ AL01048007 | D20: 0200475007 | H20: 0200475007 | I20: fim N150 | J20: =COUNTIFS(Trechos!$L$2:$L$275,A20) -> 2 | K20: =SUMIFS(Trechos!$F$2:$F$275,Trechos!$L$2:$L$275,A20) -> 57.037306 | L20: — | M20: =Blocos!AA13 -> —
A21: 13 | B21: T3 | C21: DJ AL01048007 | D21: 0200047007 | H21: 0200047007 | I21: fim 144448 | J21: =COUNTIFS(Trechos!$L$2:$L$275,A21) -> 1 | K21: =SUMIFS(Trechos!$F$2:$F$275,Trechos!$L$2:$L$275,A21) -> 11.094453 | L21: — | M21: =Blocos!AA14 -> —
A22: RAMAL DO 0300050007 — sai do tronco no poste 0300050007
A23: 14 | B23: T1 | C23: DJ AL01048007 | H23: poste N13 | I23: fim 145198 / 0300050007 | J23: =COUNTIFS(Trechos!$L$2:$L$275,A23) -> 3 | K23: =SUMIFS(Trechos!$F$2:$F$275,Trechos!$L$2:$L$275,A23) -> 39.211624 | L23: — | M23: =Blocos!AA15 -> 0300050007
A24: 15 | B24: T3 | C24: DJ AL01048007 | D24: 0300050007 | H24: 0300050007 | I24: fim 145186 | J24: =COUNTIFS(Trechos!$L$2:$L$275,A24) -> 3 | K24: =SUMIFS(Trechos!$F$2:$F$275,Trechos!$L$2:$L$275,A24) -> 380.99649 | L24: — | M24: =Blocos!AA16 -> —
A25: RAMAL N21 — sai do tronco no poste N21
A26: 16 | B26: T1 | C26: DJ AL01048007 | H26: poste N21 | I26: fim 145152 / fim 144498 | J26: =COUNTIFS(Trechos!$L$2:$L$275,A26) -> 2 | K26: =SUMIFS(Trechos!$F$2:$F$275,Trechos!$L$2:$L$275,A26) -> 27.024643 | L26: — | M26: =Blocos!AA17 -> —
A27: RAMAL 145158 — sai do tronco no poste 145158
A28: 17 | B28: T1 | C28: DJ AL01048007 | H28: poste 145158 | I28: 0200055007 | J28: =COUNTIFS(Trechos!$L$2:$L$275,A28) -> 1 | K28: =SUMIFS(Trechos!$F$2:$F$275,Trechos!$L$2:$L$275,A28) -> 2.8761034 | L28: — | M28: =Blocos!AA18 -> 0200055007
A29: 18 | B29: T3 | C29: DJ AL01048007 | D29: 0200055007 | H29: 0200055007 | I29: fim N136 | J29: =COUNTIFS(Trechos!$L$2:$L$275,A29) -> 2 | K29: =SUMIFS(Trechos!$F$2:$F$275,Trechos!$L$2:$L$275,A29) -> 41.257041 | L29: — | M29: =Blocos!AA19 -> —
A30: RAMAL DO 0300057007 — sai do tronco no poste 0300057007
A31: 19 | B31: T1 | C31: DJ AL01048007 | H31: poste N32 | I31: 0300057007 / 0300056007 | J31: =COUNTIFS(Trechos!$L$2:$L$275,A31) -> 4 | K31: =SUMIFS(Trechos!$F$2:$F$275,Trechos!$L$2:$L$275,A31) -> 24.809169 | L31: — | M31: =Blocos!AA20 -> 0300057007, 0357094007, 0300056007
A32: 20 | B32: T3 | C32: DJ AL01048007 | D32: 0300057007 | H32: 0300057007 | I32: fim 40943446 / 0357094007 | J32: =COUNTIFS(Trechos!$L$2:$L$275,A32) -> 4 | K32: =SUMIFS(Trechos!$F$2:$F$275,Trechos!$L$2:$L$275,A32) -> 188.29821 | L32: — | M32: =Blocos!AA21 -> 0357094007
A33: 21 | B33: T4 | C33: DJ AL01048007 | D33: 0300057007 | E33: 0357094007 | H33: 0357094007 | I33: fim N46 | J33: =COUNTIFS(Trechos!$L$2:$L$275,A33) -> 1 | K33: =SUMIFS(Trechos!$F$2:$F$275,Trechos!$L$2:$L$275,A33) -> 2.3526217 | L33: — | M33: =Blocos!AA22 -> —
A34: 22 | B34: T3 | C34: DJ AL01048007 | D34: 0300056007 | H34: 0300056007 | I34: fim 145054 | J34: =COUNTIFS(Trechos!$L$2:$L$275,A34) -> 1 | K34: =SUMIFS(Trechos!$F$2:$F$275,Trechos!$L$2:$L$275,A34) -> 25.770317 | L34: — | M34: =Blocos!AA23 -> —
A35: RAMAL 145048 — sai do tronco no poste 145048
A36: 23 | B36: T1 | C36: DJ AL01048007 | H36: poste 145048 | I36: 0200061007 | J36: =COUNTIFS(Trechos!$L$2:$L$275,A36) -> 1 | K36: =SUMIFS(Trechos!$F$2:$F$275,Trechos!$L$2:$L$275,A36) -> 1.9163448 | L36: — | M36: =Blocos!AA24 -> 0200061007
A37: 24 | B37: T3 | C37: DJ AL01048007 | D37: 0200061007 | H37: 0200061007 | I37: fim N139 | J37: =COUNTIFS(Trechos!$L$2:$L$275,A37) -> 2 | K37: =SUMIFS(Trechos!$F$2:$F$275,Trechos!$L$2:$L$275,A37) -> 31.662404 | L37: — | M37: =Blocos!AA25 -> —
A38: RAMAL 145047 — sai do tronco no poste 145047
A39: 25 | B39: T1 | C39: DJ AL01048007 | H39: poste 145047 | I39: 0300062007 | J39: =COUNTIFS(Trechos!$L$2:$L$275,A39) -> 1 | K39: =SUMIFS(Trechos!$F$2:$F$275,Trechos!$L$2:$L$275,A39) -> 0.32894394 | L39: — | M39: =Blocos!AA26 -> 0300062007
A40: 26 | B40: T3 | C40: DJ AL01048007 | D40: 0300062007 | H40: 0300062007 | I40: fim N50 / fim N48 | J40: =COUNTIFS(Trechos!$L$2:$L$275,A40) -> 4 | K40: =SUMIFS(Trechos!$F$2:$F$275,Trechos!$L$2:$L$275,A40) -> 10.271276 | L40: — | M40: =Blocos!AA27 -> —
A41: RAMAL DO 0300065007 — sai do tronco no poste 0300065007
...

Sheet Consulta
A1: Onde fica este poste?
A2: Digite o código do poste na célula amarela (o poste no fim do vão). A planilha mostra o vão e a sequência desde o DJ.
A4: Poste | B4: 145500 | C4: ← exemplo
A6: Trecho (vão) | B6: =IFERROR(INDEX(Trechos!$B$2:$B$275,MATCH($B$4,Trechos!$E$2:$E$275,0)),"poste não encontrado") -> TR-274
A7: Poste início | B7: =IFERROR(INDEX(Trechos!$D$2:$D$275,MATCH($B$4,Trechos!$E$2:$E$275,0)),"poste não encontrado") -> N271
A8: Zona | B8: =IFERROR(INDEX(Trechos!$I$2:$I$275,MATCH($B$4,Trechos!$E$2:$E$275,0)),"poste não encontrado") -> T2
A9: Tronco/Ramal | B9: =IFERROR(INDEX(Trechos!$J$2:$J$275,MATCH($B$4,Trechos!$E$2:$E$275,0)),"poste não encontrado") -> Ramal
A10: Ramal | B10: =IFERROR(INDEX(Trechos!$K$2:$K$275,MATCH($B$4,Trechos!$E$2:$E$275,0)),"poste não encontrado") -> Ramal N227
A11: Bloco | B11: =IFERROR(INDEX(Trechos!$L$2:$L$275,MATCH($B$4,Trechos!$E$2:$E$275,0)),"poste não encontrado") -> 48
A12: Ativo de referência | B12: =IFERROR(INDEX(Trechos!$M$2:$M$275,MATCH($B$4,Trechos!$E$2:$E$275,0)),"poste não encontrado") -> 7925573007
A13: Distância do ativo de referência (m) | B13: =IFERROR(INDEX(Trechos!$H$2:$H$275,MATCH($B$4,Trechos!$E$2:$E$275,0)),"poste não encontrado") -> 958.69452
A14: Distância do DJ (m) | B14: =IFERROR(INDEX(Trechos!$G$2:$G$275,MATCH($B$4,Trechos!$E$2:$E$275,0)),"poste não encontrado") -> 2408.0559
A15: Ativos posteriores englobados | B15: =IFERROR(INDEX(Trechos!$P$2:$P$275,MATCH($B$4,Trechos!$E$2:$E$275,0)),"poste não encontrado") -> —
A16: Outra chave no fim do vão (88…) | B16: =IFERROR(INDEX(Trechos!$R$2:$R$275,MATCH($B$4,Trechos!$E$2:$E$275,0)),"poste não encontrado") -> 0
A17: Caminho desde o DJ | B17: =IFERROR(INDEX(Trechos!$X$2:$X$275,MATCH($B$4,Trechos!$E$2:$E$275,0)),"poste não encontrado") -> DJ AL01048007 › 7925573007
A18: Latitude | B18: =IFERROR(INDEX(Trechos!$Y$2:$Y$275,MATCH($B$4,Trechos!$E$2:$E$275,0)),"poste não encontrado") -> -9.5636585
A19: Longitude | B19: =IFERROR(INDEX(Trechos!$Z$2:$Z$275,MATCH($B$4,Trechos!$E$2:$E$275,0)),"poste não encontrado") -> -48.398756

Sheet Blocos
A1: Bloco | B1: Zona | C1: Tronco/Ramal | D1: Ramal | E1: Ativo de referência | F1: De | G1: Próximo ativo 1 | H1: Próximo ativo 2 | I1: Próximo ativo 3 | J1: Próximo ativo 4 | K1: Próximo ativo 5 | L1: Próximo ativo 6 | M1: Próximo ativo 7 | N1: Próximo ativo 8 | O1: Próximo ativo 9 | P1: Próximo ativo 10 | Q1: Próximo ativo 11 | R1: Próximo ativo 12 | S1: Nível 1 | T1: Nível 2 | U1: Nível 3 | V1: Nível 4 | W1: Nível 5 | X1: Qtd. vãos | Y1: Extensão do bloco (m) | Z1: Qtd. ativos posteriores | AA1: Ativos posteriores (concatenado) | AB1: Outras chaves no bloco (88…) | AC1: Posterior 1 | AD1: Posterior 2 | AE1: Posterior 3 | AF1: Posterior 4 | AG1: Posterior 5 | AH1: Posterior 6 | AI1: Posterior 7 | AJ1: Posterior 8 | AK1: Posterior 9 | AL1: Posterior 10 | AM1: Posterior 11 | AN1: Posterior 12 | AO1: Posterior 13 | AP1: Posterior 14 | AQ1: Posterior 15 | AR1: Posterior 16 | AS1: Posterior 17 | AT1: Posterior 18 | AU1: Posterior 19 | AV1: Posterior 20 | AW1: Posterior 21 | AX1: Posterior 22 | AY1: Posterior 23
A2: 1 | B2: T1 | C2: Tronco | D2: Tronco | E2: DJ AL01048007 | F2: DJ AL01048007 | G2: 7925573007 | S2: DJ AL01048007 | X2: =COUNTIFS(Trechos!$L$2:$L$275,A2) -> 19 | Y2: =SUMIFS(Trechos!$F$2:$F$275,Trechos!$L$2:$L$275,A2) -> 1449.3614 | Z2: =COUNTA(AC2:AY2) -> 23 | AA2: =IF(COUNTA(AC2:AY2)=0,"—",_xlfn.TEXTJOIN(", ",TRUE(),AC2:AY2)) -> 7925573007, 0300040007, 0200038007, 0300111007, 0300115007, 0300145007, 0200114007, 0301201007, 0300109007, 0300068007, 0300070007, 0300073007, 0300074007, 0300065007, 0300062007, 0200061007, 0300057007, 0357094007, 0300056007, 0200055007, 0300050007, 0200475007, 0200047007 | AB2: 8800042007, 8808674007, 8800054007 | AC2: 7925573007 | AD2: 0300040007 | AE2: 0200038007 | AF2: 0300111007 | AG2: 0300115007 | AH2: 0300145007 | AI2: 0200114007 | AJ2: 0301201007 | AK2: 0300109007 | AL2: 0300068007 | AM2: 0300070007 | AN2: 0300073007 | AO2: 0300074007 | AP2: 0300065007 | AQ2: 0300062007 | AR2: 0200061007 | AS2: 0300057007 | AT2: 0357094007 | AU2: 0300056007 | AV2: 0200055007 | AW2: 0300050007 | AX2: 0200475007 | AY2: 0200047007
A3: 2 | B3: T2 | C3: Tronco | D3: Tronco | E3: 7925573007 | F3: 7925573007 | G3: fim N228 | S3: DJ AL01048007 | T3: 7925573007 | X3: =COUNTIFS(Trechos!$L$2:$L$275,A3) -> 17 | Y3: =SUMIFS(Trechos!$F$2:$F$275,Trechos!$L$2:$L$275,A3) -> 960.40964 | Z3: =COUNTA(AC3:AY3) -> 12 | AA3: =IF(COUNTA(AC3:AY3)=0,"—",_xlfn.TEXTJOIN(", ",TRUE(),AC3:AY3)) -> 0300040007, 0200038007, 0300111007, 0300115007, 0300145007, 0200114007, 0301201007, 0300109007, 0300068007, 0300070007, 0300073007, 0300074007 | AB3: 8800075007 | AC3: 0300040007 | AD3: 0200038007 | AE3: 0300111007 | AF3: 0300115007 | AG3: 0300145007 | AH3: 0200114007 | AI3: 0301201007 | AJ3: 0300109007 | AK3: 0300068007 | AL3: 0300070007 | AM3: 0300073007 | AN3: 0300074007
A4: 3 | B4: T1 | C4: Ramal | D4: Ramal 1478970 | E4: DJ AL01048007 | F4: DJ AL01048007 | G4: 0300043007 | S4: DJ AL01048007 | X4: =COUNTIFS(Trechos!$L$2:$L$275,A4) -> 2 | Y4: =SUMIFS(Trechos!$F$2:$F$275,Trechos!$L$2:$L$275,A4) -> 38.914441 | Z4: =COUNTA(AC4:AY4) -> 7 | AA4: =IF(COUNTA(AC4:AY4)=0,"—",_xlfn.TEXTJOIN(", ",TRUE(),AC4:AY4)) -> 0300043007, 0301038007, 0301039007, 0301117007, 0201291007, 0302253007, 0301273007 | AB4: — | AC4: 0300043007 | AD4: 0301038007 | AE4: 0301039007 | AF4: 0301117007 | AG4: 0201291007 | AH4: 0302253007 | AI4: 0301273007
A5: 4 | B5: T3 | C5: Ramal | D5: Ramal 1478970 | E5: 0300043007 | F5: 0300043007 | G5: 0301038007 | H5: fim 69120630 | I5: 0301117007 | J5: fim 299845 | K5: 0301273007 | S5: DJ AL01048007 | T5: 0300043007 | X5: =COUNTIFS(Trechos!$L$2:$L$275,A5) -> 15 | Y5: =SUMIFS(Trechos!$F$2:$F$275,Trechos!$L$2:$L$275,A5) -> 2457.9533 | Z5: =COUNTA(AC5:AY5) -> 6 | AA5: =IF(COUNTA(AC5:AY5)=0,"—",_xlfn.TEXTJOIN(", ",TRUE(),AC5:AY5)) -> 0301038007, 0301039007, 0301117007, 0201291007, 0302253007, 0301273007 | AB5: 386243 | AC5: 0301038007 | AD5: 0301039007 | AE5: 0301117007 | AF5: 0201291007 | AG5: 0302253007 | AH5: 0301273007
A6: 5 | B6: T4 | C6: Ramal | D6: Ramal 1478970 | E6: 0301038007 | F6: 0301038007 | G6: 0301039007 | S6: DJ AL01048007 | T6: 0300043007 | U6: 0301038007 | X6: =COUNTIFS(Trechos!$L$2:$L$275,A6) -> 2 | Y6: =SUMIFS(Trechos!$F$2:$F$275,Trechos!$L$2:$L$275,A6) -> 223.13742 | Z6: =COUNTA(AC6:AY6) -> 1 | AA6: =IF(COUNTA(AC6:AY6)=0,"—",_xlfn.TEXTJOIN(", ",TRUE(),AC6:AY6)) -> 0301039007 | AB6: — | AC6: 0301039007
A7: 6 | B7: T5 | C7: Ramal | D7: Ramal 1478970 | E7: 0301039007 | F7: 0301039007 | G7: fim 289786 | S7: DJ AL01048007 | T7: 0300043007 | U7: 0301038007 | V7: 0301039007 | X7: =COUNTIFS(Trechos!$L$2:$L$275,A7) -> 1 | Y7: =SUMIFS(Trechos!$F$2:$F$275,Trechos!$L$2:$L$275,A7) -> 92.473831 | Z7: =COUNTA(AC7:AY7) -> 0 | AA7: =IF(COUNTA(AC7:AY7)=0,"—",_xlfn.TEXTJOIN(", ",TRUE(),AC7:AY7)) -> — | AB7: —
A8: 7 | B8: T4 | C8: Ramal | D8: Ramal 1478970 | E8: 0301117007 | F8: 0301117007 | G8: 0201291007 | H8: 0302253007 | I8: fim 1078155 | S8: DJ AL01048007 | T8: 0300043007 | U8: 0301117007 | X8: =COUNTIFS(Trechos!$L$2:$L$275,A8) -> 37 | Y8: =SUMIFS(Trechos!$F$2:$F$275,Trechos!$L$2:$L$275,A8) -> 2136.3104 | Z8: =COUNTA(AC8:AY8) -> 2 | AA8: =IF(COUNTA(AC8:AY8)=0,"—",_xlfn.TEXTJOIN(", ",TRUE(),AC8:AY8)) -> 0201291007, 0302253007 | AB8: — | AC8: 0201291007 | AD8: 0302253007
A9: 8 | B9: T5 | C9: Ramal | D9: Ramal 1478970 | E9: 0201291007 | F9: 0201291007 | G9: fim 315977 | S9: DJ AL01048007 | T9: 0300043007 | U9: 0301117007 | V9: 0201291007 | X9: =COUNTIFS(Trechos!$L$2:$L$275,A9) -> 1 | Y9: =SUMIFS(Trechos!$F$2:$F$275,Trechos!$L$2:$L$275,A9) -> 16.087812 | Z9: =COUNTA(AC9:AY9) -> 0 | AA9: =IF(COUNTA(AC9:AY9)=0,"—",_xlfn.TEXTJOIN(", ",TRUE(),AC9:AY9)) -> — | AB9: —
A10: 9 | B10: T5 | C10: Ramal | D10: Ramal 1478970 | E10: 0302253007 | F10: 0302253007 | G10: fim 1088763 | H10: fim 1088774 | I10: fim 1089030 | J10: fim 1088769 | K10: fim N118 | L10: fim 1088761 | M10: fim N120 | N10: fim 1089031 | S10: DJ AL01048007 | T10: 0300043007 | U10: 0301117007 | V10: 0302253007 | X10: =COUNTIFS(Trechos!$L$2:$L$275,A10) -> 18 | Y10: =SUMIFS(Trechos!$F$2:$F$275,Trechos!$L$2:$L$275,A10) -> 1159.7448 | Z10: =COUNTA(AC10:AY10) -> 0 | AA10: =IF(COUNTA(AC10:AY10)=0,"—",_xlfn.TEXTJOIN(", ",TRUE(),AC10:AY10)) -> — | AB10: —
A11: 10 | B11: T4 | C11: Ramal | D11: Ramal 1478970 | E11: 0301273007 | F11: 0301273007 | G11: fim 309513 | S11: DJ AL01048007 | T11: 0300043007 | U11: 0301273007 | X11: =COUNTIFS(Trechos!$L$2:$L$275,A11) -> 1 | Y11: =SUMIFS(Trechos!$F$2:$F$275,Trechos!$L$2:$L$275,A11) -> 83.786375 | Z11: =COUNTA(AC11:AY11) -> 0 | AA11: =IF(COUNTA(AC11:AY11)=0,"—",_xlfn.TEXTJOIN(", ",TRUE(),AC11:AY11)) -> — | AB11: —
A12: 11 | B12: T1 | C12: Ramal | D12: Ramal do 0200475007 | E12: DJ AL01048007 | F12: poste N8 | G12: fim 144443 | H12: fim 202873 | I12: fim 202872 | J12: 0200475007 | K12: fim 145175 | L12: fim 145089 | M12: 0200047007 | N12: fim 144450 | S12: DJ AL01048007 | X12: =COUNTIFS(Trechos!$L$2:$L$275,A12) -> 15 | Y12: =SUMIFS(Trechos!$F$2:$F$275,Trechos!$L$2:$L$275,A12) -> 870.97186 | Z12: =COUNTA(AC12:AY12) -> 2 | AA12: =IF(COUNTA(AC12:AY12)=0,"—",_xlfn.TEXTJOIN(", ",TRUE(),AC12:AY12)) -> 0200475007, 0200047007 | AB12: — | AC12: 0200475007 | AD12: 0200047007
A13: 12 | B13: T3 | C13: Ramal | D13: Ramal do 0200475007 | E13: 0200475007 | F13: 0200475007 | G13: fim N150 | S13: DJ AL01048007 | T13: 0200475007 | X13: =COUNTIFS(Trechos!$L$2:$L$275,A13) -> 2 | Y13: =SUMIFS(Trechos!$F$2:$F$275,Trechos!$L$2:$L$275,A13) -> 57.037306 | Z13: =COUNTA(AC13:AY13) -> 0 | AA13: =IF(COUNTA(AC13:AY13)=0,"—",_xlfn.TEXTJOIN(", ",TRUE(),AC13:AY13)) -> — | AB13: —
A14: 13 | B14: T3 | C14: Ramal | D14: Ramal do 0200475007 | E14: 0200047007 | F14: 0200047007 | G14: fim 144448 | S14: DJ AL01048007 | T14: 0200047007 | X14: =COUNTIFS(Trechos!$L$2:$L$275,A14) -> 1 | Y14: =SUMIFS(Trechos!$F$2:$F$275,Trechos!$L$2:$L$275,A14) -> 11.094453 | Z14: =COUNTA(AC14:AY14) -> 0 | AA14: =IF(COUNTA(AC14:AY14)=0,"—",_xlfn.TEXTJOIN(", ",TRUE(),AC14:AY14)) -> — | AB14: —
A15: 14 | B15: T1 | C15: Ramal | D15: Ramal do 0300050007 | E15: DJ AL01048007 | F15: poste N13 | G15: fim 145198 | H15: 0300050007 | S15: DJ AL01048007 | X15: =COUNTIFS(Trechos!$L$2:$L$275,A15) -> 3 | Y15: =SUMIFS(Trechos!$F$2:$F$275,Trechos!$L$2:$L$275,A15) -> 39.211624 | Z15: =COUNTA(AC15:AY15) -> 1 | AA15: =IF(COUNTA(AC15:AY15)=0,"—",_xlfn.TEXTJOIN(", ",TRUE(),AC15:AY15)) -> 0300050007 | AB15: — | AC15: 0300050007
A16: 15 | B16: T3 | C16: Ramal | D16: Ramal do 0300050007 | E16: 0300050007 | F16: 0300050007 | G16: fim 145186 | S16: DJ AL01048007 | T16: 0300050007 | X16: =COUNTIFS(Trechos!$L$2:$L$275,A16) -> 3 | Y16: =SUMIFS(Trechos!$F$2:$F$275,Trechos!$L$2:$L$275,A16) -> 380.99649 | Z16: =COUNTA(AC16:AY16) -> 0 | AA16: =IF(COUNTA(AC16:AY16)=0,"—",_xlfn.TEXTJOIN(", ",TRUE(),AC16:AY16)) -> — | AB16: —
A17: 16 | B17: T1 | C17: Ramal | D17: Ramal N21 | E17: DJ AL01048007 | F17: poste N21 | G17: fim 145152 | H17: fim 144498 | S17: DJ AL01048007 | X17: =COUNTIFS(Trechos!$L$2:$L$275,A17) -> 2 | Y17: =SUMIFS(Trechos!$F$2:$F$275,Trechos!$L$2:$L$275,A17) -> 27.024643 | Z17: =COUNTA(AC17:AY17) -> 0 | AA17: =IF(COUNTA(AC17:AY17)=0,"—",_xlfn.TEXTJOIN(", ",TRUE(),AC17:AY17)) -> — | AB17: —
A18: 17 | B18: T1 | C18: Ramal | D18: Ramal 145158 | E18: DJ AL01048007 | F18: poste 145158 | G18: 0200055007 | S18: DJ AL01048007 | X18: =COUNTIFS(Trechos!$L$2:$L$275,A18) -> 1 | Y18: =SUMIFS(Trechos!$F$2:$F$275,Trechos!$L$2:$L$275,A18) -> 2.8761034 | Z18: =COUNTA(AC18:AY18) -> 1 | AA18: =IF(COUNTA(AC18:AY18)=0,"—",_xlfn.TEXTJOIN(", ",TRUE(),AC18:AY18)) -> 0200055007 | AB18: — | AC18: 0200055007
A19: 18 | B19: T3 | C19: Ramal | D19: Ramal 145158 | E19: 0200055007 | F19: 0200055007 | G19: fim N136 | S19: DJ AL01048007 | T19: 0200055007 | X19: =COUNTIFS(Trechos!$L$2:$L$275,A19) -> 2 | Y19: =SUMIFS(Trechos!$F$2:$F$275,Trechos!$L$2:$L$275,A19) -> 41.257041 | Z19: =COUNTA(AC19:AY19) -> 0 | AA19: =IF(COUNTA(AC19:AY19)=0,"—",_xlfn.TEXTJOIN(", ",TRUE(),AC19:AY19)) -> — | AB19: —
A20: 19 | B20: T1 | C20: Ramal | D20: Ramal do 0300057007 | E20: DJ AL01048007 | F20: poste N32 | G20: 0300057007 | H20: 0300056007 | S20: DJ AL01048007 | X20: =COUNTIFS(Trechos!$L$2:$L$275,A20) -> 4 | Y20: =SUMIFS(Trechos!$F$2:$F$275,Trechos!$L$2:$L$275,A20) -> 24.809169 | Z20: =COUNTA(AC20:AY20) -> 3 | AA20: =IF(COUNTA(AC20:AY20)=0,"—",_xlfn.TEXTJOIN(", ",TRUE(),AC20:AY20)) -> 0300057007, 0357094007, 0300056007 | AB20: — | AC20: 0300057007 | AD20: 0357094007 | AE20: 0300056007
A21: 20 | B21: T3 | C21: Ramal | D21: Ramal do 0300057007 | E21: 0300057007 | F21: 0300057007 | G21: fim 40943446 | H21: 0357094007 | S21: DJ AL01048007 | T21: 0300057007 | X21: =COUNTIFS(Trechos!$L$2:$L$275,A21) -> 4 | Y21: =SUMIFS(Trechos!$F$2:$F$275,Trechos!$L$2:$L$275,A21) -> 188.29821 | Z21: =COUNTA(AC21:AY21) -> 1 | AA21: =IF(COUNTA(AC21:AY21)=0,"—",_xlfn.TEXTJOIN(", ",TRUE(),AC21:AY21)) -> 0357094007 | AB21: — | AC21: 0357094007
A22: 21 | B22: T4 | C22: Ramal | D22: Ramal do 0300057007 | E22: 0357094007 | F22: 0357094007 | G22: fim N46 | S22: DJ AL01048007 | T22: 0300057007 | U22: 0357094007 | X22: =COUNTIFS(Trechos!$L$2:$L$275,A22) -> 1 | Y22: =SUMIFS(Trechos!$F$2:$F$275,Trechos!$L$2:$L$275,A22) -> 2.3526217 | Z22: =COUNTA(AC22:AY22) -> 0 | AA22: =IF(COUNTA(AC22:AY22)=0,"—",_xlfn.TEXTJOIN(", ",TRUE(),AC22:AY22)) -> — | AB22: —
A23: 22 | B23: T3 | C23: Ramal | D23: Ramal do 0300057007 | E23: 0300056007 | F23: 0300056007 | G23: fim 145054 | S23: DJ AL01048007 | T23: 0300056007 | X23: =COUNTIFS(Trechos!$L$2:$L$275,A23) -> 1 | Y23: =SUMIFS(Trechos!$F$2:$F$275,Trechos!$L$2:$L$275,A23) -> 25.770317 | Z23: =COUNTA(AC23:AY23) -> 0 | AA23: =IF(COUNTA(AC23:AY23)=0,"—",_xlfn.TEXTJOIN(", ",TRUE(),AC23:AY23)) -> — | AB23: —
A24: 23 | B24: T1 | C24: Ramal | D24: Ramal 145048 | E24: DJ AL01048007 | F24: poste 145048 | G24: 0200061007 | S24: DJ AL01048007 | X24: =COUNTIFS(Trechos!$L$2:$L$275,A24) -> 1 | Y24: =SUMIFS(Trechos!$F$2:$F$275,Trechos!$L$2:$L$275,A24) -> 1.9163448 | Z24: =COUNTA(AC24:AY24) -> 1 | AA24: =IF(COUNTA(AC24:AY24)=0,"—",_xlfn.TEXTJOIN(", ",TRUE(),AC24:AY24)) -> 0200061007 | AB24: — | AC24: 0200061007
A25: 24 | B25: T3 | C25: Ramal | D25: Ramal 145048 | E25: 0200061007 | F25: 0200061007 | G25: fim N139 | S25: DJ AL01048007 | T25: 0200061007 | X25: =COUNTIFS(Trechos!$L$2:$L$275,A25) -> 2 | Y25: =SUMIFS(Trechos!$F$2:$F$275,Trechos!$L$2:$L$275,A25) -> 31.662404 | Z25: =COUNTA(AC25:AY25) -> 0 | AA25: =IF(COUNTA(AC25:AY25)=0,"—",_xlfn.TEXTJOIN(", ",TRUE(),AC25:AY25)) -> — | AB25: —
A26: 25 | B26: T1 | C26: Ramal | D26: Ramal 145047 | E26: DJ AL01048007 | F26: poste 145047 | G26: 0300062007 | S26: DJ AL01048007 | X26: =COUNTIFS(Trechos!$L$2:$L$275,A26) -> 1 | Y26: =SUMIFS(Trechos!$F$2:$F$275,Trechos!$L$2:$L$275,A26) -> 0.32894394 | Z26: =COUNTA(AC26:AY26) -> 1 | AA26: =IF(COUNTA(AC26:AY26)=0,"—",_xlfn.TEXTJOIN(", ",TRUE(),AC26:AY26)) -> 0300062007 | AB26: — | AC26: 0300062007
A27: 26 | B27: T3 | C27: Ramal | D27: Ramal 145047 | E27: 0300062007 | F27: 0300062007 | G27: fim N50 | H27: fim N48 | S27: DJ AL01048007 | T27: 0300062007 | X27: =COUNTIFS(Trechos!$L$2:$L$275,A27) -> 4 | Y27: =SUMIFS(Trechos!$F$2:$F$275,Trechos!$L$2:$L$275,A27) -> 10.271276 | Z27: =COUNTA(AC27:AY27) -> 0 | AA27: =IF(COUNTA(AC27:AY27)=0,"—",_xlfn.TEXTJOIN(", ",TRUE(),AC27:AY27)) -> — | AB27: —
A28: 27 | B28: T1 | C28: Ramal | D28: Ramal do 0300065007 | E28: DJ AL01048007 | F28: poste N53 | G28: 0300065007 | H28: fim 145080 | S28: DJ AL01048007 | X28: =COUNTIFS(Trechos!$L$2:$L$275,A28) -> 4 | Y28: =SUMIFS(Trechos!$F$2:$F$275,Trechos!$L$2:$L$275,A28) -> 174.12782 | Z28: =COUNTA(AC28:AY28) -> 1 | AA28: =IF(COUNTA(AC28:AY28)=0,"—",_xlfn.TEXTJOIN(", ",TRUE(),AC28:AY28)) -> 0300065007 | AB28: — | AC28: 0300065007
A29: 28 | B29: T3 | C29: Ramal | D29: Ramal do 0300065007 | E29: 0300065007 | F29: 0300065007 | G29: fim 145113 | S29: DJ AL01048007 | T29: 0300065007 | X29: =COUNTIFS(Trechos!$L$2:$L$275,A29) -> 1 | Y29: =SUMIFS(Trechos!$F$2:$F$275,Trechos!$L$2:$L$275,A29) -> 102.76122 | Z29: =COUNTA(AC29:AY29) -> 0 | AA29: =IF(COUNTA(AC29:AY29)=0,"—",_xlfn.TEXTJOIN(", ",TRUE(),AC29:AY29)) -> — | AB29: —
A30: 29 | B30: T1 | C30: Ramal | D30: Ramal N59 | E30: DJ AL01048007 | F30: poste N59 | G30: fim N61 | S30: DJ AL01048007 | X30: =COUNTIFS(Trechos!$L$2:$L$275,A30) -> 1 | Y30: =SUMIFS(Trechos!$F$2:$F$275,Trechos!$L$2:$L$275,A30) -> 5.4577228 | Z30: =COUNTA(AC30:AY30) -> 0 | AA30: =IF(COUNTA(AC30:AY30)=0,"—",_xlfn.TEXTJOIN(", ",TRUE(),AC30:AY30)) -> — | AB30: —
A31: 30 | B31: T2 | C31: Ramal | D31: Ramal N152 | E31: 7925573007 | F31: poste N152 | G31: fim N153 | S31: DJ AL01048007 | T31: 7925573007 | X31: =COUNTIFS(Trechos!$L$2:$L$275,A31) -> 1 | Y31: =SUMIFS(Trechos!$F$2:$F$275,Trechos!$L$2:$L$275,A31) -> 4.7759555 | Z31: =COUNTA(AC31:AY31) -> 0 | AA31: =IF(COUNTA(AC31:AY31)=0,"—",_xlfn.TEXTJOIN(", ",TRUE(),AC31:AY31)) -> — | AB31: —
A32: 31 | B32: T2 | C32: Ramal | D32: Ramal 144482 | E32: 7925573007 | F32: poste 144482 | G32: 0300068007 | S32: DJ AL01048007 | T32: 7925573007 | X32: =COUNTIFS(Trechos!$L$2:$L$275,A32) -> 2 | Y32: =SUMIFS(Trechos!$F$2:$F$275,Trechos!$L$2:$L$275,A32) -> 44.770933 | Z32: =COUNTA(AC32:AY32) -> 4 | AA32: =IF(COUNTA(AC32:AY32)=0,"—",_xlfn.TEXTJOIN(", ",TRUE(),AC32:AY32)) -> 0300068007, 0300070007, 0300073007, 0300074007 | AB32: — | AC32: 0300068007 | AD32: 0300070007 | AE32: 0300073007 | AF32: 0300074007
A33: 32 | B33: T3 | C33: Ramal | D33: Ramal 144482 | E33: 0300068007 | F33: 0300068007 | G33: fim N202 | H33: 0300070007 | I33: 0300073007 | J33: fim 144475 | K33: fim N176 | L33: fim 145185 | M33: fim 145183 | S33: DJ AL01048007 | T33: 7925573007 | U33: 0300068007 | X33: =COUNTIFS(Trechos!$L$2:$L$275,A33) -> 16 | Y33: =SUMIFS(Trechos!$F$2:$F$275,Trechos!$L$2:$L$275,A33) -> 618.68117 | Z33: =COUNTA(AC33:AY33) -> 3 | AA33: =IF(COUNTA(AC33:AY33)=0,"—",_xlfn.TEXTJOIN(", ",TRUE(),AC33:AY33)) -> 0300070007, 0300073007, 0300074007 | AB33: — | AC33: 0300070007 | AD33: 0300073007 | AE33: 0300074007
A34: 33 | B34: T4 | C34: Ramal | D34: Ramal 144482 | E34: 0300070007 | F34: 0300070007 | G34: fim 145209 | S34: DJ AL01048007 | T34: 7925573007 | U34: 0300068007 | V34: 0300070007 | X34: =COUNTIFS(Trechos!$L$2:$L$275,A34) -> 2 | Y34: =SUMIFS(Trechos!$F$2:$F$275,Trechos!$L$2:$L$275,A34) -> 174.54062 | Z34: =COUNTA(AC34:AY34) -> 0 | AA34: =IF(COUNTA(AC34:AY34)=0,"—",_xlfn.TEXTJOIN(", ",TRUE(),AC34:AY34)) -> — | AB34: —
A35: 34 | B35: T4 | C35: Ramal | D35: Ramal 144482 | E35: 0300073007 | F35: 0300073007 | G35: 0300074007 | S35: DJ AL01048007 | T35: 7925573007 | U35: 0300068007 | V35: 0300073007 | X35: =COUNTIFS(Trechos!$L$2:$L$275,A35) -> 5 | Y35: =SUMIFS(Trechos!$F$2:$F$275,Trechos!$L$2:$L$275,A35) -> 276.32823 | Z35: =COUNTA(AC35:AY35) -> 1 | AA35: =IF(COUNTA(AC35:AY35)=0,"—",_xlfn.TEXTJOIN(", ",TRUE(),AC35:AY35)) -> 0300074007 | AB35: — | AC35: 0300074007
A36: 35 | B36: T5 | C36: Ramal | D36: Ramal 144482 | E36: 0300074007 | F36: 0300074007 | G36: fim 38877902 | S36: DJ AL01048007 | T36: 7925573007 | U36: 0300068007 | V36: 0300073007 | W36: 0300074007 | X36: =COUNTIFS(Trechos!$L$2:$L$275,A36) -> 1 | Y36: =SUMIFS(Trechos!$F$2:$F$275,Trechos!$L$2:$L$275,A36) -> 9.2894256 | Z36: =COUNTA(AC36:AY36) -> 0 | AA36: =IF(COUNTA(AC36:AY36)=0,"—",_xlfn.TEXTJOIN(", ",TRUE(),AC36:AY36)) -> — | AB36: —
A37: 36 | B37: T2 | C37: Ramal | D37: Ramal do 0300111007 | E37: 7925573007 | F37: poste N155 | G37: fim 145475 | H37: 0300111007 | I37: fim 145034 | J37: 0300109007 | S37: DJ AL01048007 | T37: 7925573007 | X37: =COUNTIFS(Trechos!$L$2:$L$275,A37) -> 7 | Y37: =SUMIFS(Trechos!$F$2:$F$275,Trechos!$L$2:$L$275,A37) -> 255.81026 | Z37: =COUNTA(AC37:AY37) -> 6 | AA37: =IF(COUNTA(AC37:AY37)=0,"—",_xlfn.TEXTJOIN(", ",TRUE(),AC37:AY37)) -> 0300111007, 0300115007, 0300145007, 0200114007, 0301201007, 0300109007 | AB37: — | AC37: 0300111007 | AD37: 0300115007 | AE37: 0300145007 | AF37: 0200114007 | AG37: 0301201007 | AH37: 0300109007
A38: 37 | B38: T3 | C38: Ramal | D38: Ramal do 0300111007 | E38: 0300111007 | F38: 0300111007 | G38: fim 346374 | H38: 0300115007 | I38: fim 145540 | J38: 0300145007 | K38: fim 373501 | L38: fim N233 | M38: fim 346375 | N38: fim 373500 | O38: fim 346371 | P38: 0200114007 | Q38: fim N205 | R38: 0301201007 | S38: DJ AL01048007 | T38: 7925573007 | U38: 0300111007 | X38: =COUNTIFS(Trechos!$L$2:$L$275,A38) -> 34 | Y38: =SUMIFS(Trechos!$F$2:$F$275,Trechos!$L$2:$L$275,A38) -> 1391.5635 | Z38: =COUNTA(AC38:AY38) -> 4 | AA38: =IF(COUNTA(AC38:AY38)=0,"—",_xlfn.TEXTJOIN(", ",TRUE(),AC38:AY38)) -> 0300115007, 0300145007, 0200114007, 0301201007 | AB38: — | AC38: 0300115007 | AD38: 0300145007 | AE38: 0200114007 | AF38: 0301201007
A39: 38 | B39: T4 | C39: Ramal | D39: Ramal do 0300111007 | E39: 0300115007 | F39: 0300115007 | G39: fim 28903358 | H39: fim 28903363 | I39: fim 28903259 | J39: fim 28903253 | S39: DJ AL01048007 | T39: 7925573007 | U39: 0300111007 | V39: 0300115007 | X39: =COUNTIFS(Trechos!$L$2:$L$275,A39) -> 16 | Y39: =SUMIFS(Trechos!$F$2:$F$275,Trechos!$L$2:$L$275,A39) -> 903.03517 | Z39: =COUNTA(AC39:AY39) -> 0 | AA39: =IF(COUNTA(AC39:AY39)=0,"—",_xlfn.TEXTJOIN(", ",TRUE(),AC39:AY39)) -> — | AB39: 8856371007
A40: 39 | B40: T4 | C40: Ramal | D40: Ramal do 0300111007 | E40: 0300145007 | F40: 0300145007 | G40: fim 1444580 | H40: fim 1444577 | I40: fim 145110 | J40: fim N244 | S40: DJ AL01048007 | T40: 7925573007 | U40: 0300111007 | V40: 0300145007 | X40: =COUNTIFS(Trechos!$L$2:$L$275,A40) -> 9 | Y40: =SUMIFS(Trechos!$F$2:$F$275,Trechos!$L$2:$L$275,A40) -> 318.29317 | Z40: =COUNTA(AC40:AY40) -> 0 | AA40: =IF(COUNTA(AC40:AY40)=0,"—",_xlfn.TEXTJOIN(", ",TRUE(),AC40:AY40)) -> — | AB40: —
...

Sheet Por bloco
A1: Bloco | B1: Zona | C1: Tronco/Ramal | D1: Ramal | E1: Ativo de referência | F1: Trecho | G1: Poste início | H1: Poste fim | I1: Extensão (m) | J1: Distância do ativo de referência até o fim (m) | K1: Outra chave no fim do vão (88…) | L1: Próximos ativos | M1: Outras chaves no bloco (88…) | N1: Ativos posteriores
A2: 1 | B2: T1 | C2: Tronco | D2: Tronco | E2: DJ AL01048007 | F2: =COUNTIFS(Trechos!$L$2:$L$275,A2)&" vãos" -> 19 vãos | I2: =SUMIFS(Trechos!$F$2:$F$275,Trechos!$L$2:$L$275,A2) -> 1449.3614 | L2: 7925573007 | M2: 8800042007, 8808674007, 8800054007 | N2: =Blocos!AA2 -> 7925573007, 0300040007, 0200038007, 0300111007, 0300115007, 0300145007, 0200114007, 0301201007, 0300109007, 0300068007, 0300070007, 0300073007, 0300074007, 0300065007, 0300062007, 0200061007, 0300057007, 0357094007, 0300056007, 0200055007, 0300050007, 0200475007, 0200047007
F3: TR-001 | G3: 1478970 | H3: N3 | I3: 41.56866 | J3: 41.56866
F4: TR-002 | G4: N3 | H4: N4 | I4: 1.6822778 | J4: 43.250938 | K4: 8800042007
F5: TR-003 | G5: N4 | H5: N6 | I5: 280.07955 | J5: 323.33049
F6: TR-004 | G6: N6 | H6: 145119 | I6: 1.6173316 | J6: 324.94782 | K6: 8808674007
F7: TR-005 | G7: 145119 | H7: N8 | I7: 14.398109 | J7: 339.34593
F8: TR-006 | G8: N8 | H8: N13 | I8: 170.41517 | J8: 509.7611
F9: TR-007 | G9: N13 | H9: 144496 | I9: 304.82191 | J9: 814.58301
F10: TR-008 | G10: 144496 | H10: N21 | I10: 48.159534 | J10: 862.74254
F11: TR-009 | G11: N21 | H11: 145155 | I11: 83.231515 | J11: 945.97406
F12: TR-010 | G12: 145155 | H12: N28 | I12: 3.8195131 | J12: 949.79357 | K12: 8800054007
F13: TR-011 | G13: N28 | H13: 145158 | I13: 103.14624 | J13: 1052.9398
F14: TR-012 | G14: 145158 | H14: N32 | I14: 29.465725 | J14: 1082.4055
F15: TR-013 | G15: N32 | H15: 145048 | I15: 153.92026 | J15: 1236.3258
F16: TR-014 | G16: 145048 | H16: 145047 | I16: 34.268223 | J16: 1270.594
F17: TR-015 | G17: 145047 | H17: N53 | I17: 20.192935 | J17: 1290.7869
F18: TR-016 | G18: N53 | H18: N59 | I18: 155.47565 | J18: 1446.2626
F19: TR-017 | G19: N59 | H19: N140 | I19: 0.24795168 | J19: 1446.5105
F20: TR-018 | G20: N140 | H20: N141 | I20: 2.7396149 | J20: 1449.2502
F21: TR-019 | G21: N141 | H21: N142 | I21: 0.11119493 | J21: 1449.3614
A22: 2 | B22: T2 | C22: Tronco | D22: Tronco | E22: 7925573007 | F22: =COUNTIFS(Trechos!$L$2:$L$275,A22)&" vãos" -> 17 vãos | I22: =SUMIFS(Trechos!$F$2:$F$275,Trechos!$L$2:$L$275,A22) -> 960.40964 | L22: fim N228 | M22: 8800075007 | N22: =Blocos!AA3 -> 0300040007, 0200038007, 0300111007, 0300115007, 0300145007, 0200114007, 0301201007, 0300109007, 0300068007, 0300070007, 0300073007, 0300074007
F23: TR-020 | G23: N142 | H23: N143 | I23: 1.8968617 | J23: 1.8968617
F24: TR-021 | G24: N143 | H24: 1251159 | I24: 0.24795168 | J24: 2.1448133
F25: TR-022 | G25: 1251159 | H25: N152 | I25: 2.7485749 | J25: 4.8933882
F26: TR-023 | G26: N152 | H26: 144482 | I26: 58.215048 | J26: 63.108436
F27: TR-024 | G27: 144482 | H27: N155 | I27: 22.660938 | J27: 85.769374
F28: TR-025 | G28: N155 | H28: 145523 | I28: 41.187563 | J28: 126.95694
F29: TR-026 | G29: 145523 | H29: 47444546 | I29: 95.135421 | J29: 222.09236
F30: TR-027 | G30: 47444546 | H30: 145527 | I30: 77.064587 | J30: 299.15695
F31: TR-028 | G31: 145527 | H31: N172 | I31: 3.4383273 | J31: 302.59527 | K31: 8800075007
F32: TR-029 | G32: N172 | H32: 145531 | I32: 148.45724 | J32: 451.05252
F33: TR-030 | G33: 145531 | H33: 145510 | I33: 38.02473 | J33: 489.07725
F34: TR-031 | G34: 145510 | H34: N197 | I34: 6.7718383 | J34: 495.84908
F35: TR-032 | G35: N197 | H35: N213 | I35: 287.45402 | J35: 783.30311
F36: TR-033 | G36: N213 | H36: 145502 | I36: 73.415709 | J36: 856.71882
F37: TR-034 | G37: 145502 | H37: 145501 | I37: 35.465519 | J37: 892.18434
F38: TR-035 | G38: 145501 | H38: N227 | I38: 63.66279 | J38: 955.84713
F39: TR-036 | G39: N227 | H39: N228 | I39: 4.5625139 | J39: 960.40964
A40: 3 | B40: T1 | C40: Ramal | D40: Ramal 1478970 | E40: DJ AL01048007 | F40: =COUNTIFS(Trechos!$L$2:$L$275,A40)&" vãos" -> 2 vãos | I40: =SUMIFS(Trechos!$F$2:$F$275,Trechos!$L$2:$L$275,A40) -> 38.914441 | L40: 0300043007 | M40: — | N40: =Blocos!AA4 -> 0300043007, 0301038007, 0301039007, 0301117007, 0201291007, 0302253007, 0301273007
...

Sheet Trechos
A1: Seq | B1: Trecho | C1: Trecho no Daimon | D1: Poste início | E1: Poste fim | F1: Extensão (m) | G1: Distância do DJ até o fim (m) | H1: Distância do ativo de referência até o fim (m) | I1: Zona | J1: Tronco/Ramal | K1: Ramal | L1: Bloco | M1: Ativo de referência | N1: Tipo do ativo de referência | O1: Próximo(s) ativo(s) | P1: Ativos posteriores englobados | Q1: Qtd. ativos posteriores | R1: Outra chave no fim do vão (88…) | S1: Nível 1 | T1: Nível 2 | U1: Nível 3 | V1: Nível 4 | W1: Nível 5 | X1: Caminho desde o DJ | Y1: Latitude (meio do vão) | Z1: Longitude (meio do vão) | AA1: Mapa | AB1: Chave do caminho (uso das fórmulas)
A2: 1 | B2: TR-001 | C2: 3050603 | D2: 1478970 | E2: N3 | F2: 41.56866 | G2: 41.56866 | H2: 41.56866 | I2: T1 | J2: Tronco | K2: Tronco | L2: 1 | M2: DJ AL01048007 | N2: Disjuntor (DJ) | O2: 7925573007 | P2: 7925573007, 0300040007, 0200038007, 0300111007, 0300115007, 0300145007, 0200114007, 0301201007, 0300109007, 0300068007, 0300070007, 0300073007, 0300074007, 0300065007, 0300062007, 0200061007, 0300057007, 0357094007, 0300056007, 0200055007, 0300050007, 0200475007, 0200047007 | Q2: 23 | S2: DJ AL01048007 | X2: DJ AL01048007 | Y2: -9.5767105 | Z2: -48.395626 | AA2: abrir | AB2: |DJ AL01048007|
A3: 2 | B3: TR-002 | C3: Suporte Chave 8800042007 | D3: N3 | E3: N4 | F3: 1.6822778 | G3: 43.250938 | H3: 43.250938 | I3: T1 | J3: Tronco | K3: Tronco | L3: 1 | M3: DJ AL01048007 | N3: Disjuntor (DJ) | O3: 7925573007 | P3: 7925573007, 0300040007, 0200038007, 0300111007, 0300115007, 0300145007, 0200114007, 0301201007, 0300109007, 0300068007, 0300070007, 0300073007, 0300074007, 0300065007, 0300062007, 0200061007, 0300057007, 0357094007, 0300056007, 0200055007, 0300050007, 0200475007, 0200047007 | Q3: 23 | R3: 8800042007 | S3: DJ AL01048007 | X3: DJ AL01048007 | Y3: -9.5765665 | Z3: -48.395754 | AA3: abrir | AB3: |DJ AL01048007|
A4: 3 | B4: TR-003 | C4: 2540074 | D4: N4 | E4: N6 | F4: 280.07955 | G4: 323.33049 | H4: 323.33049 | I4: T1 | J4: Tronco | K4: Tronco | L4: 1 | M4: DJ AL01048007 | N4: Disjuntor (DJ) | O4: 7925573007 | P4: 7925573007, 0300040007, 0200038007, 0300111007, 0300115007, 0300145007, 0200114007, 0301201007, 0300109007, 0300068007, 0300070007, 0300073007, 0300074007, 0300065007, 0300062007, 0200061007, 0300057007, 0357094007, 0300056007, 0200055007, 0300050007, 0200475007, 0200047007 | Q4: 23 | S4: DJ AL01048007 | X4: DJ AL01048007 | Y4: -9.575339 | Z4: -48.395436 | AA4: abrir | AB4: |DJ AL01048007|
A5: 4 | B5: TR-004 | C5: Suporte Chave 8808674007 | D5: N6 | E5: 145119 | F5: 1.6173316 | G5: 324.94782 | H5: 324.94782 | I5: T1 | J5: Tronco | K5: Tronco | L5: 1 | M5: DJ AL01048007 | N5: Disjuntor (DJ) | O5: 7925573007 | P5: 7925573007, 0300040007, 0200038007, 0300111007, 0300115007, 0300145007, 0200114007, 0301201007, 0300109007, 0300068007, 0300070007, 0300073007, 0300074007, 0300065007, 0300062007, 0200061007, 0300057007, 0357094007, 0300056007, 0200055007, 0300050007, 0200475007, 0200047007 | Q5: 23 | R5: 8808674007 | S5: DJ AL01048007 | X5: DJ AL01048007 | Y5: -9.574112 | Z5: -48.395117 | AA5: abrir | AB5: |DJ AL01048007|
A6: 5 | B6: TR-005 | C6: 3002072 | D6: 145119 | E6: N8 | F6: 14.398109 | G6: 339.34593 | H6: 339.34593 | I6: T1 | J6: Tronco | K6: Tronco | L6: 1 | M6: DJ AL01048007 | N6: Disjuntor (DJ) | O6: 7925573007 | P6: 7925573007, 0300040007, 0200038007, 0300111007, 0300115007, 0300145007, 0200114007, 0301201007, 0300109007, 0300068007, 0300070007, 0300073007, 0300074007, 0300065007, 0300062007, 0200061007, 0300057007, 0357094007, 0300056007, 0200055007, 0300050007, 0200475007, 0200047007 | Q6: 23 | S6: DJ AL01048007 | X6: DJ AL01048007 | Y6: -9.574044 | Z6: -48.395093 | AA6: abrir | AB6: |DJ AL01048007|
A7: 6 | B7: TR-006 | C7: 2540055 | D7: N8 | E7: N13 | F7: 170.41517 | G7: 509.7611 | H7: 509.7611 | I7: T1 | J7: Tronco | K7: Tronco | L7: 1 | M7: DJ AL01048007 | N7: Disjuntor (DJ) | O7: 7925573007 | P7: 7925573007, 0300040007, 0200038007, 0300111007, 0300115007, 0300145007, 0200114007, 0301201007, 0300109007, 0300068007, 0300070007, 0300073007, 0300074007, 0300065007, 0300062007, 0200061007, 0300057007, 0357094007, 0300056007, 0200055007, 0300050007 | Q7: 21 | S7: DJ AL01048007 | X7: DJ AL01048007 | Y7: -9.573242 | Z7: -48.394873 | AA7: abrir | AB7: |DJ AL01048007|
A8: 7 | B8: TR-007 | C8: 2690372 | D8: N13 | E8: 144496 | F8: 304.82191 | G8: 814.58301 | H8: 814.58301 | I8: T1 | J8: Tronco | K8: Tronco | L8: 1 | M8: DJ AL01048007 | N8: Disjuntor (DJ) | O8: 7925573007 | P8: 7925573007, 0300040007, 0200038007, 0300111007, 0300115007, 0300145007, 0200114007, 0301201007, 0300109007, 0300068007, 0300070007, 0300073007, 0300074007, 0300065007, 0300062007, 0200061007, 0300057007, 0357094007, 0300056007, 0200055007 | Q8: 20 | S8: DJ AL01048007 | X8: DJ AL01048007 | Y8: -9.5711775 | Z8: -48.394314 | AA8: abrir | AB8: |DJ AL01048007|
A9: 8 | B9: TR-008 | C9: 2540058 | D9: 144496 | E9: N21 | F9: 48.159534 | G9: 862.74254 | H9: 862.74254 | I9: T1 | J9: Tronco | K9: Tronco | L9: 1 | M9: DJ AL01048007 | N9: Disjuntor (DJ) | O9: 7925573007 | P9: 7925573007, 0300040007, 0200038007, 0300111007, 0300115007, 0300145007, 0200114007, 0301201007, 0300109007, 0300068007, 0300070007, 0300073007, 0300074007, 0300065007, 0300062007, 0200061007, 0300057007, 0357094007, 0300056007, 0200055007 | Q9: 20 | S9: DJ AL01048007 | X9: DJ AL01048007 | Y9: -9.569645 | Z9: -48.393895 | AA9: abrir | AB9: |DJ AL01048007|
A10: 9 | B10: TR-009 | C10: 2691019 | D10: N21 | E10: 145155 | F10: 83.231515 | G10: 945.97406 | H10: 945.97406 | I10: T1 | J10: Tronco | K10: Tronco | L10: 1 | M10: DJ AL01048007 | N10: Disjuntor (DJ) | O10: 7925573007 | P10: 7925573007, 0300040007, 0200038007, 0300111007, 0300115007, 0300145007, 0200114007, 0301201007, 0300109007, 0300068007, 0300070007, 0300073007, 0300074007, 0300065007, 0300062007, 0200061007, 0300057007, 0357094007, 0300056007, 0200055007 | Q10: 20 | S10: DJ AL01048007 | X10: DJ AL01048007 | Y10: -9.569542 | Z10: -48.393473 | AA10: abrir | AB10: |DJ AL01048007|
A11: 10 | B11: TR-010 | C11: Suporte Chave 8800054007 | D11: 145155 | E11: N28 | F11: 3.8195131 | G11: 949.79357 | H11: 949.79357 | I11: T1 | J11: Tronco | K11: Tronco | L11: 1 | M11: DJ AL01048007 | N11: Disjuntor (DJ) | O11: 7925573007 | P11: 7925573007, 0300040007, 0200038007, 0300111007, 0300115007, 0300145007, 0200114007, 0301201007, 0300109007, 0300068007, 0300070007, 0300073007, 0300074007, 0300065007, 0300062007, 0200061007, 0300057007, 0357094007, 0300056007, 0200055007 | Q11: 20 | R11: 8800054007 | S11: DJ AL01048007 | X11: DJ AL01048007 | Y11: -9.5696535 | Z11: -48.393093 | AA11: abrir | AB11: |DJ AL01048007|
A12: 11 | B12: TR-011 | C12: 2691022 | D12: N28 | E12: 145158 | F12: 103.14624 | G12: 1052.9398 | H12: 1052.9398 | I12: T1 | J12: Tronco | K12: Tronco | L12: 1 | M12: DJ AL01048007 | N12: Disjuntor (DJ) | O12: 7925573007 | P12: 7925573007, 0300040007, 0200038007, 0300111007, 0300115007, 0300145007, 0200114007, 0301201007, 0300109007, 0300068007, 0300070007, 0300073007, 0300074007, 0300065007, 0300062007, 0200061007, 0300057007, 0357094007, 0300056007, 0200055007 | Q12: 20 | S12: DJ AL01048007 | X12: DJ AL01048007 | Y12: -9.569789 | Z12: -48.392624 | AA12: abrir | AB12: |DJ AL01048007|
A13: 12 | B13: TR-012 | C13: 2690546 | D13: 145158 | E13: N32 | F13: 29.465725 | G13: 1082.4055 | H13: 1082.4055 | I13: T1 | J13: Tronco | K13: Tronco | L13: 1 | M13: DJ AL01048007 | N13: Disjuntor (DJ) | O13: 7925573007 | P13: 7925573007, 0300040007, 0200038007, 0300111007, 0300115007, 0300145007, 0200114007, 0301201007, 0300109007, 0300068007, 0300070007, 0300073007, 0300074007, 0300065007, 0300062007, 0200061007, 0300057007, 0357094007, 0300056007 | Q13: 19 | S13: DJ AL01048007 | X13: DJ AL01048007 | Y13: -9.5699525 | Z13: -48.392043 | AA13: abrir | AB13: |DJ AL01048007|
A14: 13 | B14: TR-013 | C14: 2690799 | D14: N32 | E14: 145048 | F14: 153.92026 | G14: 1236.3258 | H14: 1236.3258 | I14: T1 | J14: Tronco | K14: Tronco | L14: 1 | M14: DJ AL01048007 | N14: Disjuntor (DJ) | O14: 7925573007 | P14: 7925573007, 0300040007, 0200038007, 0300111007, 0300115007, 0300145007, 0200114007, 0301201007, 0300109007, 0300068007, 0300070007, 0300073007, 0300074007, 0300065007, 0300062007, 0200061007 | Q14: 16 | S14: DJ AL01048007 | X14: DJ AL01048007 | Y14: -9.56932 | Z14: -48.391722 | AA14: abrir | AB14: |DJ AL01048007|
A15: 14 | B15: TR-014 | C15: 2690632 | D15: 145048 | E15: 145047 | F15: 34.268223 | G15: 1270.594 | H15: 1270.594 | I15: T1 | J15: Tronco | K15: Tronco | L15: 1 | M15: DJ AL01048007 | N15: Disjuntor (DJ) | O15: 7925573007 | P15: 7925573007, 0300040007, 0200038007, 0300111007, 0300115007, 0300145007, 0200114007, 0301201007, 0300109007, 0300068007, 0300070007, 0300073007, 0300074007, 0300065007, 0300062007 | Q15: 15 | S15: DJ AL01048007 | X15: DJ AL01048007 | Y15: -9.568506 | Z15: -48.391487 | AA15: abrir | AB15: |DJ AL01048007|
A16: 15 | B16: TR-015 | C16: 2913371 | D16: 145047 | E16: N53 | F16: 20.192935 | G16: 1290.7869 | H16: 1290.7869 | I16: T1 | J16: Tronco | K16: Tronco | L16: 1 | M16: DJ AL01048007 | N16: Disjuntor (DJ) | O16: 7925573007 | P16: 7925573007, 0300040007, 0200038007, 0300111007, 0300115007, 0300145007, 0200114007, 0301201007, 0300109007, 0300068007, 0300070007, 0300073007, 0300074007, 0300065007 | Q16: 14 | S16: DJ AL01048007 | X16: DJ AL01048007 | Y16: -9.5682715 | Z16: -48.391416 | AA16: abrir | AB16: |DJ AL01048007|
A17: 16 | B17: TR-016 | C17: 2690521 | D17: N53 | E17: N59 | F17: 155.47565 | G17: 1446.2626 | H17: 1446.2626 | I17: T1 | J17: Tronco | K17: Tronco | L17: 1 | M17: DJ AL01048007 | N17: Disjuntor (DJ) | O17: 7925573007 | P17: 7925573007, 0300040007, 0200038007, 0300111007, 0300115007, 0300145007, 0200114007, 0301201007, 0300109007, 0300068007, 0300070007, 0300073007, 0300074007 | Q17: 13 | S17: DJ AL01048007 | X17: DJ AL01048007 | Y17: -9.5675165 | Z17: -48.39118 | AA17: abrir | AB17: |DJ AL01048007|
A18: 17 | B18: TR-017 | C18: Suporte Chave 9025573007 | D18: N59 | E18: N140 | F18: 0.24795168 | G18: 1446.5105 | H18: 1446.5105 | I18: T1 | J18: Tronco | K18: Tronco | L18: 1 | M18: DJ AL01048007 | N18: Disjuntor (DJ) | O18: 7925573007 | P18: 7925573007, 0300040007, 0200038007, 0300111007, 0300115007, 0300145007, 0200114007, 0301201007, 0300109007, 0300068007, 0300070007, 0300073007, 0300074007 | Q18: 13 | S18: DJ AL01048007 | X18: DJ AL01048007 | Y18: -9.566847 | Z18: -48.390972 | AA18: abrir | AB18: |DJ AL01048007|
A19: 18 | B19: TR-018 | C19: 3654912 | D19: N140 | E19: N141 | F19: 2.7396149 | G19: 1449.2502 | H19: 1449.2502 | I19: T1 | J19: Tronco | K19: Tronco | L19: 1 | M19: DJ AL01048007 | N19: Disjuntor (DJ) | O19: 7925573007 | P19: 7925573007, 0300040007, 0200038007, 0300111007, 0300115007, 0300145007, 0200114007, 0301201007, 0300109007, 0300068007, 0300070007, 0300073007, 0300074007 | Q19: 13 | S19: DJ AL01048007 | X19: DJ AL01048007 | Y19: -9.566838 | Z19: -48.390963 | AA19: abrir | AB19: |DJ AL01048007|
A20: 19 | B20: TR-019 | C20: Suporte Chave 7925573007 | D20: N141 | E20: N142 | F20: 0.11119493 | G20: 1449.3614 | H20: 1449.3614 | I20: T1 | J20: Tronco | K20: Tronco | L20: 1 | M20: DJ AL01048007 | N20: Disjuntor (DJ) | O20: 7925573007 | P20: 7925573007, 0300040007, 0200038007, 0300111007, 0300115007, 0300145007, 0200114007, 0301201007, 0300109007, 0300068007, 0300070007, 0300073007, 0300074007 | Q20: 13 | S20: DJ AL01048007 | X20: DJ AL01048007 | Y20: -9.5668295 | Z20: -48.390953 | AA20: abrir | AB20: |DJ AL01048007|
A21: 20 | B21: TR-020 | C21: 3654914 | D21: N142 | E21: N143 | F21: 1.8968617 | G21: 1451.2582 | H21: 1.8968617 | I21: T2 | J21: Tronco | K21: Tronco | L21: 2 | M21: 7925573007 | N21: Religador (79) | O21: fim N228 | P21: 0300040007, 0200038007, 0300111007, 0300115007, 0300145007, 0200114007, 0301201007, 0300109007, 0300068007, 0300070007, 0300073007, 0300074007 | Q21: 12 | S21: DJ AL01048007 | T21: 7925573007 | X21: DJ AL01048007 › 7925573007 | Y21: -9.566821 | Z21: -48.39095 | AA21: abrir | AB21: |DJ AL01048007|7925573007|
A22: 21 | B22: TR-021 | C22: Suporte Chave 9000067007 | D22: N143 | E22: 1251159 | F22: 0.24795168 | G22: 1451.5062 | H22: 2.1448133 | I22: T2 | J22: Tronco | K22: Tronco | L22: 2 | M22: 7925573007 | N22: Religador (79) | O22: fim N228 | P22: 0300040007, 0200038007, 0300111007, 0300115007, 0300145007, 0200114007, 0301201007, 0300109007, 0300068007, 0300070007, 0300073007, 0300074007 | Q22: 12 | S22: DJ AL01048007 | T22: 7925573007 | X22: DJ AL01048007 › 7925573007 | Y22: -9.566812 | Z22: -48.390948 | AA22: abrir | AB22: |DJ AL01048007|7925573007|
A23: 22 | B23: TR-022 | C23: 3654913 | D23: 1251159 | E23: N152 | F23: 2.7485749 | G23: 1454.2547 | H23: 4.8933882 | I23: T2 | J23: Tronco | K23: Tronco | L23: 2 | M23: 7925573007 | N23: Religador (79) | O23: fim N228 | P23: 0300040007, 0200038007, 0300111007, 0300115007, 0300145007, 0200114007, 0301201007, 0300109007, 0300068007, 0300070007, 0300073007, 0300074007 | Q23: 12 | S23: DJ AL01048007 | T23: 7925573007 | X23: DJ AL01048007 › 7925573007 | Y23: -9.566799 | Z23: -48.390951 | AA23: abrir | AB23: |DJ AL01048007|7925573007|
A24: 23 | B24: TR-023 | C24: 2904780 | D24: N152 | E24: 144482 | F24: 58.215048 | G24: 1512.4698 | H24: 63.108436 | I24: T2 | J24: Tronco | K24: Tronco | L24: 2 | M24: 7925573007 | N24: Religador (79) | O24: fim N228 | P24: 0300040007, 0200038007, 0300111007, 0300115007, 0300145007, 0200114007, 0301201007, 0300109007, 0300068007, 0300070007, 0300073007, 0300074007 | Q24: 12 | S24: DJ AL01048007 | T24: 7925573007 | X24: DJ AL01048007 › 7925573007 | Y24: -9.5665305 | Z24: -48.391007 | AA24: abrir | AB24: |DJ AL01048007|7925573007|
A25: 24 | B25: TR-024 | C25: 2690429 | D25: 144482 | E25: N155 | F25: 22.660938 | G25: 1535.1307 | H25: 85.769374 | I25: T2 | J25: Tronco | K25: Tronco | L25: 2 | M25: 7925573007 | N25: Religador (79) | O25: fim N228 | P25: 0300040007, 0200038007, 0300111007, 0300115007, 0300145007, 0200114007, 0301201007, 0300109007 | Q25: 8 | S25: DJ AL01048007 | T25: 7925573007 | X25: DJ AL01048007 › 7925573007 | Y25: -9.5662465 | Z25: -48.39116 | AA25: abrir | AB25: |DJ AL01048007|7925573007|
A26: 25 | B26: TR-025 | C26: 2690630 | D26: N155 | E26: 145523 | F26: 41.187563 | G26: 1576.3183 | H26: 126.95694 | I26: T2 | J26: Tronco | K26: Tronco | L26: 2 | M26: 7925573007 | N26: Religador (79) | O26: fim N228 | P26: 0300040007, 0200038007 | Q26: 2 | S26: DJ AL01048007 | T26: 7925573007 | X26: DJ AL01048007 › 7925573007 | Y26: -9.5661645 | Z26: -48.391438 | AA26: abrir | AB26: |DJ AL01048007|7925573007|
A27: 26 | B27: TR-026 | C27: 2690256 | D27: 145523 | E27: 47444546 | F27: 95.135421 | G27: 1671.4537 | H27: 222.09236 | I27: T2 | J27: Tronco | K27: Tronco | L27: 2 | M27: 7925573007 | N27: Religador (79) | O27: fim N228 | P27: 0300040007, 0200038007 | Q27: 2 | S27: DJ AL01048007 | T27: 7925573007 | X27: DJ AL01048007 › 7925573007 | Y27: -9.565987 | Z27: -48.392033 | AA27: abrir | AB27: |DJ AL01048007|7925573007|
A28: 27 | B28: TR-027 | C28: 2690258 | D28: 47444546 | E28: 145527 | F28: 77.064587 | G28: 1748.5183 | H28: 299.15695 | I28: T2 | J28: Tronco | K28: Tronco | L28: 2 | M28: 7925573007 | N28: Religador (79) | O28: fim N228 | P28: 0300040007, 0200038007 | Q28: 2 | S28: DJ AL01048007 | T28: 7925573007 | X28: DJ AL01048007 › 7925573007 | Y28: -9.565749 | Z28: -48.392781 | AA28: abrir | AB28: |DJ AL01048007|7925573007|
A29: 28 | B29: TR-028 | C29: Suporte Chave 8800075007 | D29: 145527 | E29: N172 | F29: 3.4383273 | G29: 1751.9566 | H29: 302.59527 | I29: T2 | J29: Tronco | K29: Tronco | L29: 2 | M29: 7925573007 | N29: Religador (79) | O29: fim N228 | P29: 0300040007, 0200038007 | Q29: 2 | R29: 8800075007 | S29: DJ AL01048007 | T29: 7925573007 | X29: DJ AL01048007 › 7925573007 | Y29: -9.5656295 | Z29: -48.393127 | AA29: abrir | AB29: |DJ AL01048007|7925573007|
A30: 29 | B30: TR-029 | C30: 2690260 | D30: N172 | E30: 145531 | F30: 148.45724 | G30: 1900.4139 | H30: 451.05252 | I30: T2 | J30: Tronco | K30: Tronco | L30: 2 | M30: 7925573007 | N30: Religador (79) | O30: fim N228 | P30: 0300040007, 0200038007 | Q30: 2 | S30: DJ AL01048007 | T30: 7925573007 | X30: DJ AL01048007 › 7925573007 | Y30: -9.565406 | Z30: -48.393782 | AA30: abrir | AB30: |DJ AL01048007|7925573007|
A31: 30 | B31: TR-030 | C31: 2690435 | D31: 145531 | E31: 145510 | F31: 38.02473 | G31: 1938.4386 | H31: 489.07725 | I31: T2 | J31: Tronco | K31: Tronco | L31: 2 | M31: 7925573007 | N31: Religador (79) | O31: fim N228 | P31: 0300040007, 0200038007 | Q31: 2 | S31: DJ AL01048007 | T31: 7925573007 | X31: DJ AL01048007 › 7925573007 | Y31: -9.565136 | Z31: -48.394587 | AA31: abrir | AB31: |DJ AL01048007|7925573007|
A32: 31 | B32: TR-031 | C32: 3252616 | D32: 145510 | E32: N197 | F32: 6.7718383 | G32: 1945.2104 | H32: 495.84908 | I32: T2 | J32: Tronco | K32: Tronco | L32: 2 | M32: 7925573007 | N32: Religador (79) | O32: fim N228 | P32: 0300040007 | Q32: 1 | S32: DJ AL01048007 | T32: 7925573007 | X32: DJ AL01048007 › 7925573007 | Y32: -9.565076 | Z32: -48.394782 | AA32: abrir | AB32: |DJ AL01048007|7925573007|
A33: 32 | B33: TR-032 | C33: 2690189 | D33: N197 | E33: N213 | F33: 287.45402 | G33: 2232.6645 | H33: 783.30311 | I33: T2 | J33: Tronco | K33: Tronco | L33: 2 | M33: 7925573007 | N33: Religador (79) | O33: fim N228 | P33: 0300040007 | Q33: 1 | S33: DJ AL01048007 | T33: 7925573007 | X33: DJ AL01048007 › 7925573007 | Y33: -9.5646795 | Z33: -48.396062 | AA33: abrir | AB33: |DJ AL01048007|7925573007|
A34: 33 | B34: TR-033 | C34: 2690187 | D34: N213 | E34: 145502 | F34: 73.415709 | G34: 2306.0802 | H34: 856.71882 | I34: T2 | J34: Tronco | K34: Tronco | L34: 2 | M34: 7925573007 | N34: Religador (79) | O34: fim N228 | P34: 0300040007 | Q34: 1 | S34: DJ AL01048007 | T34: 7925573007 | X34: DJ AL01048007 › 7925573007 | Y34: -9.564183 | Z34: -48.397628 | AA34: abrir | AB34: |DJ AL01048007|7925573007|
A35: 34 | B35: TR-034 | C35: 2690186 | D35: 145502 | E35: 145501 | F35: 35.465519 | G35: 2341.5457 | H35: 892.18434 | I35: T2 | J35: Tronco | K35: Tronco | L35: 2 | M35: 7925573007 | N35: Religador (79) | O35: fim N228 | P35: 0300040007 | Q35: 1 | S35: DJ AL01048007 | T35: 7925573007 | X35: DJ AL01048007 › 7925573007 | Y35: -9.564012 | Z35: -48.398093 | AA35: abrir | AB35: |DJ AL01048007|7925573007|
A36: 35 | B36: TR-035 | C36: 2690185 | D36: 145501 | E36: N227 | F36: 63.66279 | G36: 2405.2085 | H36: 955.84713 | I36: T2 | J36: Tronco | K36: Tronco | L36: 2 | M36: 7925573007 | N36: Religador (79) | O36: fim N228 | P36: — | Q36: 0 | S36: DJ AL01048007 | T36: 7925573007 | X36: DJ AL01048007 › 7925573007 | Y36: -9.5638105 | Z36: -48.398496 | AA36: abrir | AB36: |DJ AL01048007|7925573007|
A37: 36 | B37: TR-036 | C37: 3654905 | D37: N227 | E37: N228 | F37: 4.5625139 | G37: 2409.771 | H37: 960.40964 | I37: T2 | J37: Tronco | K37: Tronco | L37: 2 | M37: 7925573007 | N37: Religador (79) | O37: fim N228 | P37: — | Q37: 0 | S37: DJ AL01048007 | T37: 7925573007 | X37: DJ AL01048007 › 7925573007 | Y37: -9.5636745 | Z37: -48.39877 | AA37: abrir | AB37: |DJ AL01048007|7925573007|
A38: 37 | B38: TR-037 | C38: 2676256 | D38: 1478970 | E38: 145116 | F38: 37.178789 | G38: 37.178789 | H38: 37.178789 | I38: T1 | J38: Ramal | K38: Ramal 1478970 | L38: 3 | M38: DJ AL01048007 | N38: Disjuntor (DJ) | O38: 0300043007 | P38: 0300043007, 0301038007, 0301039007, 0301117007, 0201291007, 0302253007, 0301273007 | Q38: 7 | S38: DJ AL01048007 | X38: DJ AL01048007 | Y38: -9.5768285 | Z38: -48.395665 | AA38: abrir | AB38: |DJ AL01048007|
A39: 38 | B39: TR-038 | C39: Suporte Chave 0300043007 | D39: 145116 | E39: N2 | F39: 1.7356518 | G39: 38.914441 | H39: 38.914441 | I39: T1 | J39: Ramal | K39: Ramal 1478970 | L39: 3 | M39: DJ AL01048007 | N39: Disjuntor (DJ) | O39: 0300043007 | P39: 0300043007, 0301038007, 0301039007, 0301117007, 0201291007, 0302253007, 0301273007 | Q39: 7 | S39: DJ AL01048007 | X39: DJ AL01048007 | Y39: -9.576817 | Z39: -48.395837 | AA39: abrir | AB39: |DJ AL01048007|
A40: 39 | B40: TR-039 | C40: 2803096 | D40: N2 | E40: 1363488 | F40: 245.38344 | G40: 284.29789 | H40: 245.38344 | I40: T3 | J40: Ramal | K40: Ramal 1478970 | L40: 4 | M40: 0300043007 | N40: Chave fusível (03) | O40: 0301038007 / fim 69120630 / 0301117007 / fim 299845 / 0301273007 | P40: 0301038007, 0301039007, 0301117007, 0201291007, 0302253007, 0301273007 | Q40: 6 | S40: DJ AL01048007 | T40: 0300043007 | X40: DJ AL01048007 › 0300043007 | Y40: -9.577873 | Z40: -48.396187 | AA40: abrir | AB40: |DJ AL01048007|0300043007|
...

Sheet Ativos
A1: Ativo | B1: Tipo | C1: Poste | D1: No tronco | E1: Zona antes | F1: Zona depois | G1: Bloco onde está | H1: Blocos em que é referência | I1: Caminho desde o DJ | J1: Vãos em que é a referência | K1: Extensão em que é a referência (m) | L1: Vãos englobados (tudo a jusante) | M1: Extensão englobada (m) | N1: Ativos posteriores englobados | O1: Latitude | P1: Longitude | Q1: Mapa
A2: DJ AL01048007 | B2: Disjuntor (DJ) | C2: 1478970 | D2: sim | E2: — | F2: T1 | G2: — | H2: 1, 3, 11, 14, 16, 17, 19, 23, 25, 27, 29 | I2: DJ AL01048007 | J2: =COUNTIFS(Trechos!$M$2:$M$275,A2) -> 53 | K2: =SUMIFS(Trechos!$F$2:$F$275,Trechos!$M$2:$M$275,A2) -> 2635 | L2: =SUMPRODUCT(--ISNUMBER(SEARCH("|"&A2&"|",Trechos!$AB$2:$AB$275))) -> 274 | M2: =SUMPRODUCT(ISNUMBER(SEARCH("|"&A2&"|",Trechos!$AB$2:$AB$275))*Trechos!$F$2:$F$275) -> 15315.766 | N2: 7925573007, 0300040007, 0200038007, 0300111007, 0300115007, 0300145007, 0200114007, 0301201007, 0300109007, 0300068007, 0300070007, 0300073007, 0300074007, 0300065007, 0300062007, 0200061007, 0300057007, 0357094007, 0300056007, 0200055007, 0300050007, 0200475007, 0200047007, 0300043007, 0301038007, 0301039007, 0301117007, 0201291007, 0302253007, 0301273007 | O2: -9.576847 | P2: -48.395496 | Q2: abrir
A3: 8800042007 | B3: Chave 88 | C3: N4 | D3: sim | E3: T1 | F3: T1 | G3: 1 | H3: — | I3: DJ AL01048007 | N3: 7925573007, 0300040007, 0200038007, 0300111007, 0300115007, 0300145007, 0200114007, 0301201007, 0300109007, 0300068007, 0300070007, 0300073007, 0300074007, 0300065007, 0300062007, 0200061007, 0300057007, 0357094007, 0300056007, 0200055007, 0300050007, 0200475007, 0200047007 | O3: -9.576559 | P3: -48.395753 | Q3: abrir
A4: 8808674007 | B4: Chave 88 | C4: 145119 | D4: sim | E4: T1 | F4: T1 | G4: 1 | H4: — | I4: DJ AL01048007 | N4: 7925573007, 0300040007, 0200038007, 0300111007, 0300115007, 0300145007, 0200114007, 0301201007, 0300109007, 0300068007, 0300070007, 0300073007, 0300074007, 0300065007, 0300062007, 0200061007, 0300057007, 0357094007, 0300056007, 0200055007, 0300050007, 0200475007, 0200047007 | O4: -9.574105 | P4: -48.395115 | Q4: abrir
A5: 8800054007 | B5: Chave 88 | C5: N28 | D5: sim | E5: T1 | F5: T1 | G5: 1 | H5: — | I5: DJ AL01048007 | N5: 7925573007, 0300040007, 0200038007, 0300111007, 0300115007, 0300145007, 0200114007, 0301201007, 0300109007, 0300068007, 0300070007, 0300073007, 0300074007, 0300065007, 0300062007, 0200061007, 0300057007, 0357094007, 0300056007, 0200055007 | O5: -9.569659 | P5: -48.393076 | Q5: abrir
