Workbook

Sheet Leia-me
A1: Zonas, ramais e blocos — AL04010004
A3: Zona | B3: T1 do DJ ao 1º religador (79). Depois de qualquer religador é T2, inclusive religador em ramal: religador nunca cria T3. Depois de uma chave fusível (03) é no mínimo T3; se já estava em T3 ou mais, soma uma.
A4: Seccionamento | B4: Chave 03/33/02 com religador depois dela não conta como fusível: não muda a zona e aparece em "Outras chaves no bloco (88…)" como "Chave 03 de seccionamento".
A5: Tronco | B5: Caminho DJ → 1º religador → 2º religador e, depois do 2º, até os próximos ativos (religador ou fusível): o trecho entre dois ativos do tronco ainda é tronco. Pontas sem equipamento são ramal. Nunca tem T3. O resto é ramal, com o nome do poste onde sai do tronco.
A6: Ativo de referência | B6: Último DJ, 79 ou 03 antes do vão, vindo do DJ. Ele engloba o vão e tudo o que vem depois.
A7: Ativos posteriores englobados | B7: Os DJ/79/03 que ficam depois do vão ou do bloco. Se o ativo de referência abrir, todos ficam sem energia.
A8: Bloco | B8: Vãos com o mesmo ativo de referência e o mesmo ramal (de um ativo até o próximo). Chaves 88 e outras que não são DJ/79/fusível não dividem bloco: aparecem na coluna "Outras chaves no bloco (88…)". Chaves 02 e 33 contam como fusível.
A9: Nível 1…N | B9: Sequência de ativos desde o DJ até o ativo de referência. Filtrar um nível mostra tudo o que fica depois daquele ativo.
A10: Distâncias | B10: Calculadas a partir das coordenadas (haversine, raio 6.371 km), seguindo a rede.
A11: Abas | B11: Árvore de blocos: visão rápida da sequência, agrupada por tronco e ramal. Consulta: digite um poste e veja onde ele está. Blocos: um bloco por linha, com os ativos posteriores um por coluna e juntos numa coluna só. Por bloco: os vãos agrupados embaixo de cada bloco (botão + à esquerda). Trechos: um vão por linha. Ativos: resumo por ativo.
A13: Cores das zonas
A14: T1
A15: T2
A16: T3
A17: T4
A18: T5

Sheet Árvore de blocos
A1: Árvore de blocos — AL04010004
A2: Cada linha é um bloco. A célula colorida é o ativo de referência do bloco (cor da zona). As células em cinza à esquerda são os ativos antes dele, desde o DJ.
A3: Zonas: | B3: T1 | C3: T2 | D3: T3 | E3: T4 | F3: T5
A5: Bloco | B5: Zona | C5: Nível 1 | D5: Nível 2 | E5: Nível 3 | F5: Nível 4 | G5: Nível 5 | H5: De | I5: Até (próximos ativos) | J5: Vãos | K5: Extensão (m) | L5: Outras chaves no bloco (88…) | M5: Ativos englobados (depois do bloco)
A6: TRONCO — do DJ ao 2º religador e até os próximos ativos
A7: 1 | B7: T1 | C7: DJ AL04010004 | H7: DJ AL04010004 | I7: 7903565004 | J7: =COUNTIFS(Trechos!$L$2:$L$526,A7) -> 62 | K7: =SUMIFS(Trechos!$F$2:$F$526,Trechos!$L$2:$L$526,A7) -> 2972.1647 | L7: 8800004004, 8804421004, 8802681004, 8847597004, 8802014004, 8800554004, 8801115004 | M7: =Blocos!AU2 -> 7903565004, 7935867004, 7902218004, 0330915004, 0203711004, 0202227004, 0204190004, 0200482004, 0200484004, 0200489004, 0200490004, 0230938004, 0200492004, 0202676004, 0303862004, 0229036004, 0200495004, 0201153004, 0352542004, 0300603004, 0203117004, 0202175004, 0300600004, 0203661004, 0300596004, 0300588004, 0300591004, 0200593004, 0224749004, 0200583004, 0300584004, 0300585004, 0300582004, 0204195004, 0300578004, 0229381004, 0200580004, 0202671004, 0204249004, 0200868004, 0200573004, 0200571004, 0230252004, 0303731004, 0200556004, 0303973004, 0200550004, 0201875004, 0200549004, 0200548004, 0200547004, 0345761004, 0201072004
A8: 2 | B8: T2 | C8: DJ AL04010004 | D8: 7903565004 | H8: 7903565004 | I8: 7935867004 | J8: =COUNTIFS(Trechos!$L$2:$L$526,A8) -> 28 | K8: =SUMIFS(Trechos!$F$2:$F$526,Trechos!$L$2:$L$526,A8) -> 1067.0564 | L8: 8841355004 | M8: =Blocos!AU3 -> 7935867004, 7902218004, 0330915004, 0203711004, 0202227004, 0204190004, 0200482004, 0200484004, 0200489004, 0200490004, 0230938004, 0200492004, 0202676004, 0303862004, 0229036004, 0200495004, 0201153004, 0352542004, 0300603004, 0203117004, 0202175004, 0300600004, 0203661004, 0300596004, 0300588004, 0300591004, 0200593004, 0224749004, 0200583004, 0300584004, 0300585004, 0300582004, 0204195004, 0300578004, 0229381004, 0200580004, 0202671004, 0204249004, 0200868004, 0200573004, 0200571004, 0230252004, 0303731004, 0200556004, 0303973004
A9: 3 | B9: T2 | C9: DJ AL04010004 | D9: 7903565004 | E9: 7935867004 | H9: 7935867004 | I9: 7902218004 / 0352542004 / 0300603004 / 0203117004 / 0202175004 / 0300600004 | J9: =COUNTIFS(Trechos!$L$2:$L$526,A9) -> 55 | K9: =SUMIFS(Trechos!$F$2:$F$526,Trechos!$L$2:$L$526,A9) -> 1795.8328 | L9: 8834608004, 8800606004, 8843255004, 8800599004 | M9: =Blocos!AU4 -> 7902218004, 0330915004, 0203711004, 0202227004, 0204190004, 0200482004, 0200484004, 0200489004, 0200490004, 0230938004, 0200492004, 0202676004, 0303862004, 0229036004, 0200495004, 0201153004, 0352542004, 0300603004, 0203117004, 0202175004, 0300600004
A10: RAMAL 587997 — sai do tronco no poste 587997
A11: 4 | B11: T1 | C11: DJ AL04010004 | H11: poste 587997 | I11: fim 25524195 / fim 65878548 | J11: =COUNTIFS(Trechos!$L$2:$L$526,A11) -> 6 | K11: =SUMIFS(Trechos!$F$2:$F$526,Trechos!$L$2:$L$526,A11) -> 343.48266 | L11: — | M11: =Blocos!AU5 -> —
A12: RAMAL 122086 — sai do tronco no poste 122086
A13: 5 | B13: T1 | C13: DJ AL04010004 | H13: poste 122086 | I13: fim N34 | J13: =COUNTIFS(Trechos!$L$2:$L$526,A13) -> 1 | K13: =SUMIFS(Trechos!$F$2:$F$526,Trechos!$L$2:$L$526,A13) -> 8.4653287 | L13: — | M13: =Blocos!AU6 -> —
A14: RAMAL 104546 — sai do tronco no poste 104546
A15: 6 | B15: T1 | C15: DJ AL04010004 | H15: poste 104546 | I15: 0201072004 | J15: =COUNTIFS(Trechos!$L$2:$L$526,A15) -> 1 | K15: =SUMIFS(Trechos!$F$2:$F$526,Trechos!$L$2:$L$526,A15) -> 1.0068168 | L15: — | M15: =Blocos!AU7 -> 0201072004
A16: 7 | B16: T3 | C16: DJ AL04010004 | D16: 0201072004 | H16: 0201072004 | I16: fim N85 | J16: =COUNTIFS(Trechos!$L$2:$L$526,A16) -> 2 | K16: =SUMIFS(Trechos!$F$2:$F$526,Trechos!$L$2:$L$526,A16) -> 22.323525 | L16: — | M16: =Blocos!AU8 -> —
A17: RAMAL 33261324 — sai do tronco no poste 33261324
A18: 8 | B18: T1 | C18: DJ AL04010004 | H18: poste 33261324 | I18: 0345761004 | J18: =COUNTIFS(Trechos!$L$2:$L$526,A18) -> 1 | K18: =SUMIFS(Trechos!$F$2:$F$526,Trechos!$L$2:$L$526,A18) -> 1.0205312 | L18: — | M18: =Blocos!AU9 -> 0345761004
A19: 9 | B19: T3 | C19: DJ AL04010004 | D19: 0345761004 | H19: 0345761004 | I19: fim 33308575 | J19: =COUNTIFS(Trechos!$L$2:$L$526,A19) -> 1 | K19: =SUMIFS(Trechos!$F$2:$F$526,Trechos!$L$2:$L$526,A19) -> 8.5499772 | L19: — | M19: =Blocos!AU10 -> —
A20: RAMAL 94069 — sai do tronco no poste 94069
A21: 10 | B21: T1 | C21: DJ AL04010004 | H21: poste 94069 | I21: 0200547004 | J21: =COUNTIFS(Trechos!$L$2:$L$526,A21) -> 1 | K21: =SUMIFS(Trechos!$F$2:$F$526,Trechos!$L$2:$L$526,A21) -> 0.55440619 | L21: — | M21: =Blocos!AU11 -> 0200547004
A22: 11 | B22: T3 | C22: DJ AL04010004 | D22: 0200547004 | H22: 0200547004 | I22: fim 94065 | J22: =COUNTIFS(Trechos!$L$2:$L$526,A22) -> 1 | K22: =SUMIFS(Trechos!$F$2:$F$526,Trechos!$L$2:$L$526,A22) -> 3.8390204 | L22: — | M22: =Blocos!AU12 -> —
A23: RAMAL 94068 — sai do tronco no poste 94068
A24: 12 | B24: T1 | C24: DJ AL04010004 | H24: poste 94068 | I24: 0200548004 | J24: =COUNTIFS(Trechos!$L$2:$L$526,A24) -> 1 | K24: =SUMIFS(Trechos!$F$2:$F$526,Trechos!$L$2:$L$526,A24) -> 1.021764 | L24: — | M24: =Blocos!AU13 -> 0200548004
A25: 13 | B25: T3 | C25: DJ AL04010004 | D25: 0200548004 | H25: 0200548004 | I25: fim 94064 | J25: =COUNTIFS(Trechos!$L$2:$L$526,A25) -> 1 | K25: =SUMIFS(Trechos!$F$2:$F$526,Trechos!$L$2:$L$526,A25) -> 8.854961 | L25: — | M25: =Blocos!AU14 -> —
A26: RAMAL 20392852 — sai do tronco no poste 20392852
A27: 14 | B27: T1 | C27: DJ AL04010004 | H27: poste 20392852 | I27: 0200549004 | J27: =COUNTIFS(Trechos!$L$2:$L$526,A27) -> 1 | K27: =SUMIFS(Trechos!$F$2:$F$526,Trechos!$L$2:$L$526,A27) -> 1.0430959 | L27: — | M27: =Blocos!AU15 -> 0200549004
A28: 15 | B28: T3 | C28: DJ AL04010004 | D28: 0200549004 | H28: 0200549004 | I28: fim 94063 | J28: =COUNTIFS(Trechos!$L$2:$L$526,A28) -> 1 | K28: =SUMIFS(Trechos!$F$2:$F$526,Trechos!$L$2:$L$526,A28) -> 9.0630126 | L28: — | M28: =Blocos!AU16 -> —
A29: RAMAL 552519 — sai do tronco no poste 552519
A30: 16 | B30: T1 | C30: DJ AL04010004 | H30: poste 552519 | I30: fim 832105 | J30: =COUNTIFS(Trechos!$L$2:$L$526,A30) -> 2 | K30: =SUMIFS(Trechos!$F$2:$F$526,Trechos!$L$2:$L$526,A30) -> 79.282946 | L30: — | M30: =Blocos!AU17 -> —
A31: RAMAL 272816 — sai do tronco no poste 272816
A32: 17 | B32: T1 | C32: DJ AL04010004 | H32: poste 272816 | I32: 0201875004 | J32: =COUNTIFS(Trechos!$L$2:$L$526,A32) -> 1 | K32: =SUMIFS(Trechos!$F$2:$F$526,Trechos!$L$2:$L$526,A32) -> 0.95157043 | L32: — | M32: =Blocos!AU18 -> 0201875004
A33: 18 | B33: T3 | C33: DJ AL04010004 | D33: 0201875004 | H33: 0201875004 | I33: fim 272817 | J33: =COUNTIFS(Trechos!$L$2:$L$526,A33) -> 1 | K33: =SUMIFS(Trechos!$F$2:$F$526,Trechos!$L$2:$L$526,A33) -> 8.6844675 | L33: — | M33: =Blocos!AU19 -> —
A34: RAMAL 94067 — sai do tronco no poste 94067
A35: 19 | B35: T1 | C35: DJ AL04010004 | H35: poste 94067 | I35: 0200550004 | J35: =COUNTIFS(Trechos!$L$2:$L$526,A35) -> 1 | K35: =SUMIFS(Trechos!$F$2:$F$526,Trechos!$L$2:$L$526,A35) -> 0.86567317 | L35: — | M35: =Blocos!AU20 -> 0200550004
A36: 20 | B36: T3 | C36: DJ AL04010004 | D36: 0200550004 | H36: 0200550004 | I36: fim N96 / fim N97 | J36: =COUNTIFS(Trechos!$L$2:$L$526,A36) -> 3 | K36: =SUMIFS(Trechos!$F$2:$F$526,Trechos!$L$2:$L$526,A36) -> 46.711058 | L36: — | M36: =Blocos!AU21 -> —
A37: RAMAL 26974937 — sai do tronco no poste 26974937
A38: 21 | B38: T1 | C38: DJ AL04010004 | H38: poste 26974937 | I38: fim 106594 / fim 538410 / fim 539777 / fim 550142 / fim 539569 / fim 535127 / fim 538391 / fim 536377 / fim N123 | J38: =COUNTIFS(Trechos!$L$2:$L$526,A38) -> 24 | K38: =SUMIFS(Trechos!$F$2:$F$526,Trechos!$L$2:$L$526,A38) -> 1142.2202 | L38: — | M38: =Blocos!AU22 -> —
A39: RAMAL 550921 — sai do tronco no poste 550921
A40: 22 | B40: T1 | C40: DJ AL04010004 | H40: poste 550921 | I40: fim N82 / fim N122 | J40: =COUNTIFS(Trechos!$L$2:$L$526,A40) -> 10 | K40: =SUMIFS(Trechos!$F$2:$F$526,Trechos!$L$2:$L$526,A40) -> 134.24053 | L40: — | M40: =Blocos!AU23 -> —
A41: RAMAL N68 — sai do tronco no poste N68
...

Sheet Consulta
A1: Onde fica este poste?
A2: Digite o código do poste na célula amarela (o poste no fim do vão). A planilha mostra o vão e a sequência desde o DJ.
A4: Poste | B4: 22938819 | C4: ← exemplo
A6: Trecho (vão) | B6: =IFERROR(INDEX(Trechos!$B$2:$B$526,MATCH($B$4,Trechos!$E$2:$E$526,0)),"poste não encontrado") -> TR-525
A7: Poste início | B7: =IFERROR(INDEX(Trechos!$D$2:$D$526,MATCH($B$4,Trechos!$E$2:$E$526,0)),"poste não encontrado") -> N389
A8: Zona | B8: =IFERROR(INDEX(Trechos!$I$2:$I$526,MATCH($B$4,Trechos!$E$2:$E$526,0)),"poste não encontrado") -> T3
A9: Tronco/Ramal | B9: =IFERROR(INDEX(Trechos!$J$2:$J$526,MATCH($B$4,Trechos!$E$2:$E$526,0)),"poste não encontrado") -> Ramal
A10: Ramal | B10: =IFERROR(INDEX(Trechos!$K$2:$K$526,MATCH($B$4,Trechos!$E$2:$E$526,0)),"poste não encontrado") -> Ramal após 0352542004
A11: Bloco | B11: =IFERROR(INDEX(Trechos!$L$2:$L$526,MATCH($B$4,Trechos!$E$2:$E$526,0)),"poste não encontrado") -> 97
A12: Ativo de referência | B12: =IFERROR(INDEX(Trechos!$M$2:$M$526,MATCH($B$4,Trechos!$E$2:$E$526,0)),"poste não encontrado") -> 0352542004
A13: Distância do ativo de referência (m) | B13: =IFERROR(INDEX(Trechos!$H$2:$H$526,MATCH($B$4,Trechos!$E$2:$E$526,0)),"poste não encontrado") -> 20.635027
A14: Distância do DJ (m) | B14: =IFERROR(INDEX(Trechos!$G$2:$G$526,MATCH($B$4,Trechos!$E$2:$E$526,0)),"poste não encontrado") -> 5685.8732
A15: Ativos posteriores englobados | B15: =IFERROR(INDEX(Trechos!$P$2:$P$526,MATCH($B$4,Trechos!$E$2:$E$526,0)),"poste não encontrado") -> —
A16: Outra chave no fim do vão (88…) | B16: =IFERROR(INDEX(Trechos!$R$2:$R$526,MATCH($B$4,Trechos!$E$2:$E$526,0)),"poste não encontrado") -> 0
A17: Caminho desde o DJ | B17: =IFERROR(INDEX(Trechos!$X$2:$X$526,MATCH($B$4,Trechos!$E$2:$E$526,0)),"poste não encontrado") -> DJ AL04010004 › 7903565004 › 7935867004 › 0352542004
A18: Latitude | B18: =IFERROR(INDEX(Trechos!$Y$2:$Y$526,MATCH($B$4,Trechos!$E$2:$E$526,0)),"poste não encontrado") -> -7.188997
A19: Longitude | B19: =IFERROR(INDEX(Trechos!$Z$2:$Z$526,MATCH($B$4,Trechos!$E$2:$E$526,0)),"poste não encontrado") -> -48.206615

Sheet Blocos
A1: Bloco | B1: Zona | C1: Tronco/Ramal | D1: Ramal | E1: Ativo de referência | F1: De | G1: Próximo ativo 1 | H1: Próximo ativo 2 | I1: Próximo ativo 3 | J1: Próximo ativo 4 | K1: Próximo ativo 5 | L1: Próximo ativo 6 | M1: Próximo ativo 7 | N1: Próximo ativo 8 | O1: Próximo ativo 9 | P1: Próximo ativo 10 | Q1: Próximo ativo 11 | R1: Próximo ativo 12 | S1: Próximo ativo 13 | T1: Próximo ativo 14 | U1: Próximo ativo 15 | V1: Próximo ativo 16 | W1: Próximo ativo 17 | X1: Próximo ativo 18 | Y1: Próximo ativo 19 | Z1: Próximo ativo 20 | AA1: Próximo ativo 21 | AB1: Próximo ativo 22 | AC1: Próximo ativo 23 | AD1: Próximo ativo 24 | AE1: Próximo ativo 25 | AF1: Próximo ativo 26 | AG1: Próximo ativo 27 | AH1: Próximo ativo 28 | AI1: Próximo ativo 29 | AJ1: Próximo ativo 30 | AK1: Próximo ativo 31 | AL1: Próximo ativo 32 | AM1: Nível 1 | AN1: Nível 2 | AO1: Nível 3 | AP1: Nível 4 | AQ1: Nível 5 | AR1: Qtd. vãos | AS1: Extensão do bloco (m) | AT1: Qtd. ativos posteriores | AU1: Ativos posteriores (concatenado) | AV1: Outras chaves no bloco (88…) | AW1: Posterior 1 | AX1: Posterior 2 | AY1: Posterior 3 | AZ1: Posterior 4 | BA1: Posterior 5 | BB1: Posterior 6 | BC1: Posterior 7 | BD1: Posterior 8 | BE1: Posterior 9 | BF1: Posterior 10 | BG1: Posterior 11 | BH1: Posterior 12 | BI1: Posterior 13 | BJ1: Posterior 14 | BK1: Posterior 15 | BL1: Posterior 16 | BM1: Posterior 17 | BN1: Posterior 18 | BO1: Posterior 19 | BP1: Posterior 20 | BQ1: Posterior 21 | BR1: Posterior 22 | BS1: Posterior 23 | BT1: Posterior 24 | BU1: Posterior 25 | BV1: Posterior 26 | BW1: Posterior 27 | BX1: Posterior 28 | BY1: Posterior 29 | BZ1: Posterior 30 | CA1: Posterior 31 | CB1: Posterior 32 | CC1: Posterior 33 | CD1: Posterior 34 | CE1: Posterior 35 | CF1: Posterior 36 | CG1: Posterior 37 | CH1: Posterior 38 | CI1: Posterior 39 | CJ1: Posterior 40 | CK1: Posterior 41 | CL1: Posterior 42 | CM1: Posterior 43 | CN1: Posterior 44 | CO1: Posterior 45 | CP1: Posterior 46 | CQ1: Posterior 47 | CR1: Posterior 48 | CS1: Posterior 49 | CT1: Posterior 50 | CU1: Posterior 51 | CV1: Posterior 52 | CW1: Posterior 53
A2: 1 | B2: T1 | C2: Tronco | D2: Tronco | E2: DJ AL04010004 | F2: DJ AL04010004 | G2: 7903565004 | AM2: DJ AL04010004 | AR2: =COUNTIFS(Trechos!$L$2:$L$526,A2) -> 62 | AS2: =SUMIFS(Trechos!$F$2:$F$526,Trechos!$L$2:$L$526,A2) -> 2972.1647 | AT2: =COUNTA(AW2:CW2) -> 53 | AU2: =IF(COUNTA(AW2:CW2)=0,"—",_xlfn.TEXTJOIN(", ",TRUE(),AW2:CW2)) -> 7903565004, 7935867004, 7902218004, 0330915004, 0203711004, 0202227004, 0204190004, 0200482004, 0200484004, 0200489004, 0200490004, 0230938004, 0200492004, 0202676004, 0303862004, 0229036004, 0200495004, 0201153004, 0352542004, 0300603004, 0203117004, 0202175004, 0300600004, 0203661004, 0300596004, 0300588004, 0300591004, 0200593004, 0224749004, 0200583004, 0300584004, 0300585004, 0300582004, 0204195004, 0300578004, 0229381004, 0200580004, 0202671004, 0204249004, 0200868004, 0200573004, 0200571004, 0230252004, 0303731004, 0200556004, 0303973004, 0200550004, 0201875004, 0200549004, 0200548004, 0200547004, 0345761004, 0201072004 | AV2: 8800004004, 8804421004, 8802681004, 8847597004, 8802014004, 8800554004, 8801115004 | AW2: 7903565004 | AX2: 7935867004 | AY2: 7902218004 | AZ2: 0330915004 | BA2: 0203711004 | BB2: 0202227004 | BC2: 0204190004 | BD2: 0200482004 | BE2: 0200484004 | BF2: 0200489004 | BG2: 0200490004 | BH2: 0230938004 | BI2: 0200492004 | BJ2: 0202676004 | BK2: 0303862004 | BL2: 0229036004 | BM2: 0200495004 | BN2: 0201153004 | BO2: 0352542004 | BP2: 0300603004 | BQ2: 0203117004 | BR2: 0202175004 | BS2: 0300600004 | BT2: 0203661004 | BU2: 0300596004 | BV2: 0300588004 | BW2: 0300591004 | BX2: 0200593004 | BY2: 0224749004 | BZ2: 0200583004 | CA2: 0300584004 | CB2: 0300585004 | CC2: 0300582004 | CD2: 0204195004 | CE2: 0300578004 | CF2: 0229381004 | CG2: 0200580004 | CH2: 0202671004 | CI2: 0204249004 | CJ2: 0200868004 | CK2: 0200573004 | CL2: 0200571004 | CM2: 0230252004 | CN2: 0303731004 | CO2: 0200556004 | CP2: 0303973004 | CQ2: 0200550004 | CR2: 0201875004 | CS2: 0200549004 | CT2: 0200548004 | CU2: 0200547004 | CV2: 0345761004 | CW2: 0201072004
A3: 2 | B3: T2 | C3: Tronco | D3: Tronco | E3: 7903565004 | F3: 7903565004 | G3: 7935867004 | AM3: DJ AL04010004 | AN3: 7903565004 | AR3: =COUNTIFS(Trechos!$L$2:$L$526,A3) -> 28 | AS3: =SUMIFS(Trechos!$F$2:$F$526,Trechos!$L$2:$L$526,A3) -> 1067.0564 | AT3: =COUNTA(AW3:CW3) -> 45 | AU3: =IF(COUNTA(AW3:CW3)=0,"—",_xlfn.TEXTJOIN(", ",TRUE(),AW3:CW3)) -> 7935867004, 7902218004, 0330915004, 0203711004, 0202227004, 0204190004, 0200482004, 0200484004, 0200489004, 0200490004, 0230938004, 0200492004, 0202676004, 0303862004, 0229036004, 0200495004, 0201153004, 0352542004, 0300603004, 0203117004, 0202175004, 0300600004, 0203661004, 0300596004, 0300588004, 0300591004, 0200593004, 0224749004, 0200583004, 0300584004, 0300585004, 0300582004, 0204195004, 0300578004, 0229381004, 0200580004, 0202671004, 0204249004, 0200868004, 0200573004, 0200571004, 0230252004, 0303731004, 0200556004, 0303973004 | AV3: 8841355004 | AW3: 7935867004 | AX3: 7902218004 | AY3: 0330915004 | AZ3: 0203711004 | BA3: 0202227004 | BB3: 0204190004 | BC3: 0200482004 | BD3: 0200484004 | BE3: 0200489004 | BF3: 0200490004 | BG3: 0230938004 | BH3: 0200492004 | BI3: 0202676004 | BJ3: 0303862004 | BK3: 0229036004 | BL3: 0200495004 | BM3: 0201153004 | BN3: 0352542004 | BO3: 0300603004 | BP3: 0203117004 | BQ3: 0202175004 | BR3: 0300600004 | BS3: 0203661004 | BT3: 0300596004 | BU3: 0300588004 | BV3: 0300591004 | BW3: 0200593004 | BX3: 0224749004 | BY3: 0200583004 | BZ3: 0300584004 | CA3: 0300585004 | CB3: 0300582004 | CC3: 0204195004 | CD3: 0300578004 | CE3: 0229381004 | CF3: 0200580004 | CG3: 0202671004 | CH3: 0204249004 | CI3: 0200868004 | CJ3: 0200573004 | CK3: 0200571004 | CL3: 0230252004 | CM3: 0303731004 | CN3: 0200556004 | CO3: 0303973004
A4: 3 | B4: T2 | C4: Tronco | D4: Tronco | E4: 7935867004 | F4: 7935867004 | G4: 7902218004 | H4: 0352542004 | I4: 0300603004 | J4: 0203117004 | K4: 0202175004 | L4: 0300600004 | AM4: DJ AL04010004 | AN4: 7903565004 | AO4: 7935867004 | AR4: =COUNTIFS(Trechos!$L$2:$L$526,A4) -> 55 | AS4: =SUMIFS(Trechos!$F$2:$F$526,Trechos!$L$2:$L$526,A4) -> 1795.8328 | AT4: =COUNTA(AW4:CW4) -> 21 | AU4: =IF(COUNTA(AW4:CW4)=0,"—",_xlfn.TEXTJOIN(", ",TRUE(),AW4:CW4)) -> 7902218004, 0330915004, 0203711004, 0202227004, 0204190004, 0200482004, 0200484004, 0200489004, 0200490004, 0230938004, 0200492004, 0202676004, 0303862004, 0229036004, 0200495004, 0201153004, 0352542004, 0300603004, 0203117004, 0202175004, 0300600004 | AV4: 8834608004, 8800606004, 8843255004, 8800599004 | AW4: 7902218004 | AX4: 0330915004 | AY4: 0203711004 | AZ4: 0202227004 | BA4: 0204190004 | BB4: 0200482004 | BC4: 0200484004 | BD4: 0200489004 | BE4: 0200490004 | BF4: 0230938004 | BG4: 0200492004 | BH4: 0202676004 | BI4: 0303862004 | BJ4: 0229036004 | BK4: 0200495004 | BL4: 0201153004 | BM4: 0352542004 | BN4: 0300603004 | BO4: 0203117004 | BP4: 0202175004 | BQ4: 0300600004
A5: 4 | B5: T1 | C5: Ramal | D5: Ramal 587997 | E5: DJ AL04010004 | F5: poste 587997 | G5: fim 25524195 | H5: fim 65878548 | AM5: DJ AL04010004 | AR5: =COUNTIFS(Trechos!$L$2:$L$526,A5) -> 6 | AS5: =SUMIFS(Trechos!$F$2:$F$526,Trechos!$L$2:$L$526,A5) -> 343.48266 | AT5: =COUNTA(AW5:CW5) -> 0 | AU5: =IF(COUNTA(AW5:CW5)=0,"—",_xlfn.TEXTJOIN(", ",TRUE(),AW5:CW5)) -> — | AV5: —
A6: 5 | B6: T1 | C6: Ramal | D6: Ramal 122086 | E6: DJ AL04010004 | F6: poste 122086 | G6: fim N34 | AM6: DJ AL04010004 | AR6: =COUNTIFS(Trechos!$L$2:$L$526,A6) -> 1 | AS6: =SUMIFS(Trechos!$F$2:$F$526,Trechos!$L$2:$L$526,A6) -> 8.4653287 | AT6: =COUNTA(AW6:CW6) -> 0 | AU6: =IF(COUNTA(AW6:CW6)=0,"—",_xlfn.TEXTJOIN(", ",TRUE(),AW6:CW6)) -> — | AV6: —
A7: 6 | B7: T1 | C7: Ramal | D7: Ramal 104546 | E7: DJ AL04010004 | F7: poste 104546 | G7: 0201072004 | AM7: DJ AL04010004 | AR7: =COUNTIFS(Trechos!$L$2:$L$526,A7) -> 1 | AS7: =SUMIFS(Trechos!$F$2:$F$526,Trechos!$L$2:$L$526,A7) -> 1.0068168 | AT7: =COUNTA(AW7:CW7) -> 1 | AU7: =IF(COUNTA(AW7:CW7)=0,"—",_xlfn.TEXTJOIN(", ",TRUE(),AW7:CW7)) -> 0201072004 | AV7: — | AW7: 0201072004
A8: 7 | B8: T3 | C8: Ramal | D8: Ramal 104546 | E8: 0201072004 | F8: 0201072004 | G8: fim N85 | AM8: DJ AL04010004 | AN8: 0201072004 | AR8: =COUNTIFS(Trechos!$L$2:$L$526,A8) -> 2 | AS8: =SUMIFS(Trechos!$F$2:$F$526,Trechos!$L$2:$L$526,A8) -> 22.323525 | AT8: =COUNTA(AW8:CW8) -> 0 | AU8: =IF(COUNTA(AW8:CW8)=0,"—",_xlfn.TEXTJOIN(", ",TRUE(),AW8:CW8)) -> — | AV8: —
A9: 8 | B9: T1 | C9: Ramal | D9: Ramal 33261324 | E9: DJ AL04010004 | F9: poste 33261324 | G9: 0345761004 | AM9: DJ AL04010004 | AR9: =COUNTIFS(Trechos!$L$2:$L$526,A9) -> 1 | AS9: =SUMIFS(Trechos!$F$2:$F$526,Trechos!$L$2:$L$526,A9) -> 1.0205312 | AT9: =COUNTA(AW9:CW9) -> 1 | AU9: =IF(COUNTA(AW9:CW9)=0,"—",_xlfn.TEXTJOIN(", ",TRUE(),AW9:CW9)) -> 0345761004 | AV9: — | AW9: 0345761004
A10: 9 | B10: T3 | C10: Ramal | D10: Ramal 33261324 | E10: 0345761004 | F10: 0345761004 | G10: fim 33308575 | AM10: DJ AL04010004 | AN10: 0345761004 | AR10: =COUNTIFS(Trechos!$L$2:$L$526,A10) -> 1 | AS10: =SUMIFS(Trechos!$F$2:$F$526,Trechos!$L$2:$L$526,A10) -> 8.5499772 | AT10: =COUNTA(AW10:CW10) -> 0 | AU10: =IF(COUNTA(AW10:CW10)=0,"—",_xlfn.TEXTJOIN(", ",TRUE(),AW10:CW10)) -> — | AV10: —
A11: 10 | B11: T1 | C11: Ramal | D11: Ramal 94069 | E11: DJ AL04010004 | F11: poste 94069 | G11: 0200547004 | AM11: DJ AL04010004 | AR11: =COUNTIFS(Trechos!$L$2:$L$526,A11) -> 1 | AS11: =SUMIFS(Trechos!$F$2:$F$526,Trechos!$L$2:$L$526,A11) -> 0.55440619 | AT11: =COUNTA(AW11:CW11) -> 1 | AU11: =IF(COUNTA(AW11:CW11)=0,"—",_xlfn.TEXTJOIN(", ",TRUE(),AW11:CW11)) -> 0200547004 | AV11: — | AW11: 0200547004
A12: 11 | B12: T3 | C12: Ramal | D12: Ramal 94069 | E12: 0200547004 | F12: 0200547004 | G12: fim 94065 | AM12: DJ AL04010004 | AN12: 0200547004 | AR12: =COUNTIFS(Trechos!$L$2:$L$526,A12) -> 1 | AS12: =SUMIFS(Trechos!$F$2:$F$526,Trechos!$L$2:$L$526,A12) -> 3.8390204 | AT12: =COUNTA(AW12:CW12) -> 0 | AU12: =IF(COUNTA(AW12:CW12)=0,"—",_xlfn.TEXTJOIN(", ",TRUE(),AW12:CW12)) -> — | AV12: —
A13: 12 | B13: T1 | C13: Ramal | D13: Ramal 94068 | E13: DJ AL04010004 | F13: poste 94068 | G13: 0200548004 | AM13: DJ AL04010004 | AR13: =COUNTIFS(Trechos!$L$2:$L$526,A13) -> 1 | AS13: =SUMIFS(Trechos!$F$2:$F$526,Trechos!$L$2:$L$526,A13) -> 1.021764 | AT13: =COUNTA(AW13:CW13) -> 1 | AU13: =IF(COUNTA(AW13:CW13)=0,"—",_xlfn.TEXTJOIN(", ",TRUE(),AW13:CW13)) -> 0200548004 | AV13: — | AW13: 0200548004
A14: 13 | B14: T3 | C14: Ramal | D14: Ramal 94068 | E14: 0200548004 | F14: 0200548004 | G14: fim 94064 | AM14: DJ AL04010004 | AN14: 0200548004 | AR14: =COUNTIFS(Trechos!$L$2:$L$526,A14) -> 1 | AS14: =SUMIFS(Trechos!$F$2:$F$526,Trechos!$L$2:$L$526,A14) -> 8.854961 | AT14: =COUNTA(AW14:CW14) -> 0 | AU14: =IF(COUNTA(AW14:CW14)=0,"—",_xlfn.TEXTJOIN(", ",TRUE(),AW14:CW14)) -> — | AV14: —
A15: 14 | B15: T1 | C15: Ramal | D15: Ramal 20392852 | E15: DJ AL04010004 | F15: poste 20392852 | G15: 0200549004 | AM15: DJ AL04010004 | AR15: =COUNTIFS(Trechos!$L$2:$L$526,A15) -> 1 | AS15: =SUMIFS(Trechos!$F$2:$F$526,Trechos!$L$2:$L$526,A15) -> 1.0430959 | AT15: =COUNTA(AW15:CW15) -> 1 | AU15: =IF(COUNTA(AW15:CW15)=0,"—",_xlfn.TEXTJOIN(", ",TRUE(),AW15:CW15)) -> 0200549004 | AV15: — | AW15: 0200549004
A16: 15 | B16: T3 | C16: Ramal | D16: Ramal 20392852 | E16: 0200549004 | F16: 0200549004 | G16: fim 94063 | AM16: DJ AL04010004 | AN16: 0200549004 | AR16: =COUNTIFS(Trechos!$L$2:$L$526,A16) -> 1 | AS16: =SUMIFS(Trechos!$F$2:$F$526,Trechos!$L$2:$L$526,A16) -> 9.0630126 | AT16: =COUNTA(AW16:CW16) -> 0 | AU16: =IF(COUNTA(AW16:CW16)=0,"—",_xlfn.TEXTJOIN(", ",TRUE(),AW16:CW16)) -> — | AV16: —
A17: 16 | B17: T1 | C17: Ramal | D17: Ramal 552519 | E17: DJ AL04010004 | F17: poste 552519 | G17: fim 832105 | AM17: DJ AL04010004 | AR17: =COUNTIFS(Trechos!$L$2:$L$526,A17) -> 2 | AS17: =SUMIFS(Trechos!$F$2:$F$526,Trechos!$L$2:$L$526,A17) -> 79.282946 | AT17: =COUNTA(AW17:CW17) -> 0 | AU17: =IF(COUNTA(AW17:CW17)=0,"—",_xlfn.TEXTJOIN(", ",TRUE(),AW17:CW17)) -> — | AV17: —
A18: 17 | B18: T1 | C18: Ramal | D18: Ramal 272816 | E18: DJ AL04010004 | F18: poste 272816 | G18: 0201875004 | AM18: DJ AL04010004 | AR18: =COUNTIFS(Trechos!$L$2:$L$526,A18) -> 1 | AS18: =SUMIFS(Trechos!$F$2:$F$526,Trechos!$L$2:$L$526,A18) -> 0.95157043 | AT18: =COUNTA(AW18:CW18) -> 1 | AU18: =IF(COUNTA(AW18:CW18)=0,"—",_xlfn.TEXTJOIN(", ",TRUE(),AW18:CW18)) -> 0201875004 | AV18: — | AW18: 0201875004
A19: 18 | B19: T3 | C19: Ramal | D19: Ramal 272816 | E19: 0201875004 | F19: 0201875004 | G19: fim 272817 | AM19: DJ AL04010004 | AN19: 0201875004 | AR19: =COUNTIFS(Trechos!$L$2:$L$526,A19) -> 1 | AS19: =SUMIFS(Trechos!$F$2:$F$526,Trechos!$L$2:$L$526,A19) -> 8.6844675 | AT19: =COUNTA(AW19:CW19) -> 0 | AU19: =IF(COUNTA(AW19:CW19)=0,"—",_xlfn.TEXTJOIN(", ",TRUE(),AW19:CW19)) -> — | AV19: —
A20: 19 | B20: T1 | C20: Ramal | D20: Ramal 94067 | E20: DJ AL04010004 | F20: poste 94067 | G20: 0200550004 | AM20: DJ AL04010004 | AR20: =COUNTIFS(Trechos!$L$2:$L$526,A20) -> 1 | AS20: =SUMIFS(Trechos!$F$2:$F$526,Trechos!$L$2:$L$526,A20) -> 0.86567317 | AT20: =COUNTA(AW20:CW20) -> 1 | AU20: =IF(COUNTA(AW20:CW20)=0,"—",_xlfn.TEXTJOIN(", ",TRUE(),AW20:CW20)) -> 0200550004 | AV20: — | AW20: 0200550004
A21: 20 | B21: T3 | C21: Ramal | D21: Ramal 94067 | E21: 0200550004 | F21: 0200550004 | G21: fim N96 | H21: fim N97 | AM21: DJ AL04010004 | AN21: 0200550004 | AR21: =COUNTIFS(Trechos!$L$2:$L$526,A21) -> 3 | AS21: =SUMIFS(Trechos!$F$2:$F$526,Trechos!$L$2:$L$526,A21) -> 46.711058 | AT21: =COUNTA(AW21:CW21) -> 0 | AU21: =IF(COUNTA(AW21:CW21)=0,"—",_xlfn.TEXTJOIN(", ",TRUE(),AW21:CW21)) -> — | AV21: —
A22: 21 | B22: T1 | C22: Ramal | D22: Ramal 26974937 | E22: DJ AL04010004 | F22: poste 26974937 | G22: fim 106594 | H22: fim 538410 | I22: fim 539777 | J22: fim 550142 | K22: fim 539569 | L22: fim 535127 | M22: fim 538391 | N22: fim 536377 | O22: fim N123 | AM22: DJ AL04010004 | AR22: =COUNTIFS(Trechos!$L$2:$L$526,A22) -> 24 | AS22: =SUMIFS(Trechos!$F$2:$F$526,Trechos!$L$2:$L$526,A22) -> 1142.2202 | AT22: =COUNTA(AW22:CW22) -> 0 | AU22: =IF(COUNTA(AW22:CW22)=0,"—",_xlfn.TEXTJOIN(", ",TRUE(),AW22:CW22)) -> — | AV22: —
A23: 22 | B23: T1 | C23: Ramal | D23: Ramal 550921 | E23: DJ AL04010004 | F23: poste 550921 | G23: fim N82 | H23: fim N122 | AM23: DJ AL04010004 | AR23: =COUNTIFS(Trechos!$L$2:$L$526,A23) -> 10 | AS23: =SUMIFS(Trechos!$F$2:$F$526,Trechos!$L$2:$L$526,A23) -> 134.24053 | AT23: =COUNTA(AW23:CW23) -> 0 | AU23: =IF(COUNTA(AW23:CW23)=0,"—",_xlfn.TEXTJOIN(", ",TRUE(),AW23:CW23)) -> — | AV23: —
A24: 23 | B24: T1 | C24: Ramal | D24: Ramal N68 | E24: DJ AL04010004 | F24: poste N68 | G24: fim 308076 | AM24: DJ AL04010004 | AR24: =COUNTIFS(Trechos!$L$2:$L$526,A24) -> 1 | AS24: =SUMIFS(Trechos!$F$2:$F$526,Trechos!$L$2:$L$526,A24) -> 41.768705 | AT24: =COUNTA(AW24:CW24) -> 0 | AU24: =IF(COUNTA(AW24:CW24)=0,"—",_xlfn.TEXTJOIN(", ",TRUE(),AW24:CW24)) -> — | AV24: —
A25: 24 | B25: T1 | C25: Ramal | D25: Ramal N77 | E25: DJ AL04010004 | F25: poste N77 | G25: fim N78 | AM25: DJ AL04010004 | AR25: =COUNTIFS(Trechos!$L$2:$L$526,A25) -> 1 | AS25: =SUMIFS(Trechos!$F$2:$F$526,Trechos!$L$2:$L$526,A25) -> 5.4735809 | AT25: =COUNTA(AW25:CW25) -> 0 | AU25: =IF(COUNTA(AW25:CW25)=0,"—",_xlfn.TEXTJOIN(", ",TRUE(),AW25:CW25)) -> — | AV25: —
A26: 25 | B26: T2 | C26: Ramal | D26: Ramal N127 | E26: 7903565004 | F26: poste N127 | G26: fim N128 | AM26: DJ AL04010004 | AN26: 7903565004 | AR26: =COUNTIFS(Trechos!$L$2:$L$526,A26) -> 1 | AS26: =SUMIFS(Trechos!$F$2:$F$526,Trechos!$L$2:$L$526,A26) -> 4.263923 | AT26: =COUNTA(AW26:CW26) -> 0 | AU26: =IF(COUNTA(AW26:CW26)=0,"—",_xlfn.TEXTJOIN(", ",TRUE(),AW26:CW26)) -> — | AV26: —
A27: 26 | B27: T2 | C27: Ramal | D27: Ramal do 0303973004 | E27: 7903565004 | F27: poste N130 | G27: fim 30002378 | H27: 0303973004 | I27: fim 30002218 | AM27: DJ AL04010004 | AN27: 7903565004 | AR27: =COUNTIFS(Trechos!$L$2:$L$526,A27) -> 8 | AS27: =SUMIFS(Trechos!$F$2:$F$526,Trechos!$L$2:$L$526,A27) -> 193.17717 | AT27: =COUNTA(AW27:CW27) -> 1 | AU27: =IF(COUNTA(AW27:CW27)=0,"—",_xlfn.TEXTJOIN(", ",TRUE(),AW27:CW27)) -> 0303973004 | AV27: 8845029004 | AW27: 0303973004
A28: 27 | B28: T3 | C28: Ramal | D28: Ramal do 0303973004 | E28: 0303973004 | F28: 0303973004 | G28: fim N144 | AM28: DJ AL04010004 | AN28: 7903565004 | AO28: 0303973004 | AR28: =COUNTIFS(Trechos!$L$2:$L$526,A28) -> 2 | AS28: =SUMIFS(Trechos!$F$2:$F$526,Trechos!$L$2:$L$526,A28) -> 34.30462 | AT28: =COUNTA(AW28:CW28) -> 0 | AU28: =IF(COUNTA(AW28:CW28)=0,"—",_xlfn.TEXTJOIN(", ",TRUE(),AW28:CW28)) -> — | AV28: —
A29: 28 | B29: T2 | C29: Ramal | D29: Ramal 122229 | E29: 7903565004 | F29: poste 122229 | G29: 0200556004 | AM29: DJ AL04010004 | AN29: 7903565004 | AR29: =COUNTIFS(Trechos!$L$2:$L$526,A29) -> 1 | AS29: =SUMIFS(Trechos!$F$2:$F$526,Trechos!$L$2:$L$526,A29) -> 2.9054667 | AT29: =COUNTA(AW29:CW29) -> 1 | AU29: =IF(COUNTA(AW29:CW29)=0,"—",_xlfn.TEXTJOIN(", ",TRUE(),AW29:CW29)) -> 0200556004 | AV29: — | AW29: 0200556004
A30: 29 | B30: T3 | C30: Ramal | D30: Ramal 122229 | E30: 0200556004 | F30: 0200556004 | G30: fim N260 | AM30: DJ AL04010004 | AN30: 7903565004 | AO30: 0200556004 | AR30: =COUNTIFS(Trechos!$L$2:$L$526,A30) -> 2 | AS30: =SUMIFS(Trechos!$F$2:$F$526,Trechos!$L$2:$L$526,A30) -> 41.706607 | AT30: =COUNTA(AW30:CW30) -> 0 | AU30: =IF(COUNTA(AW30:CW30)=0,"—",_xlfn.TEXTJOIN(", ",TRUE(),AW30:CW30)) -> — | AV30: —
A31: 30 | B31: T2 | C31: Ramal | D31: Ramal 550125 | E31: 7903565004 | F31: poste 550125 | G31: fim 94055 | AM31: DJ AL04010004 | AN31: 7903565004 | AR31: =COUNTIFS(Trechos!$L$2:$L$526,A31) -> 2 | AS31: =SUMIFS(Trechos!$F$2:$F$526,Trechos!$L$2:$L$526,A31) -> 22.039154 | AT31: =COUNTA(AW31:CW31) -> 0 | AU31: =IF(COUNTA(AW31:CW31)=0,"—",_xlfn.TEXTJOIN(", ",TRUE(),AW31:CW31)) -> — | AV31: —
A32: 31 | B32: T2 | C32: Ramal | D32: Ramal 122230 | E32: 7903565004 | F32: poste 122230 | G32: 0303731004 | AM32: DJ AL04010004 | AN32: 7903565004 | AR32: =COUNTIFS(Trechos!$L$2:$L$526,A32) -> 2 | AS32: =SUMIFS(Trechos!$F$2:$F$526,Trechos!$L$2:$L$526,A32) -> 5.3811234 | AT32: =COUNTA(AW32:CW32) -> 1 | AU32: =IF(COUNTA(AW32:CW32)=0,"—",_xlfn.TEXTJOIN(", ",TRUE(),AW32:CW32)) -> 0303731004 | AV32: — | AW32: 0303731004
A33: 32 | B33: T3 | C33: Ramal | D33: Ramal 122230 | E33: 0303731004 | F33: 0303731004 | G33: fim 553594 | H33: fim 552526 | I33: fim 537929 | AM33: DJ AL04010004 | AN33: 7903565004 | AO33: 0303731004 | AR33: =COUNTIFS(Trechos!$L$2:$L$526,A33) -> 5 | AS33: =SUMIFS(Trechos!$F$2:$F$526,Trechos!$L$2:$L$526,A33) -> 167.98351 | AT33: =COUNTA(AW33:CW33) -> 0 | AU33: =IF(COUNTA(AW33:CW33)=0,"—",_xlfn.TEXTJOIN(", ",TRUE(),AW33:CW33)) -> — | AV33: —
A34: 33 | B34: T2 | C34: Ramal | D34: Ramal 1326106 | E34: 7903565004 | F34: poste 1326106 | G34: 0230252004 | AM34: DJ AL04010004 | AN34: 7903565004 | AR34: =COUNTIFS(Trechos!$L$2:$L$526,A34) -> 1 | AS34: =SUMIFS(Trechos!$F$2:$F$526,Trechos!$L$2:$L$526,A34) -> 1.0879701 | AT34: =COUNTA(AW34:CW34) -> 1 | AU34: =IF(COUNTA(AW34:CW34)=0,"—",_xlfn.TEXTJOIN(", ",TRUE(),AW34:CW34)) -> 0230252004 | AV34: — | AW34: 0230252004
A35: 34 | B35: T3 | C35: Ramal | D35: Ramal 1326106 | E35: 0230252004 | F35: 0230252004 | G35: fim N263 | AM35: DJ AL04010004 | AN35: 7903565004 | AO35: 0230252004 | AR35: =COUNTIFS(Trechos!$L$2:$L$526,A35) -> 2 | AS35: =SUMIFS(Trechos!$F$2:$F$526,Trechos!$L$2:$L$526,A35) -> 24.734505 | AT35: =COUNTA(AW35:CW35) -> 0 | AU35: =IF(COUNTA(AW35:CW35)=0,"—",_xlfn.TEXTJOIN(", ",TRUE(),AW35:CW35)) -> — | AV35: —
A36: 35 | B36: T2 | C36: Ramal | D36: Ramal do 0200571004 | E36: 7903565004 | F36: poste N157 | G36: 0200571004 | AM36: DJ AL04010004 | AN36: 7903565004 | AR36: =COUNTIFS(Trechos!$L$2:$L$526,A36) -> 1 | AS36: =SUMIFS(Trechos!$F$2:$F$526,Trechos!$L$2:$L$526,A36) -> 2.7820614 | AT36: =COUNTA(AW36:CW36) -> 1 | AU36: =IF(COUNTA(AW36:CW36)=0,"—",_xlfn.TEXTJOIN(", ",TRUE(),AW36:CW36)) -> 0200571004 | AV36: — | AW36: 0200571004
A37: 36 | B37: T3 | C37: Ramal | D37: Ramal do 0200571004 | E37: 0200571004 | F37: 0200571004 | G37: fim 94371 | AM37: DJ AL04010004 | AN37: 7903565004 | AO37: 0200571004 | AR37: =COUNTIFS(Trechos!$L$2:$L$526,A37) -> 1 | AS37: =SUMIFS(Trechos!$F$2:$F$526,Trechos!$L$2:$L$526,A37) -> 25.030774 | AT37: =COUNTA(AW37:CW37) -> 0 | AU37: =IF(COUNTA(AW37:CW37)=0,"—",_xlfn.TEXTJOIN(", ",TRUE(),AW37:CW37)) -> — | AV37: —
A38: 37 | B38: T2 | C38: Ramal | D38: Ramal 94187 | E38: 7903565004 | F38: poste 94187 | G38: fim N162 | H38: 0200573004 | AM38: DJ AL04010004 | AN38: 7903565004 | AR38: =COUNTIFS(Trechos!$L$2:$L$526,A38) -> 3 | AS38: =SUMIFS(Trechos!$F$2:$F$526,Trechos!$L$2:$L$526,A38) -> 44.461056 | AT38: =COUNTA(AW38:CW38) -> 1 | AU38: =IF(COUNTA(AW38:CW38)=0,"—",_xlfn.TEXTJOIN(", ",TRUE(),AW38:CW38)) -> 0200573004 | AV38: — | AW38: 0200573004
A39: 38 | B39: T3 | C39: Ramal | D39: Ramal 94187 | E39: 0200573004 | F39: 0200573004 | G39: fim 94185 | AM39: DJ AL04010004 | AN39: 7903565004 | AO39: 0200573004 | AR39: =COUNTIFS(Trechos!$L$2:$L$526,A39) -> 1 | AS39: =SUMIFS(Trechos!$F$2:$F$526,Trechos!$L$2:$L$526,A39) -> 22.705485 | AT39: =COUNTA(AW39:CW39) -> 0 | AU39: =IF(COUNTA(AW39:CW39)=0,"—",_xlfn.TEXTJOIN(", ",TRUE(),AW39:CW39)) -> — | AV39: —
A40: 39 | B40: T2 | C40: Ramal | D40: Ramal 101058 | E40: 7903565004 | F40: poste 101058 | G40: 0200868004 | AM40: DJ AL04010004 | AN40: 7903565004 | AR40: =COUNTIFS(Trechos!$L$2:$L$526,A40) -> 1 | AS40: =SUMIFS(Trechos!$F$2:$F$526,Trechos!$L$2:$L$526,A40) -> 1.3907679 | AT40: =COUNTA(AW40:CW40) -> 1 | AU40: =IF(COUNTA(AW40:CW40)=0,"—",_xlfn.TEXTJOIN(", ",TRUE(),AW40:CW40)) -> 0200868004 | AV40: — | AW40: 0200868004
...

Sheet Por bloco
A1: Bloco | B1: Zona | C1: Tronco/Ramal | D1: Ramal | E1: Ativo de referência | F1: Trecho | G1: Poste início | H1: Poste fim | I1: Extensão (m) | J1: Distância do ativo de referência até o fim (m) | K1: Outra chave no fim do vão (88…) | L1: Próximos ativos | M1: Outras chaves no bloco (88…) | N1: Ativos posteriores
A2: 1 | B2: T1 | C2: Tronco | D2: Tronco | E2: DJ AL04010004 | F2: =COUNTIFS(Trechos!$L$2:$L$526,A2)&" vãos" -> 62 vãos | I2: =SUMIFS(Trechos!$F$2:$F$526,Trechos!$L$2:$L$526,A2) -> 2972.1647 | L2: 7903565004 | M2: 8800004004, 8804421004, 8802681004, 8847597004, 8802014004, 8800554004, 8801115004 | N2: =Blocos!AU2 -> 7903565004, 7935867004, 7902218004, 0330915004, 0203711004, 0202227004, 0204190004, 0200482004, 0200484004, 0200489004, 0200490004, 0230938004, 0200492004, 0202676004, 0303862004, 0229036004, 0200495004, 0201153004, 0352542004, 0300603004, 0203117004, 0202175004, 0300600004, 0203661004, 0300596004, 0300588004, 0300591004, 0200593004, 0224749004, 0200583004, 0300584004, 0300585004, 0300582004, 0204195004, 0300578004, 0229381004, 0200580004, 0202671004, 0204249004, 0200868004, 0200573004, 0200571004, 0230252004, 0303731004, 0200556004, 0303973004, 0200550004, 0201875004, 0200549004, 0200548004, 0200547004, 0345761004, 0201072004
F3: TR-001 | G3: 553218 | H3: 535163 | I3: 41.822789 | J3: 41.822789
F4: TR-002 | G4: 535163 | H4: N2 | I4: 0.79990026 | J4: 42.622689 | K4: 8800004004
F5: TR-003 | G5: N2 | H5: 332180 | I5: 11.266548 | J5: 53.889238
F6: TR-004 | G6: 332180 | H6: N4 | I6: 2.1997169 | J6: 56.088954 | K6: 8804421004
F7: TR-005 | G7: N4 | H7: N5 | I7: 19.683407 | J7: 75.772361
F8: TR-006 | G8: N5 | H8: N6 | I8: 3.7592477 | J8: 79.531609
F9: TR-007 | G9: N6 | H9: N7 | I9: 23.496279 | J9: 103.02789
F10: TR-008 | G10: N7 | H10: N8 | I10: 3.6986195 | J10: 106.72651
F11: TR-009 | G11: N8 | H11: N9 | I11: 137.81839 | J11: 244.54489
F12: TR-010 | G12: N9 | H12: N10 | I12: 3.704776 | J12: 248.24967
F13: TR-011 | G13: N10 | H13: 531059 | I13: 20.440651 | J13: 268.69032
F14: TR-012 | G14: 531059 | H14: N12 | I14: 3.6760381 | J14: 272.36636
F15: TR-013 | G15: N12 | H15: N13 | I15: 12.673459 | J15: 285.03982
F16: TR-014 | G16: N13 | H16: N14 | I16: 1.1427014 | J16: 286.18252 | K16: 8802681004
F17: TR-015 | G17: N14 | H17: N15 | I17: 256.51202 | J17: 542.69454
F18: TR-016 | G18: N15 | H18: N16 | I18: 3.823669 | J18: 546.51821
F19: TR-017 | G19: N16 | H19: N17 | I19: 89.450652 | J19: 635.96886
F20: TR-018 | G20: N17 | H20: N18 | I20: 3.7965247 | J20: 639.76539
F21: TR-019 | G21: N18 | H21: N19 | I21: 56.883494 | J21: 696.64888
F22: TR-020 | G22: N19 | H22: 122082 | I22: 3.5889314 | J22: 700.23781
F23: TR-021 | G23: 122082 | H23: N21 | I23: 148.49989 | J23: 848.7377
F24: TR-022 | G24: N21 | H24: 550328 | I24: 3.6244665 | J24: 852.36217
F25: TR-023 | G25: 550328 | H25: N23 | I25: 164.31483 | J25: 1016.677
F26: TR-024 | G26: N23 | H26: N24 | I26: 2.5170796 | J26: 1019.1941
F27: TR-025 | G27: N24 | H27: 587997 | I27: 71.409924 | J27: 1090.604
F28: TR-026 | G28: 587997 | H28: 587525 | I28: 37.318146 | J28: 1127.9221
F29: TR-027 | G29: 587525 | H29: N28 | I29: 5.9434264 | J29: 1133.8656 | K29: 8847597004
F30: TR-028 | G30: N28 | H30: 536558 | I30: 90.721072 | J30: 1224.5866
F31: TR-029 | G31: 536558 | H31: 538107 | I31: 79.791259 | J31: 1304.3779
F32: TR-030 | G32: 538107 | H32: 122086 | I32: 39.706811 | J32: 1344.0847
F33: TR-031 | G33: 122086 | H33: 122087 | I33: 83.85523 | J33: 1427.9399
F34: TR-032 | G34: 122087 | H34: N39 | I34: 43.484803 | J34: 1471.4247
F35: TR-033 | G35: N39 | H35: 94070 | I35: 2.7493451 | J35: 1474.1741 | K35: 8802014004
F36: TR-034 | G36: 94070 | H36: 104546 | I36: 71.289891 | J36: 1545.464
F37: TR-035 | G37: 104546 | H37: 33261324 | I37: 97.587698 | J37: 1643.0517
F38: TR-036 | G38: 33261324 | H38: 94069 | I38: 36.74824 | J38: 1679.7999
F39: TR-037 | G39: 94069 | H39: 94068 | I39: 107.29137 | J39: 1787.0913
F40: TR-038 | G40: 94068 | H40: 536379 | I40: 43.182473 | J40: 1830.2738
...

Sheet Trechos
A1: Seq | B1: Trecho | C1: Trecho no Daimon | D1: Poste início | E1: Poste fim | F1: Extensão (m) | G1: Distância do DJ até o fim (m) | H1: Distância do ativo de referência até o fim (m) | I1: Zona | J1: Tronco/Ramal | K1: Ramal | L1: Bloco | M1: Ativo de referência | N1: Tipo do ativo de referência | O1: Próximo(s) ativo(s) | P1: Ativos posteriores englobados | Q1: Qtd. ativos posteriores | R1: Outra chave no fim do vão (88…) | S1: Nível 1 | T1: Nível 2 | U1: Nível 3 | V1: Nível 4 | W1: Nível 5 | X1: Caminho desde o DJ | Y1: Latitude (meio do vão) | Z1: Longitude (meio do vão) | AA1: Mapa | AB1: Chave do caminho (uso das fórmulas)
A2: 1 | B2: TR-001 | C2: 2517483 | D2: 553218 | E2: 535163 | F2: 41.822789 | G2: 41.822789 | H2: 41.822789 | I2: T1 | J2: Tronco | K2: Tronco | L2: 1 | M2: DJ AL04010004 | N2: Disjuntor (DJ) | O2: 7903565004 | P2: 7903565004, 7935867004, 7902218004, 0330915004, 0203711004, 0202227004, 0204190004, 0200482004, 0200484004, 0200489004, 0200490004, 0230938004, 0200492004, 0202676004, 0303862004, 0229036004, 0200495004, 0201153004, 0352542004, 0300603004, 0203117004, 0202175004, 0300600004, 0203661004, 0300596004, 0300588004, 0300591004, 0200593004, 0224749004, 0200583004, 0300584004, 0300585004, 0300582004, 0204195004, 0300578004, 0229381004, 0200580004, 0202671004, 0204249004, 0200868004, 0200573004, 0200571004, 0230252004, 0303731004, 0200556004, 0303973004, 0200550004, 0201875004, 0200549004, 0200548004, 0200547004, 0345761004, 0201072004 | Q2: 53 | S2: DJ AL04010004 | X2: DJ AL04010004 | Y2: -7.195443 | Z2: -48.238039 | AA2: abrir | AB2: |DJ AL04010004|
A3: 2 | B3: TR-002 | C3: Suporte Chave 8800004004 | D3: 535163 | E3: N2 | F3: 0.79990026 | G3: 42.622689 | H3: 42.622689 | I3: T1 | J3: Tronco | K3: Tronco | L3: 1 | M3: DJ AL04010004 | N3: Disjuntor (DJ) | O3: 7903565004 | P3: 7903565004, 7935867004, 7902218004, 0330915004, 0203711004, 0202227004, 0204190004, 0200482004, 0200484004, 0200489004, 0200490004, 0230938004, 0200492004, 0202676004, 0303862004, 0229036004, 0200495004, 0201153004, 0352542004, 0300603004, 0203117004, 0202175004, 0300600004, 0203661004, 0300596004, 0300588004, 0300591004, 0200593004, 0224749004, 0200583004, 0300584004, 0300585004, 0300582004, 0204195004, 0300578004, 0229381004, 0200580004, 0202671004, 0204249004, 0200868004, 0200573004, 0200571004, 0230252004, 0303731004, 0200556004, 0303973004, 0200550004, 0201875004, 0200549004, 0200548004, 0200547004, 0345761004, 0201072004 | Q3: 53 | R3: 8800004004 | S3: DJ AL04010004 | X3: DJ AL04010004 | Y3: -7.195577 | Z3: -48.238177 | AA3: abrir | AB3: |DJ AL04010004|
A4: 3 | B4: TR-003 | C4: 2520095 | D4: N2 | E4: 332180 | F4: 11.266548 | G4: 53.889238 | H4: 53.889238 | I4: T1 | J4: Tronco | K4: Tronco | L4: 1 | M4: DJ AL04010004 | N4: Disjuntor (DJ) | O4: 7903565004 | P4: 7903565004, 7935867004, 7902218004, 0330915004, 0203711004, 0202227004, 0204190004, 0200482004, 0200484004, 0200489004, 0200490004, 0230938004, 0200492004, 0202676004, 0303862004, 0229036004, 0200495004, 0201153004, 0352542004, 0300603004, 0203117004, 0202175004, 0300600004, 0203661004, 0300596004, 0300588004, 0300591004, 0200593004, 0224749004, 0200583004, 0300584004, 0300585004, 0300582004, 0204195004, 0300578004, 0229381004, 0200580004, 0202671004, 0204249004, 0200868004, 0200573004, 0200571004, 0230252004, 0303731004, 0200556004, 0303973004, 0200550004, 0201875004, 0200549004, 0200548004, 0200547004, 0345761004, 0201072004 | Q4: 53 | S4: DJ AL04010004 | X4: DJ AL04010004 | Y4: -7.195623 | Z4: -48.238206 | AA4: abrir | AB4: |DJ AL04010004|
A5: 4 | B5: TR-004 | C5: Suporte Chave 8804421004 | D5: 332180 | E5: N4 | F5: 2.1997169 | G5: 56.088954 | H5: 56.088954 | I5: T1 | J5: Tronco | K5: Tronco | L5: 1 | M5: DJ AL04010004 | N5: Disjuntor (DJ) | O5: 7903565004 | P5: 7903565004, 7935867004, 7902218004, 0330915004, 0203711004, 0202227004, 0204190004, 0200482004, 0200484004, 0200489004, 0200490004, 0230938004, 0200492004, 0202676004, 0303862004, 0229036004, 0200495004, 0201153004, 0352542004, 0300603004, 0203117004, 0202175004, 0300600004, 0203661004, 0300596004, 0300588004, 0300591004, 0200593004, 0224749004, 0200583004, 0300584004, 0300585004, 0300582004, 0204195004, 0300578004, 0229381004, 0200580004, 0202671004, 0204249004, 0200868004, 0200573004, 0200571004, 0230252004, 0303731004, 0200556004, 0303973004, 0200550004, 0201875004, 0200549004, 0200548004, 0200547004, 0345761004, 0201072004 | Q5: 53 | R5: 8804421004 | S5: DJ AL04010004 | X5: DJ AL04010004 | Y5: -7.1956735 | Z5: -48.238227 | AA5: abrir | AB5: |DJ AL04010004|
A6: 5 | B6: TR-005 | C6: 2796764 | D6: N4 | E6: N5 | F6: 19.683407 | G6: 75.772361 | H6: 75.772361 | I6: T1 | J6: Tronco | K6: Tronco | L6: 1 | M6: DJ AL04010004 | N6: Disjuntor (DJ) | O6: 7903565004 | P6: 7903565004, 7935867004, 7902218004, 0330915004, 0203711004, 0202227004, 0204190004, 0200482004, 0200484004, 0200489004, 0200490004, 0230938004, 0200492004, 0202676004, 0303862004, 0229036004, 0200495004, 0201153004, 0352542004, 0300603004, 0203117004, 0202175004, 0300600004, 0203661004, 0300596004, 0300588004, 0300591004, 0200593004, 0224749004, 0200583004, 0300584004, 0300585004, 0300582004, 0204195004, 0300578004, 0229381004, 0200580004, 0202671004, 0204249004, 0200868004, 0200573004, 0200571004, 0230252004, 0303731004, 0200556004, 0303973004, 0200550004, 0201875004, 0200549004, 0200548004, 0200547004, 0345761004, 0201072004 | Q6: 53 | S6: DJ AL04010004 | X6: DJ AL04010004 | Y6: -7.1957465 | Z6: -48.23816 | AA6: abrir | AB6: |DJ AL04010004|
A7: 6 | B7: TR-006 | C7: 12074474 | D7: N5 | E7: N6 | F7: 3.7592477 | G7: 79.531609 | H7: 79.531609 | I7: T1 | J7: Tronco | K7: Tronco | L7: 1 | M7: DJ AL04010004 | N7: Disjuntor (DJ) | O7: 7903565004 | P7: 7903565004, 7935867004, 7902218004, 0330915004, 0203711004, 0202227004, 0204190004, 0200482004, 0200484004, 0200489004, 0200490004, 0230938004, 0200492004, 0202676004, 0303862004, 0229036004, 0200495004, 0201153004, 0352542004, 0300603004, 0203117004, 0202175004, 0300600004, 0203661004, 0300596004, 0300588004, 0300591004, 0200593004, 0224749004, 0200583004, 0300584004, 0300585004, 0300582004, 0204195004, 0300578004, 0229381004, 0200580004, 0202671004, 0204249004, 0200868004, 0200573004, 0200571004, 0230252004, 0303731004, 0200556004, 0303973004, 0200550004, 0201875004, 0200549004, 0200548004, 0200547004, 0345761004, 0201072004 | Q7: 53 | S7: DJ AL04010004 | X7: DJ AL04010004 | Y7: -7.195824 | Z7: -48.238088 | AA7: abrir | AB7: |DJ AL04010004|
A8: 7 | B8: TR-007 | C8: 2518799 | D8: N6 | E8: N7 | F8: 23.496279 | G8: 103.02789 | H8: 103.02789 | I8: T1 | J8: Tronco | K8: Tronco | L8: 1 | M8: DJ AL04010004 | N8: Disjuntor (DJ) | O8: 7903565004 | P8: 7903565004, 7935867004, 7902218004, 0330915004, 0203711004, 0202227004, 0204190004, 0200482004, 0200484004, 0200489004, 0200490004, 0230938004, 0200492004, 0202676004, 0303862004, 0229036004, 0200495004, 0201153004, 0352542004, 0300603004, 0203117004, 0202175004, 0300600004, 0203661004, 0300596004, 0300588004, 0300591004, 0200593004, 0224749004, 0200583004, 0300584004, 0300585004, 0300582004, 0204195004, 0300578004, 0229381004, 0200580004, 0202671004, 0204249004, 0200868004, 0200573004, 0200571004, 0230252004, 0303731004, 0200556004, 0303973004, 0200550004, 0201875004, 0200549004, 0200548004, 0200547004, 0345761004, 0201072004 | Q8: 53 | S8: DJ AL04010004 | X8: DJ AL04010004 | Y8: -7.1959095 | Z8: -48.238 | AA8: abrir | AB8: |DJ AL04010004|
A9: 8 | B9: TR-008 | C9: 12072742 | D9: N7 | E9: N8 | F9: 3.6986195 | G9: 106.72651 | H9: 106.72651 | I9: T1 | J9: Tronco | K9: Tronco | L9: 1 | M9: DJ AL04010004 | N9: Disjuntor (DJ) | O9: 7903565004 | P9: 7903565004, 7935867004, 7902218004, 0330915004, 0203711004, 0202227004, 0204190004, 0200482004, 0200484004, 0200489004, 0200490004, 0230938004, 0200492004, 0202676004, 0303862004, 0229036004, 0200495004, 0201153004, 0352542004, 0300603004, 0203117004, 0202175004, 0300600004, 0203661004, 0300596004, 0300588004, 0300591004, 0200593004, 0224749004, 0200583004, 0300584004, 0300585004, 0300582004, 0204195004, 0300578004, 0229381004, 0200580004, 0202671004, 0204249004, 0200868004, 0200573004, 0200571004, 0230252004, 0303731004, 0200556004, 0303973004, 0200550004, 0201875004, 0200549004, 0200548004, 0200547004, 0345761004, 0201072004 | Q9: 53 | S9: DJ AL04010004 | X9: DJ AL04010004 | Y9: -7.1959935 | Z9: -48.23791 | AA9: abrir | AB9: |DJ AL04010004|
A10: 9 | B10: TR-009 | C10: 2794445 | D10: N8 | E10: N9 | F10: 137.81839 | G10: 244.54489 | H10: 244.54489 | I10: T1 | J10: Tronco | K10: Tronco | L10: 1 | M10: DJ AL04010004 | N10: Disjuntor (DJ) | O10: 7903565004 | P10: 7903565004, 7935867004, 7902218004, 0330915004, 0203711004, 0202227004, 0204190004, 0200482004, 0200484004, 0200489004, 0200490004, 0230938004, 0200492004, 0202676004, 0303862004, 0229036004, 0200495004, 0201153004, 0352542004, 0300603004, 0203117004, 0202175004, 0300600004, 0203661004, 0300596004, 0300588004, 0300591004, 0200593004, 0224749004, 0200583004, 0300584004, 0300585004, 0300582004, 0204195004, 0300578004, 0229381004, 0200580004, 0202671004, 0204249004, 0200868004, 0200573004, 0200571004, 0230252004, 0303731004, 0200556004, 0303973004, 0200550004, 0201875004, 0200549004, 0200548004, 0200547004, 0345761004, 0201072004 | Q10: 53 | S10: DJ AL04010004 | X10: DJ AL04010004 | Y10: -7.1962755 | Z10: -48.237336 | AA10: abrir | AB10: |DJ AL04010004|
A11: 10 | B11: TR-010 | C11: 12084027 | D11: N9 | E11: N10 | F11: 3.704776 | G11: 248.24967 | H11: 248.24967 | I11: T1 | J11: Tronco | K11: Tronco | L11: 1 | M11: DJ AL04010004 | N11: Disjuntor (DJ) | O11: 7903565004 | P11: 7903565004, 7935867004, 7902218004, 0330915004, 0203711004, 0202227004, 0204190004, 0200482004, 0200484004, 0200489004, 0200490004, 0230938004, 0200492004, 0202676004, 0303862004, 0229036004, 0200495004, 0201153004, 0352542004, 0300603004, 0203117004, 0202175004, 0300600004, 0203661004, 0300596004, 0300588004, 0300591004, 0200593004, 0224749004, 0200583004, 0300584004, 0300585004, 0300582004, 0204195004, 0300578004, 0229381004, 0200580004, 0202671004, 0204249004, 0200868004, 0200573004, 0200571004, 0230252004, 0303731004, 0200556004, 0303973004, 0200550004, 0201875004, 0200549004, 0200548004, 0200547004, 0345761004, 0201072004 | Q11: 53 | S11: DJ AL04010004 | X11: DJ AL04010004 | Y11: -7.196534 | Z11: -48.236764 | AA11: abrir | AB11: |DJ AL04010004|
A12: 11 | B12: TR-011 | C12: 3615824 | D12: N10 | E12: 531059 | F12: 20.440651 | G12: 268.69032 | H12: 268.69032 | I12: T1 | J12: Tronco | K12: Tronco | L12: 1 | M12: DJ AL04010004 | N12: Disjuntor (DJ) | O12: 7903565004 | P12: 7903565004, 7935867004, 7902218004, 0330915004, 0203711004, 0202227004, 0204190004, 0200482004, 0200484004, 0200489004, 0200490004, 0230938004, 0200492004, 0202676004, 0303862004, 0229036004, 0200495004, 0201153004, 0352542004, 0300603004, 0203117004, 0202175004, 0300600004, 0203661004, 0300596004, 0300588004, 0300591004, 0200593004, 0224749004, 0200583004, 0300584004, 0300585004, 0300582004, 0204195004, 0300578004, 0229381004, 0200580004, 0202671004, 0204249004, 0200868004, 0200573004, 0200571004, 0230252004, 0303731004, 0200556004, 0303973004, 0200550004, 0201875004, 0200549004, 0200548004, 0200547004, 0345761004, 0201072004 | Q12: 53 | S12: DJ AL04010004 | X12: DJ AL04010004 | Y12: -7.1964355 | Z12: -48.236719 | AA12: abrir | AB12: |DJ AL04010004|
A13: 12 | B13: TR-012 | C13: 12072736 | D13: 531059 | E13: N12 | F13: 3.6760381 | G13: 272.36636 | H13: 272.36636 | I13: T1 | J13: Tronco | K13: Tronco | L13: 1 | M13: DJ AL04010004 | N13: Disjuntor (DJ) | O13: 7903565004 | P13: 7903565004, 7935867004, 7902218004, 0330915004, 0203711004, 0202227004, 0204190004, 0200482004, 0200484004, 0200489004, 0200490004, 0230938004, 0200492004, 0202676004, 0303862004, 0229036004, 0200495004, 0201153004, 0352542004, 0300603004, 0203117004, 0202175004, 0300600004, 0203661004, 0300596004, 0300588004, 0300591004, 0200593004, 0224749004, 0200583004, 0300584004, 0300585004, 0300582004, 0204195004, 0300578004, 0229381004, 0200580004, 0202671004, 0204249004, 0200868004, 0200573004, 0200571004, 0230252004, 0303731004, 0200556004, 0303973004, 0200550004, 0201875004, 0200549004, 0200548004, 0200547004, 0345761004, 0201072004 | Q13: 53 | S13: DJ AL04010004 | X13: DJ AL04010004 | Y13: -7.196335 | Z13: -48.236678 | AA13: abrir | AB13: |DJ AL04010004|
A14: 13 | B14: TR-013 | C14: 2518888 | D14: N12 | E14: N13 | F14: 12.673459 | G14: 285.03982 | H14: 285.03982 | I14: T1 | J14: Tronco | K14: Tronco | L14: 1 | M14: DJ AL04010004 | N14: Disjuntor (DJ) | O14: 7903565004 | P14: 7903565004, 7935867004, 7902218004, 0330915004, 0203711004, 0202227004, 0204190004, 0200482004, 0200484004, 0200489004, 0200490004, 0230938004, 0200492004, 0202676004, 0303862004, 0229036004, 0200495004, 0201153004, 0352542004, 0300603004, 0203117004, 0202175004, 0300600004, 0203661004, 0300596004, 0300588004, 0300591004, 0200593004, 0224749004, 0200583004, 0300584004, 0300585004, 0300582004, 0204195004, 0300578004, 0229381004, 0200580004, 0202671004, 0204249004, 0200868004, 0200573004, 0200571004, 0230252004, 0303731004, 0200556004, 0303973004, 0200550004, 0201875004, 0200549004, 0200548004, 0200547004, 0345761004, 0201072004 | Q14: 53 | S14: DJ AL04010004 | X14: DJ AL04010004 | Y14: -7.196268 | Z14: -48.236647 | AA14: abrir | AB14: |DJ AL04010004|
A15: 14 | B15: TR-014 | C15: Suporte Chave 8802681004 | D15: N13 | E15: N14 | F15: 1.1427014 | G15: 286.18252 | H15: 286.18252 | I15: T1 | J15: Tronco | K15: Tronco | L15: 1 | M15: DJ AL04010004 | N15: Disjuntor (DJ) | O15: 7903565004 | P15: 7903565004, 7935867004, 7902218004, 0330915004, 0203711004, 0202227004, 0204190004, 0200482004, 0200484004, 0200489004, 0200490004, 0230938004, 0200492004, 0202676004, 0303862004, 0229036004, 0200495004, 0201153004, 0352542004, 0300603004, 0203117004, 0202175004, 0300600004, 0203661004, 0300596004, 0300588004, 0300591004, 0200593004, 0224749004, 0200583004, 0300584004, 0300585004, 0300582004, 0204195004, 0300578004, 0229381004, 0200580004, 0202671004, 0204249004, 0200868004, 0200573004, 0200571004, 0230252004, 0303731004, 0200556004, 0303973004, 0200550004, 0201875004, 0200549004, 0200548004, 0200547004, 0345761004, 0201072004 | Q15: 53 | R15: 8802681004 | S15: DJ AL04010004 | X15: DJ AL04010004 | Y15: -7.1962115 | Z15: -48.236621 | AA15: abrir | AB15: |DJ AL04010004|
A16: 15 | B16: TR-015 | C16: 2518881 | D16: N14 | E16: N15 | F16: 256.51202 | G16: 542.69454 | H16: 542.69454 | I16: T1 | J16: Tronco | K16: Tronco | L16: 1 | M16: DJ AL04010004 | N16: Disjuntor (DJ) | O16: 7903565004 | P16: 7903565004, 7935867004, 7902218004, 0330915004, 0203711004, 0202227004, 0204190004, 0200482004, 0200484004, 0200489004, 0200490004, 0230938004, 0200492004, 0202676004, 0303862004, 0229036004, 0200495004, 0201153004, 0352542004, 0300603004, 0203117004, 0202175004, 0300600004, 0203661004, 0300596004, 0300588004, 0300591004, 0200593004, 0224749004, 0200583004, 0300584004, 0300585004, 0300582004, 0204195004, 0300578004, 0229381004, 0200580004, 0202671004, 0204249004, 0200868004, 0200573004, 0200571004, 0230252004, 0303731004, 0200556004, 0303973004, 0200550004, 0201875004, 0200549004, 0200548004, 0200547004, 0345761004, 0201072004 | Q16: 53 | S16: DJ AL04010004 | X16: DJ AL04010004 | Y16: -7.1951585 | Z16: -48.236134 | AA16: abrir | AB16: |DJ AL04010004|
A17: 16 | B17: TR-016 | C17: 12072735 | D17: N15 | E17: N16 | F17: 3.823669 | G17: 546.51821 | H17: 546.51821 | I17: T1 | J17: Tronco | K17: Tronco | L17: 1 | M17: DJ AL04010004 | N17: Disjuntor (DJ) | O17: 7903565004 | P17: 7903565004, 7935867004, 7902218004, 0330915004, 0203711004, 0202227004, 0204190004, 0200482004, 0200484004, 0200489004, 0200490004, 0230938004, 0200492004, 0202676004, 0303862004, 0229036004, 0200495004, 0201153004, 0352542004, 0300603004, 0203117004, 0202175004, 0300600004, 0203661004, 0300596004, 0300588004, 0300591004, 0200593004, 0224749004, 0200583004, 0300584004, 0300585004, 0300582004, 0204195004, 0300578004, 0229381004, 0200580004, 0202671004, 0204249004, 0200868004, 0200573004, 0200571004, 0230252004, 0303731004, 0200556004, 0303973004, 0200550004, 0201875004, 0200549004, 0200548004, 0200547004, 0345761004, 0201072004 | Q17: 53 | S17: DJ AL04010004 | X17: DJ AL04010004 | Y17: -7.1940945 | Z17: -48.235642 | AA17: abrir | AB17: |DJ AL04010004|
A18: 17 | B18: TR-017 | C18: 2796461 | D18: N16 | E18: N17 | F18: 89.450652 | G18: 635.96886 | H18: 635.96886 | I18: T1 | J18: Tronco | K18: Tronco | L18: 1 | M18: DJ AL04010004 | N18: Disjuntor (DJ) | O18: 7903565004 | P18: 7903565004, 7935867004, 7902218004, 0330915004, 0203711004, 0202227004, 0204190004, 0200482004, 0200484004, 0200489004, 0200490004, 0230938004, 0200492004, 0202676004, 0303862004, 0229036004, 0200495004, 0201153004, 0352542004, 0300603004, 0203117004, 0202175004, 0300600004, 0203661004, 0300596004, 0300588004, 0300591004, 0200593004, 0224749004, 0200583004, 0300584004, 0300585004, 0300582004, 0204195004, 0300578004, 0229381004, 0200580004, 0202671004, 0204249004, 0200868004, 0200573004, 0200571004, 0230252004, 0303731004, 0200556004, 0303973004, 0200550004, 0201875004, 0200549004, 0200548004, 0200547004, 0345761004, 0201072004 | Q18: 53 | S18: DJ AL04010004 | X18: DJ AL04010004 | Y18: -7.193709 | Z18: -48.235476 | AA18: abrir | AB18: |DJ AL04010004|
A19: 18 | B19: TR-018 | C19: 12072734 | D19: N17 | E19: N18 | F19: 3.7965247 | G19: 639.76539 | H19: 639.76539 | I19: T1 | J19: Tronco | K19: Tronco | L19: 1 | M19: DJ AL04010004 | N19: Disjuntor (DJ) | O19: 7903565004 | P19: 7903565004, 7935867004, 7902218004, 0330915004, 0203711004, 0202227004, 0204190004, 0200482004, 0200484004, 0200489004, 0200490004, 0230938004, 0200492004, 0202676004, 0303862004, 0229036004, 0200495004, 0201153004, 0352542004, 0300603004, 0203117004, 0202175004, 0300600004, 0203661004, 0300596004, 0300588004, 0300591004, 0200593004, 0224749004, 0200583004, 0300584004, 0300585004, 0300582004, 0204195004, 0300578004, 0229381004, 0200580004, 0202671004, 0204249004, 0200868004, 0200573004, 0200571004, 0230252004, 0303731004, 0200556004, 0303973004, 0200550004, 0201875004, 0200549004, 0200548004, 0200547004, 0345761004, 0201072004 | Q19: 53 | S19: DJ AL04010004 | X19: DJ AL04010004 | Y19: -7.193323 | Z19: -48.235311 | AA19: abrir | AB19: |DJ AL04010004|
A20: 19 | B20: TR-019 | C20: 36726625 | D20: N18 | E20: N19 | F20: 56.883494 | G20: 696.64888 | H20: 696.64888 | I20: T1 | J20: Tronco | K20: Tronco | L20: 1 | M20: DJ AL04010004 | N20: Disjuntor (DJ) | O20: 7903565004 | P20: 7903565004, 7935867004, 7902218004, 0330915004, 0203711004, 0202227004, 0204190004, 0200482004, 0200484004, 0200489004, 0200490004, 0230938004, 0200492004, 0202676004, 0303862004, 0229036004, 0200495004, 0201153004, 0352542004, 0300603004, 0203117004, 0202175004, 0300600004, 0203661004, 0300596004, 0300588004, 0300591004, 0200593004, 0224749004, 0200583004, 0300584004, 0300585004, 0300582004, 0204195004, 0300578004, 0229381004, 0200580004, 0202671004, 0204249004, 0200868004, 0200573004, 0200571004, 0230252004, 0303731004, 0200556004, 0303973004, 0200550004, 0201875004, 0200549004, 0200548004, 0200547004, 0345761004, 0201072004 | Q20: 53 | S20: DJ AL04010004 | X20: DJ AL04010004 | Y20: -7.1930645 | Z20: -48.235223 | AA20: abrir | AB20: |DJ AL04010004|
A21: 20 | B21: TR-020 | C21: 12077670 | D21: N19 | E21: 122082 | F21: 3.5889314 | G21: 700.23781 | H21: 700.23781 | I21: T1 | J21: Tronco | K21: Tronco | L21: 1 | M21: DJ AL04010004 | N21: Disjuntor (DJ) | O21: 7903565004 | P21: 7903565004, 7935867004, 7902218004, 0330915004, 0203711004, 0202227004, 0204190004, 0200482004, 0200484004, 0200489004, 0200490004, 0230938004, 0200492004, 0202676004, 0303862004, 0229036004, 0200495004, 0201153004, 0352542004, 0300603004, 0203117004, 0202175004, 0300600004, 0203661004, 0300596004, 0300588004, 0300591004, 0200593004, 0224749004, 0200583004, 0300584004, 0300585004, 0300582004, 0204195004, 0300578004, 0229381004, 0200580004, 0202671004, 0204249004, 0200868004, 0200573004, 0200571004, 0230252004, 0303731004, 0200556004, 0303973004, 0200550004, 0201875004, 0200549004, 0200548004, 0200547004, 0345761004, 0201072004 | Q21: 53 | S21: DJ AL04010004 | X21: DJ AL04010004 | Y21: -7.192807 | Z21: -48.235135 | AA21: abrir | AB21: |DJ AL04010004|
A22: 21 | B22: TR-021 | C22: 2751430 | D22: 122082 | E22: N21 | F22: 148.49989 | G22: 848.7377 | H22: 848.7377 | I22: T1 | J22: Tronco | K22: Tronco | L22: 1 | M22: DJ AL04010004 | N22: Disjuntor (DJ) | O22: 7903565004 | P22: 7903565004, 7935867004, 7902218004, 0330915004, 0203711004, 0202227004, 0204190004, 0200482004, 0200484004, 0200489004, 0200490004, 0230938004, 0200492004, 0202676004, 0303862004, 0229036004, 0200495004, 0201153004, 0352542004, 0300603004, 0203117004, 0202175004, 0300600004, 0203661004, 0300596004, 0300588004, 0300591004, 0200593004, 0224749004, 0200583004, 0300584004, 0300585004, 0300582004, 0204195004, 0300578004, 0229381004, 0200580004, 0202671004, 0204249004, 0200868004, 0200573004, 0200571004, 0230252004, 0303731004, 0200556004, 0303973004, 0200550004, 0201875004, 0200549004, 0200548004, 0200547004, 0345761004, 0201072004 | Q22: 53 | S22: DJ AL04010004 | X22: DJ AL04010004 | Y22: -7.192196 | Z22: -48.234825 | AA22: abrir | AB22: |DJ AL04010004|
