Workbook

Sheet Leia-me
A1: Zonas, ramais e blocos — AL01010004
A3: Zona | B3: T1 do DJ ao 1º religador (79). Depois de qualquer religador é T2, inclusive religador em ramal: religador nunca cria T3. Depois de uma chave fusível (03) é T3; fusível depois de fusível continua T3 (não existe T4).
A4: Seccionamento | B4: Chave 03/33/02 com religador depois dela não conta como fusível: não muda a zona e aparece em "Outras chaves no bloco (88…)" como "Chave 03 de seccionamento".
A5: Tronco | B5: Caminho DJ → 1º religador → 2º religador e, depois do 2º, até os próximos ativos (religador ou fusível): o trecho entre dois ativos do tronco ainda é tronco. Pontas sem equipamento são ramal. Nunca tem T3. O resto é ramal, com o nome do poste onde sai do tronco.
A6: Ativo de referência | B6: Último DJ, 79 ou 03 antes do vão, vindo do DJ. Ele engloba o vão e tudo o que vem depois.
A7: Ativos posteriores englobados | B7: Os DJ/79/03 que ficam depois do vão ou do bloco. Se o ativo de referência abrir, todos ficam sem energia.
A8: Bloco | B8: Vãos com o mesmo ativo de referência e o mesmo ramal (de um ativo até o próximo). Chaves 88 e outras que não são DJ/79/fusível não dividem bloco: aparecem na coluna "Outras chaves no bloco (88…)". Chaves 02 e 33 contam como fusível.
A9: Nível 1…N | B9: Sequência de ativos desde o DJ até o ativo de referência. Filtrar um nível mostra tudo o que fica depois daquele ativo.
A10: Distâncias | B10: Calculadas a partir das coordenadas (haversine, raio 6.371 km), seguindo a rede.
A11: Abas | B11: Árvore de blocos: visão rápida da sequência, agrupada por tronco e ramal. Consulta: digite um poste e veja onde ele está. Blocos: um bloco por linha, com os ativos posteriores um por coluna e juntos numa coluna só. Por bloco: os vãos agrupados embaixo de cada bloco (botão + à esquerda). Trechos: um vão por linha. Ativos: resumo por ativo.
A12: Aviso | B12: 1 chave(s) 03/33/02 com religador depois tratada(s) como seccionamento (não mudam a zona; entram na lista do bloco): 0349277004
A14: Cores das zonas
A15: T1
A16: T2
A17: T3

Sheet Árvore de blocos
A1: Árvore de blocos — AL01010004
A2: Cada linha é um bloco. A célula colorida é o ativo de referência do bloco (cor da zona). As células em cinza à esquerda são os ativos antes dele, desde o DJ.
A3: Zonas: | B3: T1 | C3: T2 | D3: T3
A5: Bloco | B5: Zona | C5: Nível 1 | D5: Nível 2 | E5: Nível 3 | F5: Nível 4 | G5: Nível 5 | H5: Nível 6 | I5: De | J5: Até (próximos ativos) | K5: Vãos | L5: Extensão (m) | M5: Outras chaves no bloco (88…) | N5: Ativos englobados (depois do bloco)
A6: TRONCO — do DJ ao 2º religador e até os próximos ativos
A7: 1 | B7: T1 | C7: DJ AL01010004 | I7: DJ AL01010004 | J7: 7900106004 | K7: =COUNTIFS(Trechos!$L$2:$L$838,A7) -> 43 | L7: =SUMIFS(Trechos!$F$2:$F$838,Trechos!$L$2:$L$838,A7) -> 1688.686 | M7: 8800002004, 8838716004, 8836357004, 8823701004 | N7: =Blocos!BT2 -> 7900106004, 7927795004, 0300031004, 0345006004, 0352810004, 0300724004, 0342284004, 0200038004, 0328286004, 0314965004, 0344627004, 0334747004, 0347400004, 0358161004, 0342738004, 0203728004, 0328468004, 0329025004, 0203016004, 0300049004, 0203015004, 0300052004, 0200050004, 0200028004, 0300024004, 0349562004, 0349564004, 0355236004, 0200023004, 0204420004, 0302387004, 3302865004, 3300065004, 0320309004, 0310307004, 0303851004, 0310306004, 0303865004, 0342709004, 0303866004, 0303867004, 0302309004, 0300064004, 0320308004, 0301840004, 0303850004, 0320305004, 0346260004, 0346420004, 0355088004, 0340038004, 0201389004, 0303849004, 0310949004, 0210950004, 0301838004, 0301839004, 0245040004, 0303718004, 0202970004, 0354089004, 0354093004, 0220315004, 0346072004, 0345823004, 0200043004, 0200011004, 0357531004, 0303835004, 0356395004, 3300016004, 0301090004, 0303861004, 0304100004, 0201099004, 0301069004
A8: 2 | B8: T2 | C8: DJ AL01010004 | D8: 7900106004 | I8: 7900106004 | J8: 7927795004 | K8: =COUNTIFS(Trechos!$L$2:$L$838,A8) -> 29 | L8: =SUMIFS(Trechos!$F$2:$F$838,Trechos!$L$2:$L$838,A8) -> 1397.3178 | M8: 8802390004, 0349277004, 8827796004, 8800029004 | N8: =Blocos!BT3 -> 7927795004, 0300031004, 0345006004, 0352810004, 0300724004, 0342284004, 0200038004, 0328286004, 0314965004, 0344627004, 0334747004, 0347400004, 0358161004, 0342738004, 0203728004, 0328468004, 0329025004, 0203016004, 0300049004, 0203015004, 0300052004, 0200050004, 0200028004, 0300024004, 0349562004, 0349564004, 0355236004, 0200023004, 0204420004
A9: 3 | B9: T2 | C9: DJ AL01010004 | D9: 7900106004 | E9: 7927795004 | I9: 7927795004 | J9: 0300031004 / 0300724004 / 0328286004 / 0314965004 / 0344627004 / 0334747004 / 0203728004 / 0328468004 / 0329025004 / 0203016004 / 0300049004 / 0203015004 | K9: =COUNTIFS(Trechos!$L$2:$L$838,A9) -> 114 | L9: =SUMIFS(Trechos!$F$2:$F$838,Trechos!$L$2:$L$838,A9) -> 5582.6239 | M9: 8841354004, 8800034004, 8803727004, 8828470004, 8814964004, 8855846004, 8855095004, 8855094004, 8858328004, 8804463004 | N9: =Blocos!BT4 -> 0300031004, 0345006004, 0352810004, 0300724004, 0342284004, 0200038004, 0328286004, 0314965004, 0344627004, 0334747004, 0347400004, 0358161004, 0342738004, 0203728004, 0328468004, 0329025004, 0203016004, 0300049004, 0203015004
A10: RAMAL DO 0200011004 — sai do tronco no poste 0200011004
A11: 4 | B11: T1 | C11: DJ AL01010004 | I11: poste N13 | J11: 0200011004 / 0357531004 / fim 59283022 / 0303835004 / fim 554197 / 0356395004 / 3300016004 / 0201099004 / fim 48647275 / fim N107 / fim 93802 / 0301069004 / fim 555910 / fim 539462 / fim 555011 / fim N29 / fim 536530 | K11: =COUNTIFS(Trechos!$L$2:$L$838,A11) -> 73 | L11: =SUMIFS(Trechos!$F$2:$F$838,Trechos!$L$2:$L$838,A11) -> 3978.3332 | M11: 8801100004, 8801130004, 8800010004, 8800009004, 8804031004, 8858190004, 8800015004 | N11: =Blocos!BT5 -> 0200011004, 0357531004, 0303835004, 0356395004, 3300016004, 0301090004, 0303861004, 0304100004, 0201099004, 0301069004
A12: 5 | B12: T3 | C12: DJ AL01010004 | D12: 0200011004 | I12: 0200011004 | J12: fim N218 | K12: =COUNTIFS(Trechos!$L$2:$L$838,A12) -> 2 | L12: =SUMIFS(Trechos!$F$2:$F$838,Trechos!$L$2:$L$838,A12) -> 26.25525 | M12: — | N12: =Blocos!BT6 -> —
A13: 6 | B13: T3 | C13: DJ AL01010004 | D13: 0357531004 | I13: 0357531004 | J13: fim 41939697 | K13: =COUNTIFS(Trechos!$L$2:$L$838,A13) -> 2 | L13: =SUMIFS(Trechos!$F$2:$F$838,Trechos!$L$2:$L$838,A13) -> 86.236461 | M13: — | N13: =Blocos!BT7 -> —
A14: 7 | B14: T3 | C14: DJ AL01010004 | D14: 0303835004 | I14: 0303835004 | J14: fim 538289 | K14: =COUNTIFS(Trechos!$L$2:$L$838,A14) -> 2 | L14: =SUMIFS(Trechos!$F$2:$F$838,Trechos!$L$2:$L$838,A14) -> 164.5764 | M14: — | N14: =Blocos!BT8 -> —
A15: 8 | B15: T3 | C15: DJ AL01010004 | D15: 0356395004 | I15: 0356395004 | J15: fim 41939685 | K15: =COUNTIFS(Trechos!$L$2:$L$838,A15) -> 4 | L15: =SUMIFS(Trechos!$F$2:$F$838,Trechos!$L$2:$L$838,A15) -> 242.11235 | M15: — | N15: =Blocos!BT9 -> —
A16: 9 | B16: T3 | C16: DJ AL01010004 | D16: 3300016004 | I16: 3300016004 | J16: 0301090004 | K16: =COUNTIFS(Trechos!$L$2:$L$838,A16) -> 6 | L16: =SUMIFS(Trechos!$F$2:$F$838,Trechos!$L$2:$L$838,A16) -> 419.6145 | M16: — | N16: =Blocos!BT10 -> 0301090004, 0303861004, 0304100004
A17: 10 | B17: T3 | C17: DJ AL01010004 | D17: 3300016004 | E17: 0301090004 | I17: 0301090004 | J17: 0303861004 / 0304100004 / fim 115640 | K17: =COUNTIFS(Trechos!$L$2:$L$838,A17) -> 7 | L17: =SUMIFS(Trechos!$F$2:$F$838,Trechos!$L$2:$L$838,A17) -> 505.3772 | M17: — | N17: =Blocos!BT11 -> 0303861004, 0304100004
A18: 11 | B18: T3 | C18: DJ AL01010004 | D18: 3300016004 | E18: 0301090004 | F18: 0303861004 | I18: 0303861004 | J18: fim N161 | K18: =COUNTIFS(Trechos!$L$2:$L$838,A18) -> 1 | L18: =SUMIFS(Trechos!$F$2:$F$838,Trechos!$L$2:$L$838,A18) -> 122.54796 | M18: — | N18: =Blocos!BT12 -> —
A19: 12 | B19: T3 | C19: DJ AL01010004 | D19: 3300016004 | E19: 0301090004 | F19: 0304100004 | I19: 0304100004 | J19: fim 1097675 | K19: =COUNTIFS(Trechos!$L$2:$L$838,A19) -> 1 | L19: =SUMIFS(Trechos!$F$2:$F$838,Trechos!$L$2:$L$838,A19) -> 53.386472 | M19: — | N19: =Blocos!BT13 -> —
A20: 13 | B20: T3 | C20: DJ AL01010004 | D20: 0201099004 | I20: 0201099004 | J20: fim N215 / fim 590202 | K20: =COUNTIFS(Trechos!$L$2:$L$838,A20) -> 3 | L20: =SUMIFS(Trechos!$F$2:$F$838,Trechos!$L$2:$L$838,A20) -> 17.631789 | M20: — | N20: =Blocos!BT14 -> —
A21: 14 | B21: T3 | C21: DJ AL01010004 | D21: 0301069004 | I21: 0301069004 | J21: fim 556216 | K21: =COUNTIFS(Trechos!$L$2:$L$838,A21) -> 1 | L21: =SUMIFS(Trechos!$F$2:$F$838,Trechos!$L$2:$L$838,A21) -> 5.1647457 | M21: — | N21: =Blocos!BT15 -> —
A22: RAMAL 1471339 — sai do tronco no poste 1471339
A23: 15 | B23: T1 | C23: DJ AL01010004 | I23: poste 1471339 | J23: fim 1471341 | K23: =COUNTIFS(Trechos!$L$2:$L$838,A23) -> 1 | L23: =SUMIFS(Trechos!$F$2:$F$838,Trechos!$L$2:$L$838,A23) -> 81.237519 | M23: — | N23: =Blocos!BT16 -> —
A24: RAMAL DO 0302387004 — sai do tronco no poste 0302387004
A25: 16 | B25: T1 | C25: DJ AL01010004 | I25: poste N86 | J25: fim N91 / fim 93656 / fim 550067 / 0302387004 / fim 35013393 / fim 35013388 / 0346420004 / fim 539706 / fim 587027 / fim 29689259 / fim 29689060 / fim 29689128 / 0355088004 / 0340038004 / 0201389004 / fim 38388446 / fim 38388428 / fim 345020 / fim 586093 / 0303849004 / fim N204 / fim N318 / 0310949004 / fim N179 / 0301838004 / 0245040004 / fim N170 / 0303718004 / 0202970004 / fim N158 / fim 557105 / fim N274 / 0354089004 / fim 556507 / 0220315004 / fim 554755 / fim 557326 / fim 554754 / fim 557325 / fim 553761 / fim 553760 / fim 557877 / fim 557872 / fim 557871 / fim 557874 / fim 554507 / fim 34566747 / 0346072004 / fim 31715517 / 0345823004 / fim 31715612 / fim 554240 / fim 554237 / fim 553817 / fim N141 / 0200043004 | K25: =COUNTIFS(Trechos!$L$2:$L$838,A25) -> 173 | L25: =SUMIFS(Trechos!$F$2:$F$838,Trechos!$L$2:$L$838,A25) -> 8992.9892 | M25: 8802389004, 8804077004, 8844641004, 8801105004, 8802780004, 8855073004, 8803581004, 8803577004, 8845830004 | N25: =Blocos!BT17 -> 0302387004, 3302865004, 3300065004, 0320309004, 0310307004, 0303851004, 0310306004, 0303865004, 0342709004, 0303866004, 0303867004, 0302309004, 0300064004, 0320308004, 0301840004, 0303850004, 0320305004, 0346260004, 0346420004, 0355088004, 0340038004, 0201389004, 0303849004, 0310949004, 0210950004, 0301838004, 0301839004, 0245040004, 0303718004, 0202970004, 0354089004, 0354093004, 0220315004, 0346072004, 0345823004, 0200043004
A26: 17 | B26: T3 | C26: DJ AL01010004 | D26: 0302387004 | I26: 0302387004 | J26: fim 587304 / fim 538104 / 3302865004 / fim 538331 / 0303850004 / fim 553248 / 0346260004 | K26: =COUNTIFS(Trechos!$L$2:$L$838,A26) -> 13 | L26: =SUMIFS(Trechos!$F$2:$F$838,Trechos!$L$2:$L$838,A26) -> 1089.0585 | M26: — | N26: =Blocos!BT18 -> 3302865004, 3300065004, 0320309004, 0310307004, 0303851004, 0310306004, 0303865004, 0342709004, 0303866004, 0303867004, 0302309004, 0300064004, 0320308004, 0301840004, 0303850004, 0320305004, 0346260004
A27: 18 | B27: T3 | C27: DJ AL01010004 | D27: 0302387004 | E27: 3302865004 | I27: 3302865004 | J27: 3300065004 / 0300064004 / 0320308004 / 0301840004 | K27: =COUNTIFS(Trechos!$L$2:$L$838,A27) -> 12 | L27: =SUMIFS(Trechos!$F$2:$F$838,Trechos!$L$2:$L$838,A27) -> 1422.7885 | M27: — | N27: =Blocos!BT19 -> 3300065004, 0320309004, 0310307004, 0303851004, 0310306004, 0303865004, 0342709004, 0303866004, 0303867004, 0302309004, 0300064004, 0320308004, 0301840004
A28: 19 | B28: T3 | C28: DJ AL01010004 | D28: 0302387004 | E28: 3302865004 | F28: 3300065004 | I28: 3300065004 | J28: 0320309004 / fim 173794 | K28: =COUNTIFS(Trechos!$L$2:$L$838,A28) -> 5 | L28: =SUMIFS(Trechos!$F$2:$F$838,Trechos!$L$2:$L$838,A28) -> 300.01825 | M28: — | N28: =Blocos!BT20 -> 0320309004, 0310307004, 0303851004, 0310306004, 0303865004, 0342709004, 0303866004, 0303867004, 0302309004
A29: 20 | B29: T3 | C29: DJ AL01010004 | D29: 0302387004 | E29: 3302865004 | F29: 3300065004 | G29: 0320309004 | I29: 0320309004 | J29: 0310307004 / 0303851004 / 0310306004 / 0303865004 / 0342709004 / 0303866004 / 0303867004 / 0302309004 | K29: =COUNTIFS(Trechos!$L$2:$L$838,A29) -> 31 | L29: =SUMIFS(Trechos!$F$2:$F$838,Trechos!$L$2:$L$838,A29) -> 3388.7675 | M29: — | N29: =Blocos!BT21 -> 0310307004, 0303851004, 0310306004, 0303865004, 0342709004, 0303866004, 0303867004, 0302309004
A30: 21 | B30: T3 | C30: DJ AL01010004 | D30: 0302387004 | E30: 3302865004 | F30: 3300065004 | G30: 0320309004 | H30: 0310307004 | I30: 0310307004 | J30: fim 173836 | K30: =COUNTIFS(Trechos!$L$2:$L$838,A30) -> 1 | L30: =SUMIFS(Trechos!$F$2:$F$838,Trechos!$L$2:$L$838,A30) -> 35.92843 | M30: — | N30: =Blocos!BT22 -> —
A31: 22 | B31: T3 | C31: DJ AL01010004 | D31: 0302387004 | E31: 3302865004 | F31: 3300065004 | G31: 0320309004 | H31: 0303851004 | I31: 0303851004 | J31: fim 586318 | K31: =COUNTIFS(Trechos!$L$2:$L$838,A31) -> 1 | L31: =SUMIFS(Trechos!$F$2:$F$838,Trechos!$L$2:$L$838,A31) -> 466.71724 | M31: — | N31: =Blocos!BT23 -> —
A32: 23 | B32: T3 | C32: DJ AL01010004 | D32: 0302387004 | E32: 3302865004 | F32: 3300065004 | G32: 0320309004 | H32: 0310306004 | I32: 0310306004 | J32: fim 173833 | K32: =COUNTIFS(Trechos!$L$2:$L$838,A32) -> 1 | L32: =SUMIFS(Trechos!$F$2:$F$838,Trechos!$L$2:$L$838,A32) -> 261.89621 | M32: — | N32: =Blocos!BT24 -> —
A33: 24 | B33: T3 | C33: DJ AL01010004 | D33: 0302387004 | E33: 3302865004 | F33: 3300065004 | G33: 0320309004 | H33: 0303865004 | I33: 0303865004 | J33: fim 549515 | K33: =COUNTIFS(Trechos!$L$2:$L$838,A33) -> 1 | L33: =SUMIFS(Trechos!$F$2:$F$838,Trechos!$L$2:$L$838,A33) -> 114.5567 | M33: — | N33: =Blocos!BT25 -> —
A34: 25 | B34: T3 | C34: DJ AL01010004 | D34: 0302387004 | E34: 3302865004 | F34: 3300065004 | G34: 0320309004 | H34: 0342709004 | I34: 0342709004 | J34: fim 1461337 | K34: =COUNTIFS(Trechos!$L$2:$L$838,A34) -> 3 | L34: =SUMIFS(Trechos!$F$2:$F$838,Trechos!$L$2:$L$838,A34) -> 106.35573 | M34: — | N34: =Blocos!BT26 -> —
A35: 26 | B35: T3 | C35: DJ AL01010004 | D35: 0302387004 | E35: 3302865004 | F35: 3300065004 | G35: 0320309004 | H35: 0303866004 | I35: 0303866004 | J35: fim 590237 | K35: =COUNTIFS(Trechos!$L$2:$L$838,A35) -> 1 | L35: =SUMIFS(Trechos!$F$2:$F$838,Trechos!$L$2:$L$838,A35) -> 50.299251 | M35: — | N35: =Blocos!BT27 -> —
A36: 27 | B36: T3 | C36: DJ AL01010004 | D36: 0302387004 | E36: 3302865004 | F36: 3300065004 | G36: 0320309004 | H36: 0303867004 | I36: 0303867004 | J36: fim 589790 | K36: =COUNTIFS(Trechos!$L$2:$L$838,A36) -> 1 | L36: =SUMIFS(Trechos!$F$2:$F$838,Trechos!$L$2:$L$838,A36) -> 92.258631 | M36: — | N36: =Blocos!BT28 -> —
A37: 28 | B37: T3 | C37: DJ AL01010004 | D37: 0302387004 | E37: 3302865004 | F37: 3300065004 | G37: 0320309004 | H37: 0302309004 | I37: 0302309004 | J37: fim 311399 | K37: =COUNTIFS(Trechos!$L$2:$L$838,A37) -> 1 | L37: =SUMIFS(Trechos!$F$2:$F$838,Trechos!$L$2:$L$838,A37) -> 252.90918 | M37: — | N37: =Blocos!BT29 -> —
A38: 29 | B38: T3 | C38: DJ AL01010004 | D38: 0302387004 | E38: 3302865004 | F38: 0300064004 | I38: 0300064004 | J38: fim 93637 | K38: =COUNTIFS(Trechos!$L$2:$L$838,A38) -> 1 | L38: =SUMIFS(Trechos!$F$2:$F$838,Trechos!$L$2:$L$838,A38) -> 30.83559 | M38: — | N38: =Blocos!BT30 -> —
A39: 30 | B39: T3 | C39: DJ AL01010004 | D39: 0302387004 | E39: 3302865004 | F39: 0320308004 | I39: 0320308004 | J39: fim 173793 | K39: =COUNTIFS(Trechos!$L$2:$L$838,A39) -> 1 | L39: =SUMIFS(Trechos!$F$2:$F$838,Trechos!$L$2:$L$838,A39) -> 60.470929 | M39: — | N39: =Blocos!BT31 -> —
A40: 31 | B40: T3 | C40: DJ AL01010004 | D40: 0302387004 | E40: 3302865004 | F40: 0301840004 | I40: 0301840004 | J40: fim 31758476 | K40: =COUNTIFS(Trechos!$L$2:$L$838,A40) -> 1 | L40: =SUMIFS(Trechos!$F$2:$F$838,Trechos!$L$2:$L$838,A40) -> 347.96775 | M40: — | N40: =Blocos!BT32 -> —
A41: 32 | B41: T3 | C41: DJ AL01010004 | D41: 0302387004 | E41: 0303850004 | I41: 0303850004 | J41: 0320305004 / fim 553249 / fim 538115 / fim 539707 / fim 539737 | K41: =COUNTIFS(Trechos!$L$2:$L$838,A41) -> 12 | L41: =SUMIFS(Trechos!$F$2:$F$838,Trechos!$L$2:$L$838,A41) -> 559.31223 | M41: — | N41: =Blocos!BT33 -> 0320305004
...

Sheet Consulta
A1: Onde fica este poste?
A2: Digite o código do poste na célula amarela (o poste no fim do vão). A planilha mostra o vão e a sequência desde o DJ.
A4: Poste | B4: N801 | C4: ← exemplo
A6: Trecho (vão) | B6: =IFERROR(INDEX(Trechos!$B$2:$B$838,MATCH($B$4,Trechos!$E$2:$E$838,0)),"poste não encontrado") -> TR-837
A7: Poste início | B7: =IFERROR(INDEX(Trechos!$D$2:$D$838,MATCH($B$4,Trechos!$E$2:$E$838,0)),"poste não encontrado") -> 29470281
A8: Zona | B8: =IFERROR(INDEX(Trechos!$I$2:$I$838,MATCH($B$4,Trechos!$E$2:$E$838,0)),"poste não encontrado") -> T3
A9: Tronco/Ramal | B9: =IFERROR(INDEX(Trechos!$J$2:$J$838,MATCH($B$4,Trechos!$E$2:$E$838,0)),"poste não encontrado") -> Ramal
A10: Ramal | B10: =IFERROR(INDEX(Trechos!$K$2:$K$838,MATCH($B$4,Trechos!$E$2:$E$838,0)),"poste não encontrado") -> Ramal após 0344627004
A11: Bloco | B11: =IFERROR(INDEX(Trechos!$L$2:$L$838,MATCH($B$4,Trechos!$E$2:$E$838,0)),"poste não encontrado") -> 107
A12: Ativo de referência | B12: =IFERROR(INDEX(Trechos!$M$2:$M$838,MATCH($B$4,Trechos!$E$2:$E$838,0)),"poste não encontrado") -> 0344627004
A13: Distância do ativo de referência (m) | B13: =IFERROR(INDEX(Trechos!$H$2:$H$838,MATCH($B$4,Trechos!$E$2:$E$838,0)),"poste não encontrado") -> 4.5423246
A14: Distância do DJ (m) | B14: =IFERROR(INDEX(Trechos!$G$2:$G$838,MATCH($B$4,Trechos!$E$2:$E$838,0)),"poste não encontrado") -> 7348.9166
A15: Ativos posteriores englobados | B15: =IFERROR(INDEX(Trechos!$P$2:$P$838,MATCH($B$4,Trechos!$E$2:$E$838,0)),"poste não encontrado") -> —
A16: Outra chave no fim do vão (88…) | B16: =IFERROR(INDEX(Trechos!$R$2:$R$838,MATCH($B$4,Trechos!$E$2:$E$838,0)),"poste não encontrado") -> 0
A17: Caminho desde o DJ | B17: =IFERROR(INDEX(Trechos!$Y$2:$Y$838,MATCH($B$4,Trechos!$E$2:$E$838,0)),"poste não encontrado") -> DJ AL01010004 › 7900106004 › 7927795004 › 0344627004
A18: Latitude | B18: =IFERROR(INDEX(Trechos!$Z$2:$Z$838,MATCH($B$4,Trechos!$E$2:$E$838,0)),"poste não encontrado") -> -7.2158745
A19: Longitude | B19: =IFERROR(INDEX(Trechos!$AA$2:$AA$838,MATCH($B$4,Trechos!$E$2:$E$838,0)),"poste não encontrado") -> -48.217382

Sheet Blocos
A1: Bloco | B1: Zona | C1: Tronco/Ramal | D1: Ramal | E1: Ativo de referência | F1: De | G1: Próximo ativo 1 | H1: Próximo ativo 2 | I1: Próximo ativo 3 | J1: Próximo ativo 4 | K1: Próximo ativo 5 | L1: Próximo ativo 6 | M1: Próximo ativo 7 | N1: Próximo ativo 8 | O1: Próximo ativo 9 | P1: Próximo ativo 10 | Q1: Próximo ativo 11 | R1: Próximo ativo 12 | S1: Próximo ativo 13 | T1: Próximo ativo 14 | U1: Próximo ativo 15 | V1: Próximo ativo 16 | W1: Próximo ativo 17 | X1: Próximo ativo 18 | Y1: Próximo ativo 19 | Z1: Próximo ativo 20 | AA1: Próximo ativo 21 | AB1: Próximo ativo 22 | AC1: Próximo ativo 23 | AD1: Próximo ativo 24 | AE1: Próximo ativo 25 | AF1: Próximo ativo 26 | AG1: Próximo ativo 27 | AH1: Próximo ativo 28 | AI1: Próximo ativo 29 | AJ1: Próximo ativo 30 | AK1: Próximo ativo 31 | AL1: Próximo ativo 32 | AM1: Próximo ativo 33 | AN1: Próximo ativo 34 | AO1: Próximo ativo 35 | AP1: Próximo ativo 36 | AQ1: Próximo ativo 37 | AR1: Próximo ativo 38 | AS1: Próximo ativo 39 | AT1: Próximo ativo 40 | AU1: Próximo ativo 41 | AV1: Próximo ativo 42 | AW1: Próximo ativo 43 | AX1: Próximo ativo 44 | AY1: Próximo ativo 45 | AZ1: Próximo ativo 46 | BA1: Próximo ativo 47 | BB1: Próximo ativo 48 | BC1: Próximo ativo 49 | BD1: Próximo ativo 50 | BE1: Próximo ativo 51 | BF1: Próximo ativo 52 | BG1: Próximo ativo 53 | BH1: Próximo ativo 54 | BI1: Próximo ativo 55 | BJ1: Próximo ativo 56 | BK1: Nível 1 | BL1: Nível 2 | BM1: Nível 3 | BN1: Nível 4 | BO1: Nível 5 | BP1: Nível 6 | BQ1: Qtd. vãos | BR1: Extensão do bloco (m) | BS1: Qtd. ativos posteriores | BT1: Ativos posteriores (concatenado) | BU1: Outras chaves no bloco (88…) | BV1: Posterior 1 | BW1: Posterior 2 | BX1: Posterior 3 | BY1: Posterior 4 | BZ1: Posterior 5 | CA1: Posterior 6 | CB1: Posterior 7 | CC1: Posterior 8 | CD1: Posterior 9 | CE1: Posterior 10 | CF1: Posterior 11 | CG1: Posterior 12 | CH1: Posterior 13 | CI1: Posterior 14 | CJ1: Posterior 15 | CK1: Posterior 16 | CL1: Posterior 17 | CM1: Posterior 18 | CN1: Posterior 19 | CO1: Posterior 20 | CP1: Posterior 21 | CQ1: Posterior 22 | CR1: Posterior 23 | CS1: Posterior 24 | CT1: Posterior 25 | CU1: Posterior 26 | CV1: Posterior 27 | CW1: Posterior 28 | CX1: Posterior 29 | CY1: Posterior 30 | CZ1: Posterior 31 | DA1: Posterior 32 | DB1: Posterior 33 | DC1: Posterior 34 | DD1: Posterior 35 | DE1: Posterior 36 | DF1: Posterior 37 | DG1: Posterior 38 | DH1: Posterior 39 | DI1: Posterior 40 | DJ1: Posterior 41 | DK1: Posterior 42 | DL1: Posterior 43 | DM1: Posterior 44 | DN1: Posterior 45 | DO1: Posterior 46 | DP1: Posterior 47 | DQ1: Posterior 48 | DR1: Posterior 49 | DS1: Posterior 50 | DT1: Posterior 51 | DU1: Posterior 52 | DV1: Posterior 53 | DW1: Posterior 54 | DX1: Posterior 55 | DY1: Posterior 56 | DZ1: Posterior 57 | EA1: Posterior 58 | EB1: Posterior 59 | EC1: Posterior 60 | ED1: Posterior 61 | EE1: Posterior 62 | EF1: Posterior 63 | EG1: Posterior 64 | EH1: Posterior 65 | EI1: Posterior 66 | EJ1: Posterior 67 | EK1: Posterior 68 | EL1: Posterior 69 | EM1: Posterior 70 | EN1: Posterior 71 | EO1: Posterior 72 | EP1: Posterior 73 | EQ1: Posterior 74 | ER1: Posterior 75 | ES1: Posterior 76
A2: 1 | B2: T1 | C2: Tronco | D2: Tronco | E2: DJ AL01010004 | F2: DJ AL01010004 | G2: 7900106004 | BK2: DJ AL01010004 | BQ2: =COUNTIFS(Trechos!$L$2:$L$838,A2) -> 43 | BR2: =SUMIFS(Trechos!$F$2:$F$838,Trechos!$L$2:$L$838,A2) -> 1688.686 | BS2: =COUNTA(BV2:ES2) -> 76 | BT2: =IF(COUNTA(BV2:ES2)=0,"—",_xlfn.TEXTJOIN(", ",TRUE(),BV2:ES2)) -> 7900106004, 7927795004, 0300031004, 0345006004, 0352810004, 0300724004, 0342284004, 0200038004, 0328286004, 0314965004, 0344627004, 0334747004, 0347400004, 0358161004, 0342738004, 0203728004, 0328468004, 0329025004, 0203016004, 0300049004, 0203015004, 0300052004, 0200050004, 0200028004, 0300024004, 0349562004, 0349564004, 0355236004, 0200023004, 0204420004, 0302387004, 3302865004, 3300065004, 0320309004, 0310307004, 0303851004, 0310306004, 0303865004, 0342709004, 0303866004, 0303867004, 0302309004, 0300064004, 0320308004, 0301840004, 0303850004, 0320305004, 0346260004, 0346420004, 0355088004, 0340038004, 0201389004, 0303849004, 0310949004, 0210950004, 0301838004, 0301839004, 0245040004, 0303718004, 0202970004, 0354089004, 0354093004, 0220315004, 0346072004, 0345823004, 0200043004, 0200011004, 0357531004, 0303835004, 0356395004, 3300016004, 0301090004, 0303861004, 0304100004, 0201099004, 0301069004 | BU2: 8800002004, 8838716004, 8836357004, 8823701004 | BV2: 7900106004 | BW2: 7927795004 | BX2: 0300031004 | BY2: 0345006004 | BZ2: 0352810004 | CA2: 0300724004 | CB2: 0342284004 | CC2: 0200038004 | CD2: 0328286004 | CE2: 0314965004 | CF2: 0344627004 | CG2: 0334747004 | CH2: 0347400004 | CI2: 0358161004 | CJ2: 0342738004 | CK2: 0203728004 | CL2: 0328468004 | CM2: 0329025004 | CN2: 0203016004 | CO2: 0300049004 | CP2: 0203015004 | CQ2: 0300052004 | CR2: 0200050004 | CS2: 0200028004 | CT2: 0300024004 | CU2: 0349562004 | CV2: 0349564004 | CW2: 0355236004 | CX2: 0200023004 | CY2: 0204420004 | CZ2: 0302387004 | DA2: 3302865004 | DB2: 3300065004 | DC2: 0320309004 | DD2: 0310307004 | DE2: 0303851004 | DF2: 0310306004 | DG2: 0303865004 | DH2: 0342709004 | DI2: 0303866004 | DJ2: 0303867004 | DK2: 0302309004 | DL2: 0300064004 | DM2: 0320308004 | DN2: 0301840004 | DO2: 0303850004 | DP2: 0320305004 | DQ2: 0346260004 | DR2: 0346420004 | DS2: 0355088004 | DT2: 0340038004 | DU2: 0201389004 | DV2: 0303849004 | DW2: 0310949004 | DX2: 0210950004 | DY2: 0301838004 | DZ2: 0301839004 | EA2: 0245040004 | EB2: 0303718004 | EC2: 0202970004 | ED2: 0354089004 | EE2: 0354093004 | EF2: 0220315004 | EG2: 0346072004 | EH2: 0345823004 | EI2: 0200043004 | EJ2: 0200011004 | EK2: 0357531004 | EL2: 0303835004 | EM2: 0356395004 | EN2: 3300016004 | EO2: 0301090004 | EP2: 0303861004 | EQ2: 0304100004 | ER2: 0201099004 | ES2: 0301069004
A3: 2 | B3: T2 | C3: Tronco | D3: Tronco | E3: 7900106004 | F3: 7900106004 | G3: 7927795004 | BK3: DJ AL01010004 | BL3: 7900106004 | BQ3: =COUNTIFS(Trechos!$L$2:$L$838,A3) -> 29 | BR3: =SUMIFS(Trechos!$F$2:$F$838,Trechos!$L$2:$L$838,A3) -> 1397.3178 | BS3: =COUNTA(BV3:ES3) -> 29 | BT3: =IF(COUNTA(BV3:ES3)=0,"—",_xlfn.TEXTJOIN(", ",TRUE(),BV3:ES3)) -> 7927795004, 0300031004, 0345006004, 0352810004, 0300724004, 0342284004, 0200038004, 0328286004, 0314965004, 0344627004, 0334747004, 0347400004, 0358161004, 0342738004, 0203728004, 0328468004, 0329025004, 0203016004, 0300049004, 0203015004, 0300052004, 0200050004, 0200028004, 0300024004, 0349562004, 0349564004, 0355236004, 0200023004, 0204420004 | BU3: 8802390004, 0349277004, 8827796004, 8800029004 | BV3: 7927795004 | BW3: 0300031004 | BX3: 0345006004 | BY3: 0352810004 | BZ3: 0300724004 | CA3: 0342284004 | CB3: 0200038004 | CC3: 0328286004 | CD3: 0314965004 | CE3: 0344627004 | CF3: 0334747004 | CG3: 0347400004 | CH3: 0358161004 | CI3: 0342738004 | CJ3: 0203728004 | CK3: 0328468004 | CL3: 0329025004 | CM3: 0203016004 | CN3: 0300049004 | CO3: 0203015004 | CP3: 0300052004 | CQ3: 0200050004 | CR3: 0200028004 | CS3: 0300024004 | CT3: 0349562004 | CU3: 0349564004 | CV3: 0355236004 | CW3: 0200023004 | CX3: 0204420004
A4: 3 | B4: T2 | C4: Tronco | D4: Tronco | E4: 7927795004 | F4: 7927795004 | G4: 0300031004 | H4: 0300724004 | I4: 0328286004 | J4: 0314965004 | K4: 0344627004 | L4: 0334747004 | M4: 0203728004 | N4: 0328468004 | O4: 0329025004 | P4: 0203016004 | Q4: 0300049004 | R4: 0203015004 | BK4: DJ AL01010004 | BL4: 7900106004 | BM4: 7927795004 | BQ4: =COUNTIFS(Trechos!$L$2:$L$838,A4) -> 114 | BR4: =SUMIFS(Trechos!$F$2:$F$838,Trechos!$L$2:$L$838,A4) -> 5582.6239 | BS4: =COUNTA(BV4:ES4) -> 19 | BT4: =IF(COUNTA(BV4:ES4)=0,"—",_xlfn.TEXTJOIN(", ",TRUE(),BV4:ES4)) -> 0300031004, 0345006004, 0352810004, 0300724004, 0342284004, 0200038004, 0328286004, 0314965004, 0344627004, 0334747004, 0347400004, 0358161004, 0342738004, 0203728004, 0328468004, 0329025004, 0203016004, 0300049004, 0203015004 | BU4: 8841354004, 8800034004, 8803727004, 8828470004, 8814964004, 8855846004, 8855095004, 8855094004, 8858328004, 8804463004 | BV4: 0300031004 | BW4: 0345006004 | BX4: 0352810004 | BY4: 0300724004 | BZ4: 0342284004 | CA4: 0200038004 | CB4: 0328286004 | CC4: 0314965004 | CD4: 0344627004 | CE4: 0334747004 | CF4: 0347400004 | CG4: 0358161004 | CH4: 0342738004 | CI4: 0203728004 | CJ4: 0328468004 | CK4: 0329025004 | CL4: 0203016004 | CM4: 0300049004 | CN4: 0203015004
A5: 4 | B5: T1 | C5: Ramal | D5: Ramal do 0200011004 | E5: DJ AL01010004 | F5: poste N13 | G5: 0200011004 | H5: 0357531004 | I5: fim 59283022 | J5: 0303835004 | K5: fim 554197 | L5: 0356395004 | M5: 3300016004 | N5: 0201099004 | O5: fim 48647275 | P5: fim N107 | Q5: fim 93802 | R5: 0301069004 | S5: fim 555910 | T5: fim 539462 | U5: fim 555011 | V5: fim N29 | W5: fim 536530 | BK5: DJ AL01010004 | BQ5: =COUNTIFS(Trechos!$L$2:$L$838,A5) -> 73 | BR5: =SUMIFS(Trechos!$F$2:$F$838,Trechos!$L$2:$L$838,A5) -> 3978.3332 | BS5: =COUNTA(BV5:ES5) -> 10 | BT5: =IF(COUNTA(BV5:ES5)=0,"—",_xlfn.TEXTJOIN(", ",TRUE(),BV5:ES5)) -> 0200011004, 0357531004, 0303835004, 0356395004, 3300016004, 0301090004, 0303861004, 0304100004, 0201099004, 0301069004 | BU5: 8801100004, 8801130004, 8800010004, 8800009004, 8804031004, 8858190004, 8800015004 | BV5: 0200011004 | BW5: 0357531004 | BX5: 0303835004 | BY5: 0356395004 | BZ5: 3300016004 | CA5: 0301090004 | CB5: 0303861004 | CC5: 0304100004 | CD5: 0201099004 | CE5: 0301069004
A6: 5 | B6: T3 | C6: Ramal | D6: Ramal do 0200011004 | E6: 0200011004 | F6: 0200011004 | G6: fim N218 | BK6: DJ AL01010004 | BL6: 0200011004 | BQ6: =COUNTIFS(Trechos!$L$2:$L$838,A6) -> 2 | BR6: =SUMIFS(Trechos!$F$2:$F$838,Trechos!$L$2:$L$838,A6) -> 26.25525 | BS6: =COUNTA(BV6:ES6) -> 0 | BT6: =IF(COUNTA(BV6:ES6)=0,"—",_xlfn.TEXTJOIN(", ",TRUE(),BV6:ES6)) -> — | BU6: —
A7: 6 | B7: T3 | C7: Ramal | D7: Ramal do 0200011004 | E7: 0357531004 | F7: 0357531004 | G7: fim 41939697 | BK7: DJ AL01010004 | BL7: 0357531004 | BQ7: =COUNTIFS(Trechos!$L$2:$L$838,A7) -> 2 | BR7: =SUMIFS(Trechos!$F$2:$F$838,Trechos!$L$2:$L$838,A7) -> 86.236461 | BS7: =COUNTA(BV7:ES7) -> 0 | BT7: =IF(COUNTA(BV7:ES7)=0,"—",_xlfn.TEXTJOIN(", ",TRUE(),BV7:ES7)) -> — | BU7: —
A8: 7 | B8: T3 | C8: Ramal | D8: Ramal do 0200011004 | E8: 0303835004 | F8: 0303835004 | G8: fim 538289 | BK8: DJ AL01010004 | BL8: 0303835004 | BQ8: =COUNTIFS(Trechos!$L$2:$L$838,A8) -> 2 | BR8: =SUMIFS(Trechos!$F$2:$F$838,Trechos!$L$2:$L$838,A8) -> 164.5764 | BS8: =COUNTA(BV8:ES8) -> 0 | BT8: =IF(COUNTA(BV8:ES8)=0,"—",_xlfn.TEXTJOIN(", ",TRUE(),BV8:ES8)) -> — | BU8: —
A9: 8 | B9: T3 | C9: Ramal | D9: Ramal do 0200011004 | E9: 0356395004 | F9: 0356395004 | G9: fim 41939685 | BK9: DJ AL01010004 | BL9: 0356395004 | BQ9: =COUNTIFS(Trechos!$L$2:$L$838,A9) -> 4 | BR9: =SUMIFS(Trechos!$F$2:$F$838,Trechos!$L$2:$L$838,A9) -> 242.11235 | BS9: =COUNTA(BV9:ES9) -> 0 | BT9: =IF(COUNTA(BV9:ES9)=0,"—",_xlfn.TEXTJOIN(", ",TRUE(),BV9:ES9)) -> — | BU9: —
A10: 9 | B10: T3 | C10: Ramal | D10: Ramal do 0200011004 | E10: 3300016004 | F10: 3300016004 | G10: 0301090004 | BK10: DJ AL01010004 | BL10: 3300016004 | BQ10: =COUNTIFS(Trechos!$L$2:$L$838,A10) -> 6 | BR10: =SUMIFS(Trechos!$F$2:$F$838,Trechos!$L$2:$L$838,A10) -> 419.6145 | BS10: =COUNTA(BV10:ES10) -> 3 | BT10: =IF(COUNTA(BV10:ES10)=0,"—",_xlfn.TEXTJOIN(", ",TRUE(),BV10:ES10)) -> 0301090004, 0303861004, 0304100004 | BU10: — | BV10: 0301090004 | BW10: 0303861004 | BX10: 0304100004
A11: 10 | B11: T3 | C11: Ramal | D11: Ramal do 0200011004 | E11: 0301090004 | F11: 0301090004 | G11: 0303861004 | H11: 0304100004 | I11: fim 115640 | BK11: DJ AL01010004 | BL11: 3300016004 | BM11: 0301090004 | BQ11: =COUNTIFS(Trechos!$L$2:$L$838,A11) -> 7 | BR11: =SUMIFS(Trechos!$F$2:$F$838,Trechos!$L$2:$L$838,A11) -> 505.3772 | BS11: =COUNTA(BV11:ES11) -> 2 | BT11: =IF(COUNTA(BV11:ES11)=0,"—",_xlfn.TEXTJOIN(", ",TRUE(),BV11:ES11)) -> 0303861004, 0304100004 | BU11: — | BV11: 0303861004 | BW11: 0304100004
A12: 11 | B12: T3 | C12: Ramal | D12: Ramal do 0200011004 | E12: 0303861004 | F12: 0303861004 | G12: fim N161 | BK12: DJ AL01010004 | BL12: 3300016004 | BM12: 0301090004 | BN12: 0303861004 | BQ12: =COUNTIFS(Trechos!$L$2:$L$838,A12) -> 1 | BR12: =SUMIFS(Trechos!$F$2:$F$838,Trechos!$L$2:$L$838,A12) -> 122.54796 | BS12: =COUNTA(BV12:ES12) -> 0 | BT12: =IF(COUNTA(BV12:ES12)=0,"—",_xlfn.TEXTJOIN(", ",TRUE(),BV12:ES12)) -> — | BU12: —
A13: 12 | B13: T3 | C13: Ramal | D13: Ramal do 0200011004 | E13: 0304100004 | F13: 0304100004 | G13: fim 1097675 | BK13: DJ AL01010004 | BL13: 3300016004 | BM13: 0301090004 | BN13: 0304100004 | BQ13: =COUNTIFS(Trechos!$L$2:$L$838,A13) -> 1 | BR13: =SUMIFS(Trechos!$F$2:$F$838,Trechos!$L$2:$L$838,A13) -> 53.386472 | BS13: =COUNTA(BV13:ES13) -> 0 | BT13: =IF(COUNTA(BV13:ES13)=0,"—",_xlfn.TEXTJOIN(", ",TRUE(),BV13:ES13)) -> — | BU13: —
A14: 13 | B14: T3 | C14: Ramal | D14: Ramal do 0200011004 | E14: 0201099004 | F14: 0201099004 | G14: fim N215 | H14: fim 590202 | BK14: DJ AL01010004 | BL14: 0201099004 | BQ14: =COUNTIFS(Trechos!$L$2:$L$838,A14) -> 3 | BR14: =SUMIFS(Trechos!$F$2:$F$838,Trechos!$L$2:$L$838,A14) -> 17.631789 | BS14: =COUNTA(BV14:ES14) -> 0 | BT14: =IF(COUNTA(BV14:ES14)=0,"—",_xlfn.TEXTJOIN(", ",TRUE(),BV14:ES14)) -> — | BU14: —
A15: 14 | B15: T3 | C15: Ramal | D15: Ramal do 0200011004 | E15: 0301069004 | F15: 0301069004 | G15: fim 556216 | BK15: DJ AL01010004 | BL15: 0301069004 | BQ15: =COUNTIFS(Trechos!$L$2:$L$838,A15) -> 1 | BR15: =SUMIFS(Trechos!$F$2:$F$838,Trechos!$L$2:$L$838,A15) -> 5.1647457 | BS15: =COUNTA(BV15:ES15) -> 0 | BT15: =IF(COUNTA(BV15:ES15)=0,"—",_xlfn.TEXTJOIN(", ",TRUE(),BV15:ES15)) -> — | BU15: —
A16: 15 | B16: T1 | C16: Ramal | D16: Ramal 1471339 | E16: DJ AL01010004 | F16: poste 1471339 | G16: fim 1471341 | BK16: DJ AL01010004 | BQ16: =COUNTIFS(Trechos!$L$2:$L$838,A16) -> 1 | BR16: =SUMIFS(Trechos!$F$2:$F$838,Trechos!$L$2:$L$838,A16) -> 81.237519 | BS16: =COUNTA(BV16:ES16) -> 0 | BT16: =IF(COUNTA(BV16:ES16)=0,"—",_xlfn.TEXTJOIN(", ",TRUE(),BV16:ES16)) -> — | BU16: —
A17: 16 | B17: T1 | C17: Ramal | D17: Ramal do 0302387004 | E17: DJ AL01010004 | F17: poste N86 | G17: fim N91 | H17: fim 93656 | I17: fim 550067 | J17: 0302387004 | K17: fim 35013393 | L17: fim 35013388 | M17: 0346420004 | N17: fim 539706 | O17: fim 587027 | P17: fim 29689259 | Q17: fim 29689060 | R17: fim 29689128 | S17: 0355088004 | T17: 0340038004 | U17: 0201389004 | V17: fim 38388446 | W17: fim 38388428 | X17: fim 345020 | Y17: fim 586093 | Z17: 0303849004 | AA17: fim N204 | AB17: fim N318 | AC17: 0310949004 | AD17: fim N179 | AE17: 0301838004 | AF17: 0245040004 | AG17: fim N170 | AH17: 0303718004 | AI17: 0202970004 | AJ17: fim N158 | AK17: fim 557105 | AL17: fim N274 | AM17: 0354089004 | AN17: fim 556507 | AO17: 0220315004 | AP17: fim 554755 | AQ17: fim 557326 | AR17: fim 554754 | AS17: fim 557325 | AT17: fim 553761 | AU17: fim 553760 | AV17: fim 557877 | AW17: fim 557872 | AX17: fim 557871 | AY17: fim 557874 | AZ17: fim 554507 | BA17: fim 34566747 | BB17: 0346072004 | BC17: fim 31715517 | BD17: 0345823004 | BE17: fim 31715612 | BF17: fim 554240 | BG17: fim 554237 | BH17: fim 553817 | BI17: fim N141 | BJ17: 0200043004 | BK17: DJ AL01010004 | BQ17: =COUNTIFS(Trechos!$L$2:$L$838,A17) -> 173 | BR17: =SUMIFS(Trechos!$F$2:$F$838,Trechos!$L$2:$L$838,A17) -> 8992.9892 | BS17: =COUNTA(BV17:ES17) -> 36 | BT17: =IF(COUNTA(BV17:ES17)=0,"—",_xlfn.TEXTJOIN(", ",TRUE(),BV17:ES17)) -> 0302387004, 3302865004, 3300065004, 0320309004, 0310307004, 0303851004, 0310306004, 0303865004, 0342709004, 0303866004, 0303867004, 0302309004, 0300064004, 0320308004, 0301840004, 0303850004, 0320305004, 0346260004, 0346420004, 0355088004, 0340038004, 0201389004, 0303849004, 0310949004, 0210950004, 0301838004, 0301839004, 0245040004, 0303718004, 0202970004, 0354089004, 0354093004, 0220315004, 0346072004, 0345823004, 0200043004 | BU17: 8802389004, 8804077004, 8844641004, 8801105004, 8802780004, 8855073004, 8803581004, 8803577004, 8845830004 | BV17: 0302387004 | BW17: 3302865004 | BX17: 3300065004 | BY17: 0320309004 | BZ17: 0310307004 | CA17: 0303851004 | CB17: 0310306004 | CC17: 0303865004 | CD17: 0342709004 | CE17: 0303866004 | CF17: 0303867004 | CG17: 0302309004 | CH17: 0300064004 | CI17: 0320308004 | CJ17: 0301840004 | CK17: 0303850004 | CL17: 0320305004 | CM17: 0346260004 | CN17: 0346420004 | CO17: 0355088004 | CP17: 0340038004 | CQ17: 0201389004 | CR17: 0303849004 | CS17: 0310949004 | CT17: 0210950004 | CU17: 0301838004 | CV17: 0301839004 | CW17: 0245040004 | CX17: 0303718004 | CY17: 0202970004 | CZ17: 0354089004 | DA17: 0354093004 | DB17: 0220315004 | DC17: 0346072004 | DD17: 0345823004 | DE17: 0200043004
A18: 17 | B18: T3 | C18: Ramal | D18: Ramal do 0302387004 | E18: 0302387004 | F18: 0302387004 | G18: fim 587304 | H18: fim 538104 | I18: 3302865004 | J18: fim 538331 | K18: 0303850004 | L18: fim 553248 | M18: 0346260004 | BK18: DJ AL01010004 | BL18: 0302387004 | BQ18: =COUNTIFS(Trechos!$L$2:$L$838,A18) -> 13 | BR18: =SUMIFS(Trechos!$F$2:$F$838,Trechos!$L$2:$L$838,A18) -> 1089.0585 | BS18: =COUNTA(BV18:ES18) -> 17 | BT18: =IF(COUNTA(BV18:ES18)=0,"—",_xlfn.TEXTJOIN(", ",TRUE(),BV18:ES18)) -> 3302865004, 3300065004, 0320309004, 0310307004, 0303851004, 0310306004, 0303865004, 0342709004, 0303866004, 0303867004, 0302309004, 0300064004, 0320308004, 0301840004, 0303850004, 0320305004, 0346260004 | BU18: — | BV18: 3302865004 | BW18: 3300065004 | BX18: 0320309004 | BY18: 0310307004 | BZ18: 0303851004 | CA18: 0310306004 | CB18: 0303865004 | CC18: 0342709004 | CD18: 0303866004 | CE18: 0303867004 | CF18: 0302309004 | CG18: 0300064004 | CH18: 0320308004 | CI18: 0301840004 | CJ18: 0303850004 | CK18: 0320305004 | CL18: 0346260004
A19: 18 | B19: T3 | C19: Ramal | D19: Ramal do 0302387004 | E19: 3302865004 | F19: 3302865004 | G19: 3300065004 | H19: 0300064004 | I19: 0320308004 | J19: 0301840004 | BK19: DJ AL01010004 | BL19: 0302387004 | BM19: 3302865004 | BQ19: =COUNTIFS(Trechos!$L$2:$L$838,A19) -> 12 | BR19: =SUMIFS(Trechos!$F$2:$F$838,Trechos!$L$2:$L$838,A19) -> 1422.7885 | BS19: =COUNTA(BV19:ES19) -> 13 | BT19: =IF(COUNTA(BV19:ES19)=0,"—",_xlfn.TEXTJOIN(", ",TRUE(),BV19:ES19)) -> 3300065004, 0320309004, 0310307004, 0303851004, 0310306004, 0303865004, 0342709004, 0303866004, 0303867004, 0302309004, 0300064004, 0320308004, 0301840004 | BU19: — | BV19: 3300065004 | BW19: 0320309004 | BX19: 0310307004 | BY19: 0303851004 | BZ19: 0310306004 | CA19: 0303865004 | CB19: 0342709004 | CC19: 0303866004 | CD19: 0303867004 | CE19: 0302309004 | CF19: 0300064004 | CG19: 0320308004 | CH19: 0301840004
A20: 19 | B20: T3 | C20: Ramal | D20: Ramal do 0302387004 | E20: 3300065004 | F20: 3300065004 | G20: 0320309004 | H20: fim 173794 | BK20: DJ AL01010004 | BL20: 0302387004 | BM20: 3302865004 | BN20: 3300065004 | BQ20: =COUNTIFS(Trechos!$L$2:$L$838,A20) -> 5 | BR20: =SUMIFS(Trechos!$F$2:$F$838,Trechos!$L$2:$L$838,A20) -> 300.01825 | BS20: =COUNTA(BV20:ES20) -> 9 | BT20: =IF(COUNTA(BV20:ES20)=0,"—",_xlfn.TEXTJOIN(", ",TRUE(),BV20:ES20)) -> 0320309004, 0310307004, 0303851004, 0310306004, 0303865004, 0342709004, 0303866004, 0303867004, 0302309004 | BU20: — | BV20: 0320309004 | BW20: 0310307004 | BX20: 0303851004 | BY20: 0310306004 | BZ20: 0303865004 | CA20: 0342709004 | CB20: 0303866004 | CC20: 0303867004 | CD20: 0302309004
A21: 20 | B21: T3 | C21: Ramal | D21: Ramal do 0302387004 | E21: 0320309004 | F21: 0320309004 | G21: 0310307004 | H21: 0303851004 | I21: 0310306004 | J21: 0303865004 | K21: 0342709004 | L21: 0303866004 | M21: 0303867004 | N21: 0302309004 | BK21: DJ AL01010004 | BL21: 0302387004 | BM21: 3302865004 | BN21: 3300065004 | BO21: 0320309004 | BQ21: =COUNTIFS(Trechos!$L$2:$L$838,A21) -> 31 | BR21: =SUMIFS(Trechos!$F$2:$F$838,Trechos!$L$2:$L$838,A21) -> 3388.7675 | BS21: =COUNTA(BV21:ES21) -> 8 | BT21: =IF(COUNTA(BV21:ES21)=0,"—",_xlfn.TEXTJOIN(", ",TRUE(),BV21:ES21)) -> 0310307004, 0303851004, 0310306004, 0303865004, 0342709004, 0303866004, 0303867004, 0302309004 | BU21: — | BV21: 0310307004 | BW21: 0303851004 | BX21: 0310306004 | BY21: 0303865004 | BZ21: 0342709004 | CA21: 0303866004 | CB21: 0303867004 | CC21: 0302309004
A22: 21 | B22: T3 | C22: Ramal | D22: Ramal do 0302387004 | E22: 0310307004 | F22: 0310307004 | G22: fim 173836 | BK22: DJ AL01010004 | BL22: 0302387004 | BM22: 3302865004 | BN22: 3300065004 | BO22: 0320309004 | BP22: 0310307004 | BQ22: =COUNTIFS(Trechos!$L$2:$L$838,A22) -> 1 | BR22: =SUMIFS(Trechos!$F$2:$F$838,Trechos!$L$2:$L$838,A22) -> 35.92843 | BS22: =COUNTA(BV22:ES22) -> 0 | BT22: =IF(COUNTA(BV22:ES22)=0,"—",_xlfn.TEXTJOIN(", ",TRUE(),BV22:ES22)) -> — | BU22: —
A23: 22 | B23: T3 | C23: Ramal | D23: Ramal do 0302387004 | E23: 0303851004 | F23: 0303851004 | G23: fim 586318 | BK23: DJ AL01010004 | BL23: 0302387004 | BM23: 3302865004 | BN23: 3300065004 | BO23: 0320309004 | BP23: 0303851004 | BQ23: =COUNTIFS(Trechos!$L$2:$L$838,A23) -> 1 | BR23: =SUMIFS(Trechos!$F$2:$F$838,Trechos!$L$2:$L$838,A23) -> 466.71724 | BS23: =COUNTA(BV23:ES23) -> 0 | BT23: =IF(COUNTA(BV23:ES23)=0,"—",_xlfn.TEXTJOIN(", ",TRUE(),BV23:ES23)) -> — | BU23: —
A24: 23 | B24: T3 | C24: Ramal | D24: Ramal do 0302387004 | E24: 0310306004 | F24: 0310306004 | G24: fim 173833 | BK24: DJ AL01010004 | BL24: 0302387004 | BM24: 3302865004 | BN24: 3300065004 | BO24: 0320309004 | BP24: 0310306004 | BQ24: =COUNTIFS(Trechos!$L$2:$L$838,A24) -> 1 | BR24: =SUMIFS(Trechos!$F$2:$F$838,Trechos!$L$2:$L$838,A24) -> 261.89621 | BS24: =COUNTA(BV24:ES24) -> 0 | BT24: =IF(COUNTA(BV24:ES24)=0,"—",_xlfn.TEXTJOIN(", ",TRUE(),BV24:ES24)) -> — | BU24: —
A25: 24 | B25: T3 | C25: Ramal | D25: Ramal do 0302387004 | E25: 0303865004 | F25: 0303865004 | G25: fim 549515 | BK25: DJ AL01010004 | BL25: 0302387004 | BM25: 3302865004 | BN25: 3300065004 | BO25: 0320309004 | BP25: 0303865004 | BQ25: =COUNTIFS(Trechos!$L$2:$L$838,A25) -> 1 | BR25: =SUMIFS(Trechos!$F$2:$F$838,Trechos!$L$2:$L$838,A25) -> 114.5567 | BS25: =COUNTA(BV25:ES25) -> 0 | BT25: =IF(COUNTA(BV25:ES25)=0,"—",_xlfn.TEXTJOIN(", ",TRUE(),BV25:ES25)) -> — | BU25: —
A26: 25 | B26: T3 | C26: Ramal | D26: Ramal do 0302387004 | E26: 0342709004 | F26: 0342709004 | G26: fim 1461337 | BK26: DJ AL01010004 | BL26: 0302387004 | BM26: 3302865004 | BN26: 3300065004 | BO26: 0320309004 | BP26: 0342709004 | BQ26: =COUNTIFS(Trechos!$L$2:$L$838,A26) -> 3 | BR26: =SUMIFS(Trechos!$F$2:$F$838,Trechos!$L$2:$L$838,A26) -> 106.35573 | BS26: =COUNTA(BV26:ES26) -> 0 | BT26: =IF(COUNTA(BV26:ES26)=0,"—",_xlfn.TEXTJOIN(", ",TRUE(),BV26:ES26)) -> — | BU26: —
A27: 26 | B27: T3 | C27: Ramal | D27: Ramal do 0302387004 | E27: 0303866004 | F27: 0303866004 | G27: fim 590237 | BK27: DJ AL01010004 | BL27: 0302387004 | BM27: 3302865004 | BN27: 3300065004 | BO27: 0320309004 | BP27: 0303866004 | BQ27: =COUNTIFS(Trechos!$L$2:$L$838,A27) -> 1 | BR27: =SUMIFS(Trechos!$F$2:$F$838,Trechos!$L$2:$L$838,A27) -> 50.299251 | BS27: =COUNTA(BV27:ES27) -> 0 | BT27: =IF(COUNTA(BV27:ES27)=0,"—",_xlfn.TEXTJOIN(", ",TRUE(),BV27:ES27)) -> — | BU27: —
A28: 27 | B28: T3 | C28: Ramal | D28: Ramal do 0302387004 | E28: 0303867004 | F28: 0303867004 | G28: fim 589790 | BK28: DJ AL01010004 | BL28: 0302387004 | BM28: 3302865004 | BN28: 3300065004 | BO28: 0320309004 | BP28: 0303867004 | BQ28: =COUNTIFS(Trechos!$L$2:$L$838,A28) -> 1 | BR28: =SUMIFS(Trechos!$F$2:$F$838,Trechos!$L$2:$L$838,A28) -> 92.258631 | BS28: =COUNTA(BV28:ES28) -> 0 | BT28: =IF(COUNTA(BV28:ES28)=0,"—",_xlfn.TEXTJOIN(", ",TRUE(),BV28:ES28)) -> — | BU28: —
A29: 28 | B29: T3 | C29: Ramal | D29: Ramal do 0302387004 | E29: 0302309004 | F29: 0302309004 | G29: fim 311399 | BK29: DJ AL01010004 | BL29: 0302387004 | BM29: 3302865004 | BN29: 3300065004 | BO29: 0320309004 | BP29: 0302309004 | BQ29: =COUNTIFS(Trechos!$L$2:$L$838,A29) -> 1 | BR29: =SUMIFS(Trechos!$F$2:$F$838,Trechos!$L$2:$L$838,A29) -> 252.90918 | BS29: =COUNTA(BV29:ES29) -> 0 | BT29: =IF(COUNTA(BV29:ES29)=0,"—",_xlfn.TEXTJOIN(", ",TRUE(),BV29:ES29)) -> — | BU29: —
A30: 29 | B30: T3 | C30: Ramal | D30: Ramal do 0302387004 | E30: 0300064004 | F30: 0300064004 | G30: fim 93637 | BK30: DJ AL01010004 | BL30: 0302387004 | BM30: 3302865004 | BN30: 0300064004 | BQ30: =COUNTIFS(Trechos!$L$2:$L$838,A30) -> 1 | BR30: =SUMIFS(Trechos!$F$2:$F$838,Trechos!$L$2:$L$838,A30) -> 30.83559 | BS30: =COUNTA(BV30:ES30) -> 0 | BT30: =IF(COUNTA(BV30:ES30)=0,"—",_xlfn.TEXTJOIN(", ",TRUE(),BV30:ES30)) -> — | BU30: —
A31: 30 | B31: T3 | C31: Ramal | D31: Ramal do 0302387004 | E31: 0320308004 | F31: 0320308004 | G31: fim 173793 | BK31: DJ AL01010004 | BL31: 0302387004 | BM31: 3302865004 | BN31: 0320308004 | BQ31: =COUNTIFS(Trechos!$L$2:$L$838,A31) -> 1 | BR31: =SUMIFS(Trechos!$F$2:$F$838,Trechos!$L$2:$L$838,A31) -> 60.470929 | BS31: =COUNTA(BV31:ES31) -> 0 | BT31: =IF(COUNTA(BV31:ES31)=0,"—",_xlfn.TEXTJOIN(", ",TRUE(),BV31:ES31)) -> — | BU31: —
A32: 31 | B32: T3 | C32: Ramal | D32: Ramal do 0302387004 | E32: 0301840004 | F32: 0301840004 | G32: fim 31758476 | BK32: DJ AL01010004 | BL32: 0302387004 | BM32: 3302865004 | BN32: 0301840004 | BQ32: =COUNTIFS(Trechos!$L$2:$L$838,A32) -> 1 | BR32: =SUMIFS(Trechos!$F$2:$F$838,Trechos!$L$2:$L$838,A32) -> 347.96775 | BS32: =COUNTA(BV32:ES32) -> 0 | BT32: =IF(COUNTA(BV32:ES32)=0,"—",_xlfn.TEXTJOIN(", ",TRUE(),BV32:ES32)) -> — | BU32: —
A33: 32 | B33: T3 | C33: Ramal | D33: Ramal do 0302387004 | E33: 0303850004 | F33: 0303850004 | G33: 0320305004 | H33: fim 553249 | I33: fim 538115 | J33: fim 539707 | K33: fim 539737 | BK33: DJ AL01010004 | BL33: 0302387004 | BM33: 0303850004 | BQ33: =COUNTIFS(Trechos!$L$2:$L$838,A33) -> 12 | BR33: =SUMIFS(Trechos!$F$2:$F$838,Trechos!$L$2:$L$838,A33) -> 559.31223 | BS33: =COUNTA(BV33:ES33) -> 1 | BT33: =IF(COUNTA(BV33:ES33)=0,"—",_xlfn.TEXTJOIN(", ",TRUE(),BV33:ES33)) -> 0320305004 | BU33: — | BV33: 0320305004
A34: 33 | B34: T3 | C34: Ramal | D34: Ramal do 0302387004 | E34: 0320305004 | F34: 0320305004 | G34: fim 432617 | H34: fim 173832 | BK34: DJ AL01010004 | BL34: 0302387004 | BM34: 0303850004 | BN34: 0320305004 | BQ34: =COUNTIFS(Trechos!$L$2:$L$838,A34) -> 10 | BR34: =SUMIFS(Trechos!$F$2:$F$838,Trechos!$L$2:$L$838,A34) -> 647.3029 | BS34: =COUNTA(BV34:ES34) -> 0 | BT34: =IF(COUNTA(BV34:ES34)=0,"—",_xlfn.TEXTJOIN(", ",TRUE(),BV34:ES34)) -> — | BU34: —
A35: 34 | B35: T3 | C35: Ramal | D35: Ramal do 0302387004 | E35: 0346260004 | F35: 0346260004 | G35: fim N341 | H35: fim N340 | BK35: DJ AL01010004 | BL35: 0302387004 | BM35: 0346260004 | BQ35: =COUNTIFS(Trechos!$L$2:$L$838,A35) -> 3 | BR35: =SUMIFS(Trechos!$F$2:$F$838,Trechos!$L$2:$L$838,A35) -> 23.527215 | BS35: =COUNTA(BV35:ES35) -> 0 | BT35: =IF(COUNTA(BV35:ES35)=0,"—",_xlfn.TEXTJOIN(", ",TRUE(),BV35:ES35)) -> — | BU35: —
A36: 35 | B36: T3 | C36: Ramal | D36: Ramal do 0302387004 | E36: 0346420004 | F36: 0346420004 | G36: fim N349 | BK36: DJ AL01010004 | BL36: 0346420004 | BQ36: =COUNTIFS(Trechos!$L$2:$L$838,A36) -> 2 | BR36: =SUMIFS(Trechos!$F$2:$F$838,Trechos!$L$2:$L$838,A36) -> 14.975521 | BS36: =COUNTA(BV36:ES36) -> 0 | BT36: =IF(COUNTA(BV36:ES36)=0,"—",_xlfn.TEXTJOIN(", ",TRUE(),BV36:ES36)) -> — | BU36: —
A37: 36 | B37: T3 | C37: Ramal | D37: Ramal do 0302387004 | E37: 0355088004 | F37: 0355088004 | G37: fim 28576683 | BK37: DJ AL01010004 | BL37: 0355088004 | BQ37: =COUNTIFS(Trechos!$L$2:$L$838,A37) -> 1 | BR37: =SUMIFS(Trechos!$F$2:$F$838,Trechos!$L$2:$L$838,A37) -> 13.618165 | BS37: =COUNTA(BV37:ES37) -> 0 | BT37: =IF(COUNTA(BV37:ES37)=0,"—",_xlfn.TEXTJOIN(", ",TRUE(),BV37:ES37)) -> — | BU37: —
A38: 37 | B38: T3 | C38: Ramal | D38: Ramal do 0302387004 | E38: 0340038004 | F38: 0340038004 | G38: fim 1107431 | H38: fim 1394050 | I38: fim N412 | J38: fim 1394770 | BK38: DJ AL01010004 | BL38: 0340038004 | BQ38: =COUNTIFS(Trechos!$L$2:$L$838,A38) -> 11 | BR38: =SUMIFS(Trechos!$F$2:$F$838,Trechos!$L$2:$L$838,A38) -> 499.02867 | BS38: =COUNTA(BV38:ES38) -> 0 | BT38: =IF(COUNTA(BV38:ES38)=0,"—",_xlfn.TEXTJOIN(", ",TRUE(),BV38:ES38)) -> — | BU38: —
A39: 38 | B39: T3 | C39: Ramal | D39: Ramal do 0302387004 | E39: 0201389004 | F39: 0201389004 | G39: fim 212906 | BK39: DJ AL01010004 | BL39: 0201389004 | BQ39: =COUNTIFS(Trechos!$L$2:$L$838,A39) -> 1 | BR39: =SUMIFS(Trechos!$F$2:$F$838,Trechos!$L$2:$L$838,A39) -> 99.536474 | BS39: =COUNTA(BV39:ES39) -> 0 | BT39: =IF(COUNTA(BV39:ES39)=0,"—",_xlfn.TEXTJOIN(", ",TRUE(),BV39:ES39)) -> — | BU39: —
A40: 39 | B40: T3 | C40: Ramal | D40: Ramal do 0302387004 | E40: 0303849004 | F40: 0303849004 | G40: fim 537428 | H40: fim 586089 | BK40: DJ AL01010004 | BL40: 0303849004 | BQ40: =COUNTIFS(Trechos!$L$2:$L$838,A40) -> 7 | BR40: =SUMIFS(Trechos!$F$2:$F$838,Trechos!$L$2:$L$838,A40) -> 438.92528 | BS40: =COUNTA(BV40:ES40) -> 0 | BT40: =IF(COUNTA(BV40:ES40)=0,"—",_xlfn.TEXTJOIN(", ",TRUE(),BV40:ES40)) -> — | BU40: —
...

Sheet Por bloco
A1: Bloco | B1: Zona | C1: Tronco/Ramal | D1: Ramal | E1: Ativo de referência | F1: Trecho | G1: Poste início | H1: Poste fim | I1: Extensão (m) | J1: Distância do ativo de referência até o fim (m) | K1: Outra chave no fim do vão (88…) | L1: Próximos ativos | M1: Outras chaves no bloco (88…) | N1: Ativos posteriores
A2: 1 | B2: T1 | C2: Tronco | D2: Tronco | E2: DJ AL01010004 | F2: =COUNTIFS(Trechos!$L$2:$L$838,A2)&" vãos" -> 43 vãos | I2: =SUMIFS(Trechos!$F$2:$F$838,Trechos!$L$2:$L$838,A2) -> 1688.686 | L2: 7900106004 | M2: 8800002004, 8838716004, 8836357004, 8823701004 | N2: =Blocos!BT2 -> 7900106004, 7927795004, 0300031004, 0345006004, 0352810004, 0300724004, 0342284004, 0200038004, 0328286004, 0314965004, 0344627004, 0334747004, 0347400004, 0358161004, 0342738004, 0203728004, 0328468004, 0329025004, 0203016004, 0300049004, 0203015004, 0300052004, 0200050004, 0200028004, 0300024004, 0349562004, 0349564004, 0355236004, 0200023004, 0204420004, 0302387004, 3302865004, 3300065004, 0320309004, 0310307004, 0303851004, 0310306004, 0303865004, 0342709004, 0303866004, 0303867004, 0302309004, 0300064004, 0320308004, 0301840004, 0303850004, 0320305004, 0346260004, 0346420004, 0355088004, 0340038004, 0201389004, 0303849004, 0310949004, 0210950004, 0301838004, 0301839004, 0245040004, 0303718004, 0202970004, 0354089004, 0354093004, 0220315004, 0346072004, 0345823004, 0200043004, 0200011004, 0357531004, 0303835004, 0356395004, 3300016004, 0301090004, 0303861004, 0304100004, 0201099004, 0301069004
F3: TR-001 | G3: N0 | H3: N1 | I3: 41.038122 | J3: 41.038122
F4: TR-002 | G4: N1 | H4: 330494 | I4: 1.9997507 | J4: 43.037873 | K4: 8800002004
F5: TR-003 | G5: 330494 | H5: N3 | I5: 17.14693 | J5: 60.184803
F6: TR-004 | G6: N3 | H6: 535160 | I6: 2.9245512 | J6: 63.109355
F7: TR-005 | G7: 535160 | H7: 535157 | I7: 36.045809 | J7: 99.155164
F8: TR-006 | G8: 535157 | H8: N6 | I8: 3.4251 | J8: 102.58026
F9: TR-007 | G9: N6 | H9: N7 | I9: 20.084828 | J9: 122.66509
F10: TR-008 | G10: N7 | H10: N8 | I10: 3.0989279 | J10: 125.76402
F11: TR-009 | G11: N8 | H11: 531051 | I11: 50.705196 | J11: 176.46922
F12: TR-010 | G12: 531051 | H12: N10 | I12: 3.4488076 | J12: 179.91802
F13: TR-011 | G13: N10 | H13: N11 | I13: 16.092437 | J13: 196.01046
F14: TR-012 | G14: N11 | H14: 536161 | I14: 3.7237339 | J14: 199.73419
F15: TR-013 | G15: 536161 | H15: N13 | I15: 97.129334 | J15: 296.86353
F16: TR-014 | G16: N13 | H16: N14 | I16: 12.306964 | J16: 309.17049
F17: TR-015 | G17: N14 | H17: 1239378 | I17: 1.1379354 | J17: 310.30843 | K17: 8838716004
F18: TR-016 | G18: 1239378 | H18: 538537 | I18: 6.8687295 | J18: 317.17716
F19: TR-017 | G19: 538537 | H19: 1385568 | I19: 27.884363 | J19: 345.06152
F20: TR-018 | G20: 1385568 | H20: N20 | I20: 3.5961121 | J20: 348.65763
F21: TR-019 | G21: N20 | H21: N21 | I21: 12.949422 | J21: 361.60705
F22: TR-020 | G22: N21 | H22: N22 | I22: 3.7737511 | J22: 365.38081
F23: TR-021 | G23: N22 | H23: N23 | I23: 13.986461 | J23: 379.36727
F24: TR-022 | G24: N23 | H24: 1471339 | I24: 3.6114774 | J24: 382.97874
F25: TR-023 | G25: 1471339 | H25: 538784 | I25: 20.016609 | J25: 402.99535
F26: TR-024 | G26: 538784 | H26: N28 | I26: 3.5889262 | J26: 406.58428
F27: TR-025 | G27: N28 | H27: 537819 | I27: 44.833582 | J27: 451.41786
F28: TR-026 | G28: 537819 | H28: 26339935 | I28: 239.44687 | J28: 690.86473
F29: TR-027 | G29: 26339935 | H29: N37 | I29: 45.292437 | J29: 736.15716
F30: TR-028 | G30: N37 | H30: 537824 | I30: 3.4278801 | J30: 739.58504 | K30: 8836357004
F31: TR-029 | G31: 537824 | H31: 538290 | I31: 136.45502 | J31: 876.04007
F32: TR-030 | G32: 538290 | H32: N52 | I32: 138.40206 | J32: 1014.4421
F33: TR-031 | G33: N52 | H33: 539877 | I33: 3.7237237 | J33: 1018.1658
F34: TR-032 | G34: 539877 | H34: 23466725 | I34: 118.02834 | J34: 1136.1942
F35: TR-033 | G35: 23466725 | H35: 538761 | I35: 99.4 | J35: 1235.5942
F36: TR-034 | G36: 538761 | H36: N86 | I36: 294.72556 | J36: 1530.3197
F37: TR-035 | G37: N86 | H37: 538767 | I37: 27.808344 | J37: 1558.1281
F38: TR-036 | G38: 538767 | H38: N90 | I38: 5.1156951 | J38: 1563.2438 | K38: 8823701004
F39: TR-037 | G39: N90 | H39: N95 | I39: 45.628998 | J39: 1608.8728
F40: TR-038 | G40: N95 | H40: N96 | I40: 3.3272004 | J40: 1612.2
...

Sheet Trechos
A1: Seq | B1: Trecho | C1: Trecho no Daimon | D1: Poste início | E1: Poste fim | F1: Extensão (m) | G1: Distância do DJ até o fim (m) | H1: Distância do ativo de referência até o fim (m) | I1: Zona | J1: Tronco/Ramal | K1: Ramal | L1: Bloco | M1: Ativo de referência | N1: Tipo do ativo de referência | O1: Próximo(s) ativo(s) | P1: Ativos posteriores englobados | Q1: Qtd. ativos posteriores | R1: Outra chave no fim do vão (88…) | S1: Nível 1 | T1: Nível 2 | U1: Nível 3 | V1: Nível 4 | W1: Nível 5 | X1: Nível 6 | Y1: Caminho desde o DJ | Z1: Latitude (meio do vão) | AA1: Longitude (meio do vão) | AB1: Mapa | AC1: Chave do caminho (uso das fórmulas)
A2: 1 | B2: TR-001 | C2: 2517480 | D2: N0 | E2: N1 | F2: 41.038122 | G2: 41.038122 | H2: 41.038122 | I2: T1 | J2: Tronco | K2: Tronco | L2: 1 | M2: DJ AL01010004 | N2: Disjuntor (DJ) | O2: 7900106004 | P2: 7900106004, 7927795004, 0300031004, 0345006004, 0352810004, 0300724004, 0342284004, 0200038004, 0328286004, 0314965004, 0344627004, 0334747004, 0347400004, 0358161004, 0342738004, 0203728004, 0328468004, 0329025004, 0203016004, 0300049004, 0203015004, 0300052004, 0200050004, 0200028004, 0300024004, 0349562004, 0349564004, 0355236004, 0200023004, 0204420004, 0302387004, 3302865004, 3300065004, 0320309004, 0310307004, 0303851004, 0310306004, 0303865004, 0342709004, 0303866004, 0303867004, 0302309004, 0300064004, 0320308004, 0301840004, 0303850004, 0320305004, 0346260004, 0346420004, 0355088004, 0340038004, 0201389004, 0303849004, 0310949004, 0210950004, 0301838004, 0301839004, 0245040004, 0303718004, 0202970004, 0354089004, 0354093004, 0220315004, 0346072004, 0345823004, 0200043004, 0200011004, 0357531004, 0303835004, 0356395004, 3300016004, 0301090004, 0303861004, 0304100004, 0201099004, 0301069004 | Q2: 76 | S2: DJ AL01010004 | Y2: DJ AL01010004 | Z2: -7.19538 | AA2: -48.23811 | AB2: abrir | AC2: |DJ AL01010004|
A3: 2 | B3: TR-002 | C3: Suporte Chave 8800002004 | D3: N1 | E3: 330494 | F3: 1.9997507 | G3: 43.037873 | H3: 43.037873 | I3: T1 | J3: Tronco | K3: Tronco | L3: 1 | M3: DJ AL01010004 | N3: Disjuntor (DJ) | O3: 7900106004 | P3: 7900106004, 7927795004, 0300031004, 0345006004, 0352810004, 0300724004, 0342284004, 0200038004, 0328286004, 0314965004, 0344627004, 0334747004, 0347400004, 0358161004, 0342738004, 0203728004, 0328468004, 0329025004, 0203016004, 0300049004, 0203015004, 0300052004, 0200050004, 0200028004, 0300024004, 0349562004, 0349564004, 0355236004, 0200023004, 0204420004, 0302387004, 3302865004, 3300065004, 0320309004, 0310307004, 0303851004, 0310306004, 0303865004, 0342709004, 0303866004, 0303867004, 0302309004, 0300064004, 0320308004, 0301840004, 0303850004, 0320305004, 0346260004, 0346420004, 0355088004, 0340038004, 0201389004, 0303849004, 0310949004, 0210950004, 0301838004, 0301839004, 0245040004, 0303718004, 0202970004, 0354089004, 0354093004, 0220315004, 0346072004, 0345823004, 0200043004, 0200011004, 0357531004, 0303835004, 0356395004, 3300016004, 0301090004, 0303861004, 0304100004, 0201099004, 0301069004 | Q3: 76 | R3: 8800002004 | S3: DJ AL01010004 | Y3: DJ AL01010004 | Z3: -7.1955055 | AA3: -48.238258 | AB3: abrir | AC3: |DJ AL01010004|
A4: 3 | B4: TR-003 | C4: 2520098 | D4: 330494 | E4: N3 | F4: 17.14693 | G4: 60.184803 | H4: 60.184803 | I4: T1 | J4: Tronco | K4: Tronco | L4: 1 | M4: DJ AL01010004 | N4: Disjuntor (DJ) | O4: 7900106004 | P4: 7900106004, 7927795004, 0300031004, 0345006004, 0352810004, 0300724004, 0342284004, 0200038004, 0328286004, 0314965004, 0344627004, 0334747004, 0347400004, 0358161004, 0342738004, 0203728004, 0328468004, 0329025004, 0203016004, 0300049004, 0203015004, 0300052004, 0200050004, 0200028004, 0300024004, 0349562004, 0349564004, 0355236004, 0200023004, 0204420004, 0302387004, 3302865004, 3300065004, 0320309004, 0310307004, 0303851004, 0310306004, 0303865004, 0342709004, 0303866004, 0303867004, 0302309004, 0300064004, 0320308004, 0301840004, 0303850004, 0320305004, 0346260004, 0346420004, 0355088004, 0340038004, 0201389004, 0303849004, 0310949004, 0210950004, 0301838004, 0301839004, 0245040004, 0303718004, 0202970004, 0354089004, 0354093004, 0220315004, 0346072004, 0345823004, 0200043004, 0200011004, 0357531004, 0303835004, 0356395004, 3300016004, 0301090004, 0303861004, 0304100004, 0201099004, 0301069004 | Q4: 76 | S4: DJ AL01010004 | Y4: DJ AL01010004 | Z4: -7.1955785 | AA4: -48.238304 | AB4: abrir | AC4: |DJ AL01010004|
A5: 4 | B5: TR-004 | C5: 12072724 | D5: N3 | E5: 535160 | F5: 2.9245512 | G5: 63.109355 | H5: 63.109355 | I5: T1 | J5: Tronco | K5: Tronco | L5: 1 | M5: DJ AL01010004 | N5: Disjuntor (DJ) | O5: 7900106004 | P5: 7900106004, 7927795004, 0300031004, 0345006004, 0352810004, 0300724004, 0342284004, 0200038004, 0328286004, 0314965004, 0344627004, 0334747004, 0347400004, 0358161004, 0342738004, 0203728004, 0328468004, 0329025004, 0203016004, 0300049004, 0203015004, 0300052004, 0200050004, 0200028004, 0300024004, 0349562004, 0349564004, 0355236004, 0200023004, 0204420004, 0302387004, 3302865004, 3300065004, 0320309004, 0310307004, 0303851004, 0310306004, 0303865004, 0342709004, 0303866004, 0303867004, 0302309004, 0300064004, 0320308004, 0301840004, 0303850004, 0320305004, 0346260004, 0346420004, 0355088004, 0340038004, 0201389004, 0303849004, 0310949004, 0210950004, 0301838004, 0301839004, 0245040004, 0303718004, 0202970004, 0354089004, 0354093004, 0220315004, 0346072004, 0345823004, 0200043004, 0200011004, 0357531004, 0303835004, 0356395004, 3300016004, 0301090004, 0303861004, 0304100004, 0201099004, 0301069004 | Q5: 76 | S5: DJ AL01010004 | Y5: DJ AL01010004 | Z5: -7.195657 | AA5: -48.238343 | AB5: abrir | AC5: |DJ AL01010004|
A6: 5 | B6: TR-005 | C6: 2796761 | D6: 535160 | E6: 535157 | F6: 36.045809 | G6: 99.155164 | H6: 99.155164 | I6: T1 | J6: Tronco | K6: Tronco | L6: 1 | M6: DJ AL01010004 | N6: Disjuntor (DJ) | O6: 7900106004 | P6: 7900106004, 7927795004, 0300031004, 0345006004, 0352810004, 0300724004, 0342284004, 0200038004, 0328286004, 0314965004, 0344627004, 0334747004, 0347400004, 0358161004, 0342738004, 0203728004, 0328468004, 0329025004, 0203016004, 0300049004, 0203015004, 0300052004, 0200050004, 0200028004, 0300024004, 0349562004, 0349564004, 0355236004, 0200023004, 0204420004, 0302387004, 3302865004, 3300065004, 0320309004, 0310307004, 0303851004, 0310306004, 0303865004, 0342709004, 0303866004, 0303867004, 0302309004, 0300064004, 0320308004, 0301840004, 0303850004, 0320305004, 0346260004, 0346420004, 0355088004, 0340038004, 0201389004, 0303849004, 0310949004, 0210950004, 0301838004, 0301839004, 0245040004, 0303718004, 0202970004, 0354089004, 0354093004, 0220315004, 0346072004, 0345823004, 0200043004, 0200011004, 0357531004, 0303835004, 0356395004, 3300016004, 0301090004, 0303861004, 0304100004, 0201099004, 0301069004 | Q6: 76 | S6: DJ AL01010004 | Y6: DJ AL01010004 | Z6: -7.195788 | AA6: -48.238229 | AB6: abrir | AC6: |DJ AL01010004|
A7: 6 | B7: TR-006 | C7: 12074471 | D7: 535157 | E7: N6 | F7: 3.4251 | G7: 102.58026 | H7: 102.58026 | I7: T1 | J7: Tronco | K7: Tronco | L7: 1 | M7: DJ AL01010004 | N7: Disjuntor (DJ) | O7: 7900106004 | P7: 7900106004, 7927795004, 0300031004, 0345006004, 0352810004, 0300724004, 0342284004, 0200038004, 0328286004, 0314965004, 0344627004, 0334747004, 0347400004, 0358161004, 0342738004, 0203728004, 0328468004, 0329025004, 0203016004, 0300049004, 0203015004, 0300052004, 0200050004, 0200028004, 0300024004, 0349562004, 0349564004, 0355236004, 0200023004, 0204420004, 0302387004, 3302865004, 3300065004, 0320309004, 0310307004, 0303851004, 0310306004, 0303865004, 0342709004, 0303866004, 0303867004, 0302309004, 0300064004, 0320308004, 0301840004, 0303850004, 0320305004, 0346260004, 0346420004, 0355088004, 0340038004, 0201389004, 0303849004, 0310949004, 0210950004, 0301838004, 0301839004, 0245040004, 0303718004, 0202970004, 0354089004, 0354093004, 0220315004, 0346072004, 0345823004, 0200043004, 0200011004, 0357531004, 0303835004, 0356395004, 3300016004, 0301090004, 0303861004, 0304100004, 0201099004, 0301069004 | Q7: 76 | S7: DJ AL01010004 | Y7: DJ AL01010004 | Z7: -7.1959115 | AA7: -48.238102 | AB7: abrir | AC7: |DJ AL01010004|
